Workbook

Sheet Expense
D2: =SUM(D4:D35) -> 76022191 | E2: =SUM(G2:AC2) -> 76022191 | G2: =G38 -> 6500000 | H2: =H38 -> 34539540 | I2: =I38 -> 646.13 | J2: =J38 -> 0 | K2: =K38 -> 0 | L2: =L38 -> 1661252.7 | M2: =M38 -> 2420995.6 | N2: =N38 -> 0 | ... AC2: =AC38 -> 0
A3: Column 1 | B3: Column 2 | C3: Column 3 | D3: Column 4 | E3: Total | G3: inter | H3: pay. batch | I3: bank charge | J3: NIMC Sponsorship | K3: Refund | L3: MWC REgistration | M3: Flight Ticket/Accommodation | N3: Tatvasoft | O3: Hotel/Acc | P3: Management Allowance | Q3: Office Supplies & Fuel | R3: Software Tools | S3: Shipping & Freight | T3: AWS | U3: UAE funding | V3: BTA | W3: NIMC -Licenses Fee | X3: VAT | Y3: WHT | Z3: Hosting | AA3: Salary | AB3: Paye | AC3: Bis Premises & Dev Levy
A4: OUTFLOWS | C4: FBN (PROJECT) | D4: 0 | E4: =SUM(G4:AC4) -> 0
A5: Interbank | B5: =G2 -> 6500000 | C5: FIDELITY | D5: 0 | E5: =SUM(G5:AC5) -> 0
A6: Payment Batches | B6: =H2 -> 34539540 | C6: POLARIS MAIN | D6: 0 | E6: =SUM(G6:AC6) -> 0
A7: =R3 -> Software Tools | B7: =R2 -> 286865.18 | C7: POLARIS (OPERATIONS 1) | D7: 0 | E7: =SUM(G7:AC7) -> 0
A8: Management Allowance | B8: =P2 -> 7013010 | C8: POLARIS (OPERATIONS 2) | D8: 0 | E8: =SUM(G8:AC8) -> 0
A9: MWC Registration | B9: =L2 -> 1661252.7 | C9: SCB | D9: 0 | E9: =SUM(G9:AC9) -> 0
A10: Flight Ticket/Accommodation | B10: =M2 -> 2420995.6 | C10: UBA Main | D10: 30 | E10: =SUM(G10:AC10) -> 30 | I10: 30
A11: PAYE | B11: =AB2 -> 22731381 | C11: UBA (PROJECT) | D11: 0 | E11: =SUM(G11:AC11) -> 0
A12: Office Supplies & Fuel | B12: =Q2 -> 868500 | C12: UBA (COLLECTION 1) | D12: 0 | E12: =SUM(G12:AC12) -> 0
A13: Bank Charges | B13: =I2 -> 646.13 | C13: UBA (COLLECTION 2) | D13: 0 | E13: =SUM(G13:AC13) -> 0
C14: UBA APG | D14: 0 | E14: =SUM(G14:AC14) -> 0
C15: UNION BANK | D15: 0 | E15: =SUM(G15:AC15) -> 0
C16: ZENITH CALL 1 | D16: 0 | E16: =SUM(G16:AC16) -> 0
C17: ZENITH (SETTLEMENT) | D17: 0 | E17: =SUM(G17:AC17) -> 0
C18: GTB | D18: 22731781 | E18: =SUM(G18:AC18) -> 22731781 | I18: 400 | AB18: 22731381
A19: Total | B19: =SUM(B5:B18) -> 76022191 | C19: GTB (Mastercard corporate debit) | D19: 472295.85 | E19: =SUM(G19:AC19) -> 472295.85 | M19: 472295.85
A20: Interbank | B20: =B5 -> 6500000 | C20: Access Bank Main A/C | D20: 46699757 | E20: =SUM(G20:AC20) -> 46699757 | G20: 6500000 | H20: 34539540 | I20: 216.13 | P20: 5660000
B21: =SUM(B19-B20) -> 69522191 | C21: Access Bank Salary A/C | D21: 0 | E21: =SUM(G21:AC21) -> 0
C22: Wema Card | D22: 868500 | E22: =SUM(G22:AC22) -> 868500 | Q22: 868500
C23: Globus | D23: 0 | E23: =SUM(G23:AC23) -> 0
C24: MoMo Wallet | D24: 0 | E24: =SUM(G24:AC24) -> 0
D25: 0
C26: ZENITH (USD) | D26: 0 | E26: =SUM(G26:AB26) -> 0
C27: CASH IN HAND (USD) | D27: =1000*C36 -> 1353010 | E27: =SUM(G27:AB27) -> 1353010 | P27: =1000*C36 -> 1353010
C28: CASH IN HAND (POUNDS) | D28: 0 | E28: =SUM(G28:AB28) -> 0
C29: CASH IN TRANSIT | D29: 0 | E29: =SUM(G29:AB29) -> 0
C30: GTB | D30: 0 | E30: =SUM(G30:AB30) -> 0
C31: GTB MASTERCARD CCC (DOLLAR) | D31: =2880.11*C36 -> 3896817.6 | E31: =SUM(G31:AB31) -> 3896817.6 | L31: =1227.82*C36 -> 1661252.7 | M31: =1440.27* C36 -> 1948699.7 | R31: =212.02*C36 -> 286865.18
C32: SCB | D32: 0 | E32: =SUM(G32:AB32) -> 0
C33: SCB Funding | D33: 0 | E33: =SUM(G33:AB33) -> 0
C34: UBA | D34: 0 | E34: =SUM(G34:AB34) -> 0
C35: Access USD | D35: 0 | E35: =SUM(G35:AB35) -> 0
C36: =Income!C36 -> 1353.01
D37: =SUM(D4:D35) -> 76022191 | E37: =SUM(E4:E35) -> 76022191
G38: =SUM(G4:G37) -> 6500000 | H38: =SUM(H4:H37) -> 34539540 | I38: =SUM(I4:I37) -> 646.13 | J38: =SUM(J4:J37) -> 0 | K38: =SUM(K4:K37) -> 0 | L38: =SUM(L4:L37) -> 1661252.7 | M38: =SUM(M4:M37) -> 2420995.6 | N38: =SUM(N4:N37) -> 0 | ... AC38: =SUM(AC4:AC37) -> 0

Sheet Income
D2: =SUM(D4:D35) -> 1.5770603e+08 | E2: =SUM(F2:AF2) -> 1.5770603e+08 | F2: =F36 -> 6500000 | G2: =G36 -> 195663.5 | H2: =H36 -> 10993.48 | I2: =I36 -> 0 | J2: =J36 -> 0 | K2: =K36 -> 35884531 | L2: =L36 -> 0 | M2: =M36 -> 66857989 | ... Y2: =Y36
E3: Total | F3: Interbank | G3: Refund/Reversal | H3: idqr | I3: Investment Liquidation | J3: Insurance Claim | K3: MTN CIV Income | L3: Interest Earned | M3: NIMC Income | N3: iTranscript Income | O3: NextGen | P3: Loan Repayment | Q3: Insurance Claim | R3: MTN Income
A4: Inflows | C4: FBN (PROJECT) | D4: 0 | E4: =SUM(F4:W4) -> 0
A5: Interbank | B5: =F2 -> 6500000 | C5: FIDELITY | D5: 0 | E5: =SUM(F5:W5) -> 0
A6: Nimc Income | B6: =M2 -> 66857989 | C6: POLARIS MAIN | D6: 0 | E6: =SUM(F6:W6) -> 0
A7: IDQR Income | B7: =H2 -> 10993.48 | C7: POLARIS (OPERATIONS 1) | D7: 0 | E7: =SUM(F7:W7) -> 0
A8: iTranscript Income | B8: =N2 -> 527863.32 | C8: POLARIS (OPERATIONS 2) | D8: 0 | E8: =SUM(F8:W8) -> 0
A9: Refund/Reversal | B9: =G2 -> 195663.5 | C9: SCB | D9: 0 | E9: =SUM(F9:W9) -> 0
A10: MTN CIV Income | B10: =K2 -> 35884531 | C10: UBA MAIN | D10: 10993.48 | E10: =SUM(F10:W10) -> 10993.48 | H10: 10993.48
A11: NIMC Income | B11: =R2 -> 47728988 | C11: UBA Project | D11: 0 | E11: =SUM(F11:W11) -> 0
A12: Total | B12: =SUM(B5:B11) -> 1.5770603e+08 | C12: UBA (COLLECTION 1) | D12: 0 | E12: =SUM(F12:W12) -> 0
B13: =B5 -> 6500000 | C13: UBA (COLLECTION 2) | D13: 0 | E13: =SUM(F13:W13) -> 0
B14: =B12-B13 -> 1.5120603e+08 | C14: UBA APG | D14: 0 | E14: =SUM(F14:W14) -> 0
C15: UNION BANK | D15: 0 | E15: =SUM(F15:W15) -> 0
C16: ZENITH CALL 1 | D16: 5000000 | E16: =SUM(F16:W16) -> 5000000 | F16: 5000000
C17: ZENITH (SETTLEMENT) | D17: 0 | E17: =SUM(F17:W17) -> 0
C18: GTB | D18: 27756000 | E18: =SUM(F18:W18) -> 27756000 | M18: 27756000
C19: GTB (Mastercard corporate debit) | E19: =SUM(F19:W19) -> 0
C20: Access Bank Main A/C | D20: 47763278 | E20: =SUM(F20:W20) -> 47763278 | G20: 34290 | R20: 47728988
C21: Access Bank Salary A/C | D21: 0 | E21: =SUM(F21:W21) -> 0
C22: Wema Card | D22: 1500000 | E22: =SUM(F22:W22) -> 1500000 | F22: 1500000
C23: Globus | D23: 0 | E23: =SUM(F23:W23) -> 0
C24: MoMo Wallet | D24: 0 | E24: =SUM(F24:W24) -> 0
D25: 0 | E25: =SUM(F25:W25) -> 0
C26: ZENITH (USD) | D26: =390.14*C36 -> 527863.32 | E26: =SUM(F26:W26) -> 527863.32 | N26: =390.14*C36 -> 527863.32
C27: CASH IN HAND (USD) | D27: 0 | E27: =SUM(F27:W27) -> 0
C28: CASH IN HAND (POUNDS) | D28: 0 | E28: =SUM(F28:W28) -> 0
C29: CASH IN TRANSIT | D29: 0 | E29: =SUM(F29:W29) -> 0
C30: GTB | D30: =17000*C36 -> 23001170 | E30: =SUM(G30:W30) -> 23001170 | M30: =17000*C36 -> 23001170
C31: GTB MASTERCARD CCC (DOLLAR) | D31: =119.27*C36 -> 161373.5 | E31: =SUM(F31:W31) -> 161373.5 | G31: =119.27*C36 -> 161373.5
C32: SCB | D32: 0 | E32: =SUM(G32:W32) -> 0
C33: SCB Funding | D33: 0 | E33: =SUM(F33:W33) -> 0
C34: UBA | D34: 0 | E34: =SUM(F34:W34) -> 0
C35: Access USD | D35: =38422*C36 -> 51985350 | E35: =SUM(F35:W35) -> 51985350 | K35: =26522*C36 -> 35884531 | M35: =11900*C36 -> 16100819
C36: ='Cash Report'!E31 -> 1353.01 | D36: =SUM(D4:D35) -> 1.5770603e+08 | E36: =SUM(E4:E35) -> 1.5770603e+08 | F36: =SUM(F4:F35) -> 6500000 | G36: =SUM(G4:G35) -> 195663.5 | H36: =SUM(H4:H35) -> 10993.48 | I36: =SUM(I4:I35) -> 0 | J36: =SUM(J4:J35) -> 0 | K36: =SUM(K4:K35) -> 35884531 | ... W36: =SUM(W4:W35) -> 0
D39: =D36-F36 -> 1.5120603e+08

Sheet Cash Report
A1: sa
B2: SEAMFIX LIMITED
B3: CASH AND CASH EQUIVALENT REPORT AS AT 13TH FEBRUARY 2026
B4: CASH IN HAND AND BANK
B5: S/N | C5: Banks | D5: OPENING BALANCE | E5: EXCHANGE RATE | F5: OPENING BALANCE (NGN) | G5: INFLOW | H5: OUTFLOW | I5: NET DIFFERENCE | J5: CLOSING BALANCE | K5: Remarks
B6: 1 | C6: FBN (PROJECT) | D6: 1057208.4 | E6: 1 | F6: =D6*E6 -> 1057208.4 | G6: 0 | H6: 0 | I6: =G6-H6 -> 0 | J6: =F6+I6 -> 1057208.4 | K6: Inflow: Outflow:
B7: 2 | C7: FIDELITY | D7: 73124.13 | E7: 1 | F7: =D7*E7 -> 73124.13 | G7: 0 | H7: 0 | I7: =G7-H7 -> 0 | J7: =F7+I7 -> 73124.13 | K7: Inflow: Outflow:
B8: 3 | C8: POLARIS MAIN | D8: 1239057.9 | E8: 1 | F8: =D8*E8 -> 1239057.9 | G8: 0 | H8: 0 | I8: =G8-H8 -> 0 | J8: =F8+I8 -> 1239057.9 | K8: Inflow: Outflow:
B9: 4 | C9: POLARIS (OPERATIONS 1) | D9: 31493.46 | E9: 1 | F9: =D9*E9 -> 31493.46 | G9: 0 | H9: 0 | I9: =G9-H9 -> 0 | J9: =F9+I9 -> 31493.46 | K9: Inflow: Outflow:
B10: 5 | C10: POLARIS (OPERATIONS 2) | D10: 208999.86 | E10: 1 | F10: =D10*E10 -> 208999.86 | G10: 0 | H10: 0 | I10: =G10-H10 -> 0 | J10: =F10+I10 -> 208999.86 | K10: Inflow: Outflow:
B11: 6 | C11: SCB | D11: 2415181.7 | E11: 1 | F11: =D11*E11 -> 2415181.7 | G11: 0 | H11: 0 | I11: =G11-H11 -> 0 | J11: =F11+I11 -> 2415181.7 | K11: Inflow: Outflow:
B12: 7 | C12: UBA MAIN | D12: 3393431.5 | E12: 1 | F12: =D12*E12 -> 3393431.5 | G12: 10993.48 | H12: 30 | I12: =G12-H12 -> 10963.48 | J12: =F12+I12 -> 3404395 | K12: Inflow: IDQR Income Outflow: Bank Charges
B13: 8 | C13: UBA (PROJECT) | D13: 1169752.2 | E13: 1 | F13: =D13*E13 -> 1169752.2 | G13: 0 | H13: 0 | I13: =G13-H13 -> 0 | J13: =F13+I13 -> 1169752.2 | K13: Inflow: Outflow:
B14: 9 | C14: UBA (COLLECTION 1) | D14: 564653.84 | E14: 1 | F14: =D14*E14 -> 564653.84 | G14: 0 | H14: 0 | I14: =G14-H14 -> 0 | J14: =F14+I14 -> 564653.84 | K14: Inflow: Outflow:
B15: 10 | C15: UBA (COLLECTION 2) | D15: 745578.1 | E15: 1 | F15: =D15*E15 -> 745578.1 | G15: 0 | H15: 0 | I15: =G15-H15 -> 0 | J15: =F15+I15 -> 745578.1 | K15: Inflow: Outflow:
B16: 11 | C16: UBA APG | D16: 11745.64 | E16: 1 | F16: =D16*E16 -> 11745.64 | G16: 0 | H16: 0 | I16: =G16-H16 -> 0 | J16: =F16+I16 -> 11745.64 | K16: Inflow: Outflow:
B17: 12 | C17: UNION BANK | D17: 158755.71 | E17: 1 | F17: =D17*E17 -> 158755.71 | G17: 0 | H17: 0 | I17: =G17-H17 -> 0 | J17: =F17+I17 -> 158755.71 | K17: Inflow: Interbank transfer Outflow:
... B21: 16 | C21: GTB (Mastercard corporate debit) | D21: 3826693 | E21: 1 | F21: =D21*E21 -> 3826693 | G21: 0 | H21: 472295.85 | I21: =G21-H21 -> -472295.85 | J21: =F21+I21 -> 3354397.2 | K21: Inflows: Outflow: Flight booking
A22: C | B22: 17 | C22: Access Bank Main A/C | D22: 74410180 | E22: 1 | F22: =D22*E22 -> 74410180 | G22: 47763278 | H22: 46699757 | I22: =G22-H22 -> 1063521.4 | J22: =F22+I22 -> 75473702 | K22: Inflow: Refund and MTN income Outflow: Payment Batch, management Allowance & Bank charge,
B23: 18 | C23: Access Bank Salary A/C | D23: 262736.66 | E23: 1 | F23: =D23*E23 -> 262736.66 | G23: 0 | H23: 0 | I23: =G23-H23 -> 0 | J23: =F23+I23 -> 262736.66 | K23: Inflows: Outflow: Bank charges
B24: 19 | C24: Wema | D24: 101797.4 | E24: 1 | F24: =D24*E24 -> 101797.4 | G24: 0 | H24: 0 | I24: =G24-H24 -> 0 | J24: =F24+I24 -> 101797.4 | K24: Inflow: Outflow:
B25: 20 | C25: Wema card A/c | D25: 972011.85 | E25: 1 | F25: =D25*E25 -> 972011.85 | G25: 1500000 | H25: 868500 | I25: =G25-H25 -> 631500 | J25: =F25+I25 -> 1603511.9 | K25: Inflow: Interbank transfer Outflow:
B26: 21 | C26: Globus | D26: 990050.45 | E26: 1 | F26: =D26*E26 -> 990050.45 | G26: 0 | H26: 0 | I26: =G26-H26 -> 0 | J26: =F26+I26 -> 990050.45 | K26: Inflow: Outflow:
B27: 22 | C27: Momo Account | D27: 0 | E27: 1 | F27: =D27*E27 -> 0 | G27: 0 | H27: 0 | I27: =G27-H27 -> 0 | J27: =F27+I27 -> 0 | K27: Inflow: Outflow:
C28: TOTAL CASH (NGN) | D28: =SUM(D6:D27) -> 1.0395606e+08 | F28: =SUM(F6:F27) -> 1.0395606e+08 | G28: =SUM(G6:G27) -> 82030271 | H28: =SUM(H6:H27) -> 70772363 | I28: =SUM(I6:I27) -> 11257908 | J28: =SUM(J6:J27) -> 1.1521396e+08 | K28: Inflow: Outflow:
C30: CASH IN HAND (POUNDS) | D30: 2525 | E30: 1844.24 | F30: =D30*E30 -> 4656706 | G30: 0 | H30: 0 | I30: =G30-H30 -> 0 | J30: =F30+I30 -> 4656706 | K30: Inflow: Outflow:
B31: 23 | C31: ZENITH BANK (USD) | D31: 5465.72 | E31: 1353.01 | F31: =D31*E31 -> 7395173.8 | G31: =390.14*E31 -> 527863.32 | H31: 0 | I31: =G31-H31 -> 527863.32 | J31: =F31+I31 -> 7923037.1 | K31: Inflow: iTranscript Income Outflow:
B32: 24 | C32: CASH IN HAND (USD) | D32: 6946 | E32: =$E$31 -> 1353.01 | F32: =D32*E32 -> 9398007.5 | G32: 0 | H32: =1000*E32 -> 1353010 | I32: =G32-H32 -> -1353010 | J32: =F32+I32 -> 8044997.5 | K32: Inflow: Outflow: Management allowance
B33: 26 | C33: CASH IN TRANSIT | D33: 0 | E33: =$E$31 -> 1353.01 | F33: =D33*E33 -> 0 | G33: 0 | H33: 0 | I33: =G33-H33 -> 0 | J33: =F33+I33 -> 0 | K33: Inflow: Outflow:
B34: 27 | C34: GTB MAIN (USD) | D34: 94121.16 | E34: =$E$31 -> 1353.01 | F34: =D34*E34 -> 1.2734687e+08 | G34: =17000*E34 -> 23001170 | H34: 0 | I34: =G34-H34 -> 23001170 | J34: =F34+I34 -> 1.5034804e+08 | K34: Inflow:Nimc Income Outflow:
B35: 28 | C35: GTB DEBIT CARD (USD) | D35: 14997.94 | E35: =$E$31 -> 1353.01 | F35: =D35*E35 -> 20292363 | G35: =119.27*E35 -> 161373.5 | H35: =2880.11*E35 -> 3896817.6 | I35: =G35-H35 -> -3735444.1 | J35: =F35+I35 -> 16556919 | K35: Inflow: Hotel refund Outflow:Software Tools, Flight & hotel bookings and MWC registration
B36: 30 | C36: SCB | D36: 47346.38 | E36: =$E$31 -> 1353.01 | F36: =D36*E36 -> 64060126 | G36: 0 | H36: 0 | I36: =G36-H36 -> 0 | J36: =F36+I36 -> 64060126 | K36: Inflow: Outflow:
B37: 31 | C37: UBA | D37: 13405.91 | E37: =$E$31 -> 1353.01 | F37: =D37*E37 -> 18138330 | G37: 0 | H37: 0 | I37: =G37-H37 -> 0 | J37: =F37+I37 -> 18138330 | K37: Inflow: Outflow:
B38: 32 | C38: Access USD | D38: 21040.26 | E38: =$E$31 -> 1353.01 | F38: =D38*E38 -> 28467682 | G38: =38422*E38 -> 51985350 | H38: 0 | I38: =G38-H38 -> 51985350 | J38: =F38+I38 -> 80453032 | K38: Inflow: NIMC Income and MTN CIV Income Outflow:
B39: TOTAL CASH (USD | D39: =SUM(D31:D38) -> 203323.37 | E39: =$E$31 -> 1353.01 | F39: =SUM(F31:F38) -> 2.7509855e+08 | G39: =SUM(G31:G38) -> 75675757 | H39: =SUM(H31:H38) -> 5249827.6 | I39: =SUM(I31:I38) -> 70425929 | J39: =SUM(J31:J38) -> 3.4552448e+08
I40: =I39+I28 -> 81683838
I41: ='Breakdown of Income and Expendi'!C22 -> 81683838
B43: TOTAL INVESTMENTS (NGN)
C44: INVESTMENT HOUSE | D44: OPENING BALANCE (PRINCIPAL & iNTEREST PAID | E44: EXCHANGE RATE | F44: OPENING BALANCE (NGN) | G44: INFLOW | H44: OUTFLOW | I44: NET DIFFERENCE | J44: CLOSING BALANCE | K44: COMMENTS
B45: 29 | C45: STANBIC IBTC | D45: 7359160.5 | E45: 1 | F45: =D45*E45 -> 7359160.5 | G45: 0 | H45: 0 | I45: =G45-H45 -> 0 | J45: =F45+G45-H45 -> 7359160.5
...

Sheet Breakdown of Income and Expendi
G2: CASH REPORT - 13TH FEBRUARY 2026
B3: Inflows: | C3: Amount | D3: % Ratio | G3: Details | H3: Amount | I3: Exc rate | J3: Naira Equivalent
B4: Nimc Income | C4: 66857989 | D4: =C4/$C$10 -> 0.44216484 | G4: Opening Balance- 7th Feb NGN | H4: ='Cash Report'!F28 -> 1.0395606e+08 | I4: 1 | J4: =H4*I4 -> 1.0395606e+08
B5: IDQR Income | C5: 10993.48 | D5: =C5/$C$10 -> 7.2705302e-05 | G5: Opening Balance- 7th Feb USD | H5: ='Cash Report'!D39 -> 203323.37 | I5: ='Cash Report'!$E$31 -> 1353.01 | J5: =H5*I5 -> 2.7509855e+08
B6: iTranscript Income | C6: 527863.32 | D6: =C6/$C$10 -> 0.0034910203 | G6: Opening Balance- 7th Feb GBP | H6: 2525 | I6: ='Cash Report'!E30 -> 1844.24 | J6: =H6*I6 -> 4656706
B7: Refund/Reversal | C7: 195663.5 | D7: =C7/$C$10 -> 0.0012940192
B8: MTN CIV Income | C8: 35884531 | D8: =C8/$C$10 -> 0.23732209 | G8: Total Opening Balance | J8: =J4+J5+J6 -> 3.8371132e+08
B9: MTN NG Income | C9: 47728988 | D9: =C9/$C$10 -> 0.31565532
B10: Total Cash Inflows for the week | C10: =sum(C4:C9) -> 1.5120603e+08 | D10: =C10/$C$10*100 -> 100 | G10: INFLOWS | H10: Amount | I10: % Ratio
G11: Nimc Income | H11: 66857989 | I11: 0.44216484
B12: OUTFLOWS | C12: Amount | D12: % Ratio | G12: IDQR Income | H12: 10993.48 | I12: 7.2705302e-05
B13: Payment Batches | C13: 34539540 | D13: =C13/C$21*100 -> 49.681318 | G13: iTranscript Income | H13: 527863.32 | I13: 0.0034910203
B14: Software Tools | C14: 286865.18 | D14: =C14/C$21*100 -> 0.41262391 | G14: Refund/Reversal | H14: 195663.5 | I14: 0.0012940192
B15: Management Allowance | C15: 7013010 | D15: =C15/C$21*100 -> 10.087441 | G15: MTN CIV Income | H15: 35884531 | I15: 0.23732209
B16: MWC Registration | C16: 1661252.7 | D16: =C16/C$21*100 -> 2.3895288 | G16: MTN NG Income | H16: 47728988 | I16: 0.31565532
B17: Flight Ticket/Accommodation | C17: 2420995.6 | D17: =C17/C$21*100 -> 3.482335 | H17: =SUM(H11:H16) -> 1.5120603e+08 | I17: =H17/$H$17*100 -> 100 | J17: =H17 -> 1.5120603e+08
B18: PAYE | C18: 22731381 | D18: =C18/C$21*100 -> 32.696583 | G18: TOTAL CASH BALANCE BEFORE OUTFLOWS | J18: =SUM(J8:J17) -> 5.3491734e+08
B19: Office Supplies & Fuel | C19: 868500 | D19: =C19/C$21*100 -> 1.2492414
B20: Bank Charges | C20: 646.13 | D20: =C20/C$21*100 -> 0.00092938671 | G20: OUTFLOWS | I20: % Ratio
B21: Total Cash Outflow for the week | C21: =SUM(C13:C20) -> 69522191 | D21: =SUM(D13:D20) -> 100 | G21: Payment Batches | H21: 34539540 | I21: 49.681318
B22: Net Cash Inflow for the Week | C22: =C10-C21 -> 81683838 | G22: Software Tools | H22: 286865.18 | I22: 0.41262391
G23: Management Allowance | H23: 7013010 | I23: 10.087441
G24: MWC Registration | H24: 1661252.7 | I24: 2.3895288
G25: Flight Ticket/Accommodation | H25: 2420995.6 | I25: 3.482335
G26: PAYE | H26: 22731381 | I26: 32.696583
G27: Office Supplies & Fuel | H27: 868500 | I27: 1.2492414
G28: Bank Charges | H28: 646.13 | I28: 0.00092938671
H29: =SUM(H21:H28) -> 69522191 | I29: =sum(I21:I28) -> 100 | J29: =H29 -> 69522191
G30: CASH BALANCE AS AT 13TH FEB 2026 | J30: =J18-J29 -> 4.6539515e+08
G32: Breakdown of Alitheia Investment Balance held in SCB
G33: Opening Balance | H33: 768.94 | I33: ='Cash Report'!$E$31 -> 1353.01 | J33: =H33*I33 -> 1040383.5
G35: Closing Balance | H35: =SUM(H33) -> 768.94 | I35: ='Cash Report'!$E$31 -> 1353.01 | J35: =H35*I35 -> 1040383.5
G38: BREAKDOWN OF PAYMENT BATCH FOR THE WEEK
G39: Beneficiary Names | H39: Amount (N) | I39: Description
G40: Microware Solutions Limited | H40: 3280000 | I40: 40% balnace payment for Acumatica IMPLEMENTATION SERVICE FEE
G41: K.k business company ltd | H41: 1369060 | I41: New motorcycle purchase
G42: Doris Obiakor | H42: 81790 | I42: Refund for printing of document for NIMC Expression of interest submission.
G43: Ezeaku Frederick | H43: 29112588 | I43: UNN accumulated partner splits for 2025
G44: Yusuf Oni | H44: 100000 | I44: Wedding gift
G45: Bolt | H45: 154770 | I45: Staff Bolt Rides for January 2026
...

Sheet Cash Balance Summary 
B2: BREAKDOWN OF SEAMFIX CASH BALANCES AS AT 13TH FEB 2026
B3: Cash Balances | C3: Amount (Naira) | D3: Amount (USD) | E3: Amount (GBP) | F3: Exchange rate | G3: Naira Equivalent
B4: Seamfix operational A/c balances (Naira) | C4: ='Cash Report'!D64 -> 1.1521396e+08 | D4: 0 | E4: 0 | F4: 1 | G4: =C4*F4 -> 1.1521396e+08
B5: Seamfix operational A/c balances (USD) | C5: 0 | D5: ='Cash Report'!D65 -> 255374.67 | E5: 0 | F5: ='Cash Report'!$E$31 -> 1353.01 | G5: ='Cash Report'!J39 -> 3.4552448e+08
B6: Seamfix operational A/c balances (GBP) | C6: 0 | D6: 0 | E6: ='Cash Report'!D66 -> 2525 | F6: ='Cash Report'!E30 -> 1844.24 | G6: ='Cash Report'!F66 -> 4656706
B7: Alitheia funds in the SCB funding a/c | C7: 0 | D7: ='Breakdown of Income and Expendi'!H35 -> 768.94 | E7: 0 | F7: ='Cash Report'!$E$31 -> 1353.01 | G7: =D7*F7 -> 1040383.5
B8: TOTAL | C8: =SUM(C4:C7) -> 1.1521396e+08 | D8: =SUM(D4:D7) -> 256143.61 | E8: =SUM(E4:E7) -> 2525 | G8: =SUM(G4:G7) -> 4.6643554e+08
B12: BREAKDOWN OF AIF INVESTMENT FUND
B13: Investment House | C13: Principal | D13: Interest | E13: Total | F13: Maturity Date | G13: Investment Type | H13: Comment
B14: Stanbic IBTC Asset Management | C14: =59500-59500 -> 0 | D14: 689.68 | E14: =SUM(C14:D14) -> 689.68 | F14: N/A | G14: Mutual Fund
B15: Cardinal Stone Asset Management Ltd | C15: =752544.4-123000-60000 -> 569544.4 | D15: 130154.35 | E15: =SUM(C15:D15) -> 699698.75 | F15: N/A | G15: Mutual Fund
B16: FBNQuest Asset management | C16: 111975.35 | D16: 593.71 | E16: =SUM(C16:D16) -> 112569.06 | F16: N/A | G16: Mutual Fund
B17: FBN Quest & Stanbic Investment | C17: 45314.87 | D17: 32146.39 | E17: =SUM(C17:D17) -> 77461.26 | F17: N/A | G17: Mutual Fund | H17: This is held in Naira with FBN and Stanbic. Naira equivalent is N110.2m
B18: Absa Bank | C18: 528300 | D18: 0 | E18: =SUM(C18:D18) -> 528300 | F18: 46063 | G18: Fixed Deposit
B19: SCB Investment/Funding A/c Balance | C19: 769 | D19: 0 | E19: =SUM(C19:D19) -> 769 | F19: N/A | G19: N/A
C20: =SUM(C14:C19) -> 1255903.6 | D20: =SUM(D14:D19) -> 163584.13 | E20: =SUM(E14:E19) -> 1419487.7
I22: =E20+E26 -> 1460121.1
B23: BREAKDOWN OF OTHER DOLLAR INVESTMENT | I23: =I22*F5 -> 1975558434
B24: Investment House | C24: Principal | D24: Interest | E24: Total | F24: Maturity Date | G24: Investment Type | H24: Comment
B25: FBNQuest Asset Management | C25: 38400 | D25: 2233.34 | E25: =C25+D25 -> 40633.34 | F25: N/A | G25: Mutual Fund | H25: Earmarked for MinIo/Glo project licenses.
B26: Total USD Investments | C26: =SUM(C25) -> 38400 | D26: =SUM(D25) -> 2233.34 | E26: =SUM(E25) -> 40633.34
B29: BREAKDOWN OF OTHER NAIRA INVESTMENTS
B30: Investment House | C30: Principal | D30: Interest | E30: Total | F30: Maturity Date | G30: Investment Type | H30: Comment
B31: FBN Mutual Fund | C31: 0 | D31: 9141371.5 | E31: =C31+D31 -> 9141371.5 | F31: N/A | G31: Mutual Fund
B32: CORDROS MMF | C32: 5000000 | D32: 2679400 | E32: =C32+D32 -> 7679400 | F32: N/A | G32: Mutual Fund
B33: Total Naira Investments | C33: =SUM(C31:C32) -> 5000000 | D33: =SUM(D31:D32) -> 11820772 | E33: =SUM(E31:E32) -> 16820772

Sheet Cash Utilizations from Safe
B2: USAGE OF LAST FOUR CASH WITHDRAWALS FOR SAFE
B4: Date | C4: Description | D4: Inflow | E4: Outflow | F4: Balance
B5: 14/10/2025 | C5: Balance brought forward from 13th Oct 2025 | F5: 5151
B6: 14/10/2025 | C6: Cash withdrawn from SCB | D6: 5000 | F6: =F5+D6-E6 -> 10151
B7: 14/10/2025 | C7: BTA to George for MWC Event Kigali | E7: 670 | F7: =F6+D7-E7 -> 9481
B8: 14/10/2025 | C8: BTA to Kolade for MWC Event Kigali | E8: 1210 | F8: =F7+D8-E8 -> 8271
B9: 14/10/2025 | C9: BTA to Cynthia for MWC Event Kigali | E9: 910 | F9: =F8+D9-E9 -> 7361
B10: 14/10/2025 | C10: Media coverage for MWC Event handed over to Cynthia | E10: 725 | F10: =F9+D10-E10 -> 6636
B11: 14/10/2025 | C11: BTA to Chimezie for MWC Event Kigali | E11: 1200 | F11: =F10+D11-E11 -> 5436
B12: 14/10/2025 | C12: BTA to Frank for MWC Event Kigali | E12: 1200 | F12: =F11+D12-E12 -> 4236
B13: 45758 | C13: BTA refund from George for Kigali Trip | D13: 200 | F13: =F12+D13-E13 -> 4436
B14: 45758 | C14: BTA refund from Cynthia for Kigali Trip | D14: 210 | F14: =F13+D14-E14 -> 4646
B15: 45819 | C15: Cash withdrwan from GTBank | D15: 20000 | F15: =F14+D15-E15 -> 24646
B16: 45819 | C16: Oct 2025 Management allowance - Lilian | E16: 2000 | F16: =F15+D16-E16 -> 22646
B17: 45819 | C17: Oct 2025 Management allowance - Tobi | E17: 2000 | F17: =F16+D17-E17 -> 20646
B18: 45819 | C18: Oct 2025 Management allowance - Kolade | E18: 2000 | F18: =F17+D18-E18 -> 18646
B19: 45819 | C19: Oct 2025 Management allowance - Diyan | E19: 3250 | F19: =F18+D19-E19 -> 15396
B20: 45819 | C20: BTA refund from Kolade for Kigali Trip | D20: 500 | F20: =F19+D20-E20 -> 15896
B21: 45819 | C21: BTA for South African trip - Chimezie | E21: 700 | F21: =F20+D21-E21 -> 15196
B22: 45819 | C22: BTA for South African trip - Frank | E22: 1620 | F22: =F21+D22-E22 -> 13576
B23: 45819 | C23: Cash deposit into SCB account | E23: 3000 | F23: =F22+D23-E23 -> 10576
B24: 17/11/2025 | C24: BTA for Kenyan trip - Kolade | E24: 1120 | F24: =F23+D24-E24 -> 9456
B25: 17/11/2025 | C25: BTA for Kenyan trip - Samuel | E25: 890 | F25: =F24+D25-E25 -> 8566
B26: 17/11/2025 | C26: BTA for Kenyan trip - Jessica | E26: 890 | F26: =F25+D26-E26 -> 7676
B27: 24/11/2025 | C27: Nov management Allowance to Kolade | E27: 2000 | F27: =F26+D27-E27 -> 5676
B28: 24/11/2025 | C28: BTA refund by Kolade for Kenyan trip | D28: 420 | F28: =F27+D28-E28 -> 6096
B29: 30/11/2025 | C29: BTA refund by Jessica for Kenyan trip | D29: 310 | F29: =F28+D29-E29 -> 6406
B30: 45669 | C30: Dec Management Allowance - Frank | E30: 1000 | F30: =F29+D30-E30 -> 5406
B31: 45881 | C31: Cash withdrawn from Access | D31: 10000 | F31: =F30+D31-E31 -> 15406
B32: 16/12/2025 | C32: Nov Management allowance to Tobi | E32: 2000 | F32: =F31+D32-E32 -> 13406
B33: 16/12/2025 | C33: Dec Management allowance to Tobi | E33: 2000 | F33: =F32+D33-E33 -> 11406
B34: 16/12/2025 | C34: 13th month Management allowance to Tobi | E34: 1000 | F34: =F33+D34-E34 -> 10406
B35: 16/12/2025 | C35: Nov Management allowance to Lilian | E35: 2000 | F35: =F34+D35-E35 -> 8406
B36: 16/12/2025 | C36: Dec Management allowance to Lilian | E36: 2000 | F36: =F35+D36-E36 -> 6406
B37: 16/12/2025 | C37: 13th month Management allowance to Lilian | E37: 1000 | F37: =F36+D37-E37 -> 5406
B38: 16/12/2025 | C38: Dec Management allowance to Kolade | E38: 2000 | F38: =F37+D38-E38 -> 3406
B39: 16/12/2025 | C39: 13th month Management allowance to Kolade | E39: 1000 | F39: =F38+D39-E39 -> 2406
B40: 16/12/2025 | C40: Cash withdrawn from SCB | D40: 13000 | F40: =F39+D40-E40 -> 15406
B41: 16/12/2025 | C41: Nov Management allowance to Diyan | E41: 3250 | F41: =F40+D41-E41 -> 12156
B42: 16/12/2025 | C42: Dec Management allowance to Diyan | E42: 3250 | F42: =F41+D42-E42 -> 8906
...
