Workbook

Sheet Expense
D2: =SUM(D4:D35) -> 59186852 | E2: =SUM(G2:AC2) -> 59186852 | G2: =G38 -> 1500000 | H2: =H38 -> 16039879 | I2: =I38 -> 12148.63 | J2: =J38 -> 0 | K2: =K38 -> 0 | L2: =L38 -> 0 | M2: =M38 -> 0 | N2: =N38 -> 0 | ... AC2: =AC38 -> 0
A3: Column 1 | B3: Column 2 | C3: Column 3 | D3: Column 4 | E3: Total | G3: inter | H3: pay. batch | I3: bank charge | J3: NIMC Sponsorship | K3: Refund | L3: MWC REgistration | M3: Flight Ticket/Accommodation | N3: Tatvasoft | O3: Hotel/Acc | P3: Management Allowance | Q3: Office Supplies & Fuel | R3: Software Tools | S3: Shipping & Freight | T3: AWS | U3: UAE funding | V3: BTA | W3: Nimc consultancy fee | X3: VAT | Y3: WHT | Z3: Hosting | AA3: Salary | AB3: Paye | AC3: Bis Premises & Dev Levy
A4: OUTFLOWS | C4: FBN (PROJECT) | D4: 0 | E4: =SUM(G4:AC4) -> 0
A5: Interbank | B5: =G2 -> 1500000 | C5: FIDELITY | D5: 0 | E5: =SUM(G5:AC5) -> 0
A6: Payment Batches | B6: =H2 -> 16039879 | C6: POLARIS MAIN | D6: 0 | E6: =SUM(G6:AC6) -> 0
A7: =R3 -> Software Tools | B7: =R2 -> 3062831.8 | C7: POLARIS (OPERATIONS 1) | D7: 0 | E7: =SUM(G7:AC7) -> 0
A8: Nimc consultancy fee | B8: =W2 -> 36341100 | C8: POLARIS (OPERATIONS 2) | D8: 0 | E8: =SUM(G8:AC8) -> 0
A9: Salary | B9: =AA2 -> 857142.86 | C9: SCB | D9: 0 | E9: =SUM(G9:AC9) -> 0
A10: Office Supplies, Fuel & Letter Dispatch | B10: =Q2 -> 1373750 | C10: UBA Main | D10: 150 | E10: =SUM(G10:AC10) -> 150 | I10: 150
A11: Bank Charges | B11: =I2 -> 12148.63 | C11: UBA (PROJECT) | D11: 0 | E11: =SUM(G11:AC11) -> 0
C12: UBA (COLLECTION 1) | D12: 0 | E12: =SUM(G12:AC12) -> 0
C13: UBA (COLLECTION 2) | D13: 0 | E13: =SUM(G13:AC13) -> 0
C14: UBA APG | D14: 0 | E14: =SUM(G14:AC14) -> 0
C15: UNION BANK | D15: 0 | E15: =SUM(G15:AC15) -> 0
C16: ZENITH CALL 1 | D16: 0 | E16: =SUM(G16:AC16) -> 0
C17: ZENITH (SETTLEMENT) | D17: 0 | E17: =SUM(G17:AC17) -> 0
C18: GTB | D18: 9137.5 | E18: =SUM(G18:AC18) -> 9137.5 | I18: 9137.5
A19: Total | B19: =SUM(B5:B18) -> 59186852 | C19: GTB (Mastercard corporate debit) | D19: 219212.28 | E19: =SUM(G19:AC19) -> 219212.28 | R19: 219212.28
A20: Interbank | B20: =B5 -> 1500000 | C20: Access Bank Main A/C | D20: 54740983 | E20: =SUM(G20:AC20) -> 54740983 | G20: 1500000 | H20: 16039879 | I20: 2861.13 | W20: 36341100 | AA20: 857142.86
B21: =SUM(B19-B20) -> 57686852 | C21: Access Bank Salary A/C | D21: 0 | E21: =SUM(G21:AC21) -> 0
C22: Wema Card | D22: 1373750 | E22: =SUM(G22:AC22) -> 1373750 | Q22: 1373750
C23: Globus | D23: 0 | E23: =SUM(G23:AC23) -> 0
C24: MoMo Wallet | D24: 0 | E24: =SUM(G24:AC24) -> 0
D25: 0
C26: ZENITH (USD) | D26: 0 | E26: =SUM(G26:AB26) -> 0
C27: CASH IN HAND (USD) | D27: 0 | E27: =SUM(G27:AB27) -> 0
C28: CASH IN HAND (POUNDS) | D28: 0 | E28: =SUM(G28:AB28) -> 0
C29: CASH IN TRANSIT | D29: 0 | E29: =SUM(G29:AB29) -> 0
C30: GTB | D30: 0 | E30: =SUM(G30:AB30) -> 0
C31: GTB MASTERCARD CCC (DOLLAR) | D31: =2116.56*C36 -> 2843619.5 | E31: =SUM(G31:AB31) -> 2843619.5 | R31: =2116.56*C36 -> 2843619.5
C32: SCB | D32: 0 | E32: =SUM(G32:AB32) -> 0
C33: SCB Funding | D33: 0 | E33: =SUM(G33:AB33) -> 0
C34: UBA | D34: 0 | E34: =SUM(G34:AB34) -> 0
C35: Access USD | D35: 0 | E35: =SUM(G35:AB35) -> 0
C36: =Income!C36 -> 1343.51
D37: =SUM(D4:D35) -> 59186852 | E37: =SUM(E4:E35) -> 59186852
G38: =SUM(G4:G37) -> 1500000 | H38: =SUM(H4:H37) -> 16039879 | I38: =SUM(I4:I37) -> 12148.63 | J38: =SUM(J4:J37) -> 0 | K38: =SUM(K4:K37) -> 0 | L38: =SUM(L4:L37) -> 0 | M38: =SUM(M4:M37) -> 0 | N38: =SUM(N4:N37) -> 0 | ... AC38: =SUM(AC4:AC37) -> 0

Sheet Income
D2: =SUM(D4:D35) -> 33821507 | E2: =SUM(F2:AF2) -> 33821507 | F2: =F36 -> 1500000 | G2: =G36 -> 3175000 | H2: =H36 -> 0 | I2: =I36 -> 0 | J2: =J36 -> 0 | K2: =K36 -> 0 | L2: =L36 -> 0 | M2: =M36 -> 29146507 | ... Y2: =Y36
E3: Total | F3: Interbank | G3: Refund/Reversal | H3: idqr | I3: Investment Liquidation | J3: Insurance Claim | K3: MTN CIV Income | L3: Interest Earned | M3: NIMC Income | N3: iTranscript Income | O3: NextGen | P3: Loan Repayment | Q3: Insurance Claim | R3: MTN Income
A4: Inflows | C4: FBN (PROJECT) | D4: 0 | E4: =SUM(F4:W4) -> 0
A5: Interbank | B5: =F2 -> 1500000 | C5: FIDELITY | D5: 0 | E5: =SUM(F5:W5) -> 0
A6: Nimc Income | B6: =M2 -> 29146507 | C6: POLARIS MAIN | D6: 0 | E6: =SUM(F6:W6) -> 0
A7: Refund/Reversal | B7: =G2 -> 3175000 | C7: POLARIS (OPERATIONS 1) | D7: 0 | E7: =SUM(F7:W7) -> 0
A8: iTranscript Income | B8: =N2 -> 0 | C8: POLARIS (OPERATIONS 2) | D8: 0 | E8: =SUM(F8:W8) -> 0
C9: SCB | D9: 0 | E9: =SUM(F9:W9) -> 0
A10: MTN CIV Income | B10: =K2 -> 0 | C10: UBA MAIN | D10: 0 | E10: =SUM(F10:W10) -> 0
A11: NIMC Income | B11: =R2 -> 0 | C11: UBA Project | D11: 0 | E11: =SUM(F11:W11) -> 0
A12: Total | B12: =SUM(B5:B11) -> 33821507 | C12: UBA (COLLECTION 1) | D12: 0 | E12: =SUM(F12:W12) -> 0
B13: =B5 -> 1500000 | C13: UBA (COLLECTION 2) | D13: 0 | E13: =SUM(F13:W13) -> 0
B14: =B12-B13 -> 32321507 | C14: UBA APG | D14: 0 | E14: =SUM(F14:W14) -> 0
C15: UNION BANK | D15: 0 | E15: =SUM(F15:W15) -> 0
C16: ZENITH CALL 1 | D16: 0 | E16: =SUM(F16:W16) -> 0
C17: ZENITH (SETTLEMENT) | D17: 0 | E17: =SUM(F17:W17) -> 0
C18: GTB | D18: 3820000 | E18: =SUM(F18:W18) -> 3820000 | M18: 3820000
C19: GTB (Mastercard corporate debit) | D19: 0 | E19: =SUM(F19:W19) -> 0
C20: Access Bank Main A/C | D20: 3175000 | E20: =SUM(F20:W20) -> 3175000 | G20: 3175000
C21: Access Bank Salary A/C | D21: 0 | E21: =SUM(F21:W21) -> 0
C22: Wema Card | D22: 1500000 | E22: =SUM(F22:W22) -> 1500000 | F22: 1500000
C23: Globus | D23: 0 | E23: =SUM(F23:W23) -> 0
C24: MoMo Wallet | D24: 0 | E24: =SUM(F24:W24) -> 0
D25: 0 | E25: =SUM(F25:W25) -> 0
C26: ZENITH (USD) | D26: 0 | E26: =SUM(F26:W26) -> 0
C27: CASH IN HAND (USD) | D27: 0 | E27: =SUM(F27:W27) -> 0
C28: CASH IN HAND (POUNDS) | D28: 0 | E28: =SUM(F28:W28) -> 0
C29: CASH IN TRANSIT | D29: 0 | E29: =SUM(F29:W29) -> 0
C30: GTB | D30: =13051*C36 -> 17534149 | E30: =SUM(G30:W30) -> 17534149 | M30: =13051*C36 -> 17534149
C31: GTB MASTERCARD CCC (DOLLAR) | D31: 0 | E31: =SUM(F31:W31) -> 0
C32: SCB | D32: 0 | E32: =SUM(G32:W32) -> 0
C33: SCB Funding | D33: 0 | E33: =SUM(F33:W33) -> 0
C34: UBA | D34: 0 | E34: =SUM(F34:W34) -> 0
C35: Access USD | D35: =5800*C36 -> 7792358 | E35: =SUM(F35:W35) -> 7792358 | M35: =5800*C36 -> 7792358
C36: ='Cash Report'!E31 -> 1343.51 | D36: =SUM(D4:D35) -> 33821507 | E36: =SUM(E4:E35) -> 33821507 | F36: =SUM(F4:F35) -> 1500000 | G36: =SUM(G4:G35) -> 3175000 | H36: =SUM(H4:H35) -> 0 | I36: =SUM(I4:I35) -> 0 | J36: =SUM(J4:J35) -> 0 | K36: =SUM(K4:K35) -> 0 | ... W36: =SUM(W4:W35) -> 0

Sheet Cash Report
A1: sa
B2: SEAMFIX LIMITED
B3: CASH AND CASH EQUIVALENT REPORT AS AT 20TH FEBRUARY 2026
B4: CASH IN HAND AND BANK
B5: S/N | C5: Banks | D5: OPENING BALANCE | E5: EXCHANGE RATE | F5: OPENING BALANCE (NGN) | G5: INFLOW | H5: OUTFLOW | I5: NET DIFFERENCE | J5: CLOSING BALANCE | K5: Remarks
B6: 1 | C6: FBN (PROJECT) | D6: 1057208.4 | E6: 1 | F6: =D6*E6 -> 1057208.4 | G6: 0 | H6: 0 | I6: =G6-H6 -> 0 | J6: =F6+I6 -> 1057208.4 | K6: Inflow: Outflow:
B7: 2 | C7: FIDELITY | D7: 73124.13 | E7: 1 | F7: =D7*E7 -> 73124.13 | G7: 0 | H7: 0 | I7: =G7-H7 -> 0 | J7: =F7+I7 -> 73124.13 | K7: Inflow: Outflow:
B8: 3 | C8: POLARIS MAIN | D8: 1239057.9 | E8: 1 | F8: =D8*E8 -> 1239057.9 | G8: 0 | H8: 0 | I8: =G8-H8 -> 0 | J8: =F8+I8 -> 1239057.9 | K8: Inflow: Outflow:
B9: 4 | C9: POLARIS (OPERATIONS 1) | D9: 31493.46 | E9: 1 | F9: =D9*E9 -> 31493.46 | G9: 0 | H9: 0 | I9: =G9-H9 -> 0 | J9: =F9+I9 -> 31493.46 | K9: Inflow: Outflow:
B10: 5 | C10: POLARIS (OPERATIONS 2) | D10: 208999.86 | E10: 1 | F10: =D10*E10 -> 208999.86 | G10: 0 | H10: 0 | I10: =G10-H10 -> 0 | J10: =F10+I10 -> 208999.86 | K10: Inflow: Outflow:
B11: 6 | C11: SCB | D11: 2415181.7 | E11: 1 | F11: =D11*E11 -> 2415181.7 | G11: 0 | H11: 0 | I11: =G11-H11 -> 0 | J11: =F11+I11 -> 2415181.7 | K11: Inflow: Outflow:
B12: 7 | C12: UBA MAIN | D12: 3404395 | E12: 1 | F12: =D12*E12 -> 3404395 | G12: 0 | H12: 150 | I12: =G12-H12 -> -150 | J12: =F12+I12 -> 3404245 | K12: Inflow: Outflow: Bank Charges
B13: 8 | C13: UBA (PROJECT) | D13: 1169752.2 | E13: 1 | F13: =D13*E13 -> 1169752.2 | G13: 0 | H13: 0 | I13: =G13-H13 -> 0 | J13: =F13+I13 -> 1169752.2 | K13: Inflow: Outflow:
B14: 9 | C14: UBA (COLLECTION 1) | D14: 564653.84 | E14: 1 | F14: =D14*E14 -> 564653.84 | G14: 0 | H14: 0 | I14: =G14-H14 -> 0 | J14: =F14+I14 -> 564653.84 | K14: Inflow: Outflow:
B15: 10 | C15: UBA (COLLECTION 2) | D15: 745578.1 | E15: 1 | F15: =D15*E15 -> 745578.1 | G15: 0 | H15: 0 | I15: =G15-H15 -> 0 | J15: =F15+I15 -> 745578.1 | K15: Inflow: Outflow:
B16: 11 | C16: UBA APG | D16: 11745.64 | E16: 1 | F16: =D16*E16 -> 11745.64 | G16: 0 | H16: 0 | I16: =G16-H16 -> 0 | J16: =F16+I16 -> 11745.64 | K16: Inflow: Outflow:
B17: 12 | C17: UNION BANK | D17: 158755.71 | E17: 1 | F17: =D17*E17 -> 158755.71 | G17: 0 | H17: 0 | I17: =G17-H17 -> 0 | J17: =F17+I17 -> 158755.71 | K17: Inflow: Interbank transfer Outflow:
... B21: 16 | C21: GTB (Mastercard corporate debit) | D21: 3354397.2 | E21: 1 | F21: =D21*E21 -> 3354397.2 | G21: 0 | H21: 219212.28 | I21: =G21-H21 -> -219212.28 | J21: =F21+I21 -> 3135184.9 | K21: Inflows: Outflow: Hosting fee
A22: C | B22: 17 | C22: Access Bank Main A/C | D22: 75473702 | E22: 1 | F22: =D22*E22 -> 75473702 | G22: 3175000 | H22: 54740983 | I22: =G22-H22 -> -51565983 | J22: =F22+I22 -> 23907719 | K22: Inflow: Staff loan repayment Outflow: Payment Batch, Nimc Consultancy fee, salary & Bank charges
B23: 18 | C23: Access Bank Salary A/C | D23: 262736.66 | E23: 1 | F23: =D23*E23 -> 262736.66 | G23: 0 | H23: 0 | I23: =G23-H23 -> 0 | J23: =F23+I23 -> 262736.66 | K23: Inflows: Outflow: Bank charges
B24: 19 | C24: Wema | D24: 101797.4 | E24: 1 | F24: =D24*E24 -> 101797.4 | G24: 0 | H24: 0 | I24: =G24-H24 -> 0 | J24: =F24+I24 -> 101797.4 | K24: Inflow: Outflow:
B25: 20 | C25: Wema card A/c | D25: 1603511.9 | E25: 1 | F25: =D25*E25 -> 1603511.9 | G25: 1500000 | H25: 1373750 | I25: =G25-H25 -> 126250 | J25: =F25+I25 -> 1729761.9 | K25: Inflow: Interbank transfer Outflow:
B26: 21 | C26: Globus | D26: 990050.45 | E26: 1 | F26: =D26*E26 -> 990050.45 | G26: 0 | H26: 0 | I26: =G26-H26 -> 0 | J26: =F26+I26 -> 990050.45 | K26: Inflow: Outflow:
B27: 22 | C27: Momo Account | D27: 0 | E27: 1 | F27: =D27*E27 -> 0 | G27: 0 | H27: 0 | I27: =G27-H27 -> 0 | J27: =F27+I27 -> 0 | K27: Inflow: Outflow:
C28: TOTAL CASH (NGN) | D28: =SUM(D6:D27) -> 1.1521396e+08 | F28: =SUM(F6:F27) -> 1.1521396e+08 | G28: =SUM(G6:G27) -> 8495000 | H28: =SUM(H6:H27) -> 56343233 | I28: =SUM(I6:I27) -> -47848233 | J28: =SUM(J6:J27) -> 67365732 | K28: Inflow: Outflow:
B30: 23 | C30: CASH IN HAND (POUNDS) | D30: 2525 | E30: 1810.4 | F30: =D30*E30 -> 4571260 | G30: 0 | H30: 0 | I30: =G30-H30 -> 0 | J30: =F30+I30 -> 4571260 | K30: Inflow: Outflow:
B31: 24 | C31: ZENITH BANK (USD) | D31: 5855.86 | E31: 1343.51 | F31: =D31*E31 -> 7867406.5 | G31: 0 | H31: 0 | I31: =G31-H31 -> 0 | J31: =F31+I31 -> 7867406.5 | K31: Inflow: Outflow:
B32: 25 | C32: CASH IN HAND (USD) | D32: 5946 | E32: =$E$31 -> 1343.51 | F32: =D32*E32 -> 7988510.5 | G32: 0 | H32: 0 | I32: =G32-H32 -> 0 | J32: =F32+I32 -> 7988510.5 | K32: Inflow: Outflow:
B33: 26 | C33: CASH IN TRANSIT | D33: 0 | E33: =$E$31 -> 1343.51 | F33: =D33*E33 -> 0 | G33: 0 | H33: 0 | I33: =G33-H33 -> 0 | J33: =F33+I33 -> 0 | K33: Inflow: Outflow:
B34: 27 | C34: GTB MAIN (USD) | D34: 111121.16 | E34: =$E$31 -> 1343.51 | F34: =D34*E34 -> 1.4929239e+08 | G34: =13051*E34 -> 17534149 | H34: 0 | I34: =G34-H34 -> 17534149 | J34: =F34+I34 -> 1.6682654e+08 | K34: Inflow:Nimc Income Outflow:
B35: 28 | C35: GTB DEBIT CARD (USD) | D35: 12237.1 | E35: =$E$31 -> 1343.51 | F35: =D35*E35 -> 16440666 | G35: 0 | H35: =2116.56*E35 -> 2843619.5 | I35: =G35-H35 -> -2843619.5 | J35: =F35+I35 -> 13597047 | K35: Inflow: Outflow:Software Tools
B36: 29 | C36: SCB | D36: 47346.38 | E36: =$E$31 -> 1343.51 | F36: =D36*E36 -> 63610335 | G36: 0 | H36: 0 | I36: =G36-H36 -> 0 | J36: =F36+I36 -> 63610335 | K36: Inflow: Outflow:
B37: 30 | C37: UBA | D37: 13405.91 | E37: =$E$31 -> 1343.51 | F37: =D37*E37 -> 18010974 | G37: 0 | H37: 0 | I37: =G37-H37 -> 0 | J37: =F37+I37 -> 18010974 | K37: Inflow: Outflow:
B38: 31 | C38: Access USD | D38: 59462.26 | E38: =$E$31 -> 1343.51 | F38: =D38*E38 -> 79888141 | G38: =5800*E38 -> 7792358 | H38: 0 | I38: =G38-H38 -> 7792358 | J38: =F38+I38 -> 87680499 | K38: Inflow: NIMC Income Outflow:
B39: TOTAL CASH (USD | D39: =SUM(D31:D38) -> 255374.67 | E39: =$E$31 -> 1343.51 | F39: =SUM(F31:F38) -> 3.4309842e+08 | G39: =SUM(G31:G38) -> 25326507 | H39: =SUM(H31:H38) -> 2843619.5 | I39: =SUM(I31:I38) -> 22482887 | J39: =SUM(J31:J38) -> 3.6558131e+08
B43: TOTAL INVESTMENTS (NGN)
C44: INVESTMENT HOUSE | D44: OPENING BALANCE (PRINCIPAL & iNTEREST PAID | E44: EXCHANGE RATE | F44: OPENING BALANCE (NGN) | G44: INFLOW | H44: OUTFLOW | I44: NET DIFFERENCE | J44: CLOSING BALANCE | K44: COMMENTS
B45: 29 | C45: STANBIC IBTC | D45: 7565289.3 | E45: 1 | F45: =D45*E45 -> 7565289.3 | G45: 0 | H45: 0 | I45: =G45-H45 -> 0 | J45: =F45+G45-H45 -> 7565289.3
B46: =B45+1 -> 30 | C46: FBN QUEST | D46: 9255303.4 | E46: 1 | F46: =D46*E46 -> 9255303.4 | G46: 0 | H46: 0 | I46: =G46-H46 -> 0 | J46: =F46+G46-H46 -> 9255303.4
B47: 32 | C47: CORDROS MMF | D47: 7786750.6 | E47: 1 | F47: =D47*E47 -> 7786750.6 | G47: 0 | H47: 0 | I47: =G47-H47 -> 0 | J47: =F47+G47-H47 -> 7786750.6
...

Sheet Breakdown of Income and Expendi
G2: CASH REPORT - 20TH FEBRUARY 2026
B3: Inflows: | C3: Amount | D3: % Ratio | G3: Details | H3: Amount | I3: Exc rate | J3: Naira Equivalent
B4: Nimc Income | C4: 29146507 | D4: =C4/$C$6 -> 0.90176819 | G4: Opening Balance- 14th Feb NGN | H4: ='Cash Report'!F28 -> 1.1521396e+08 | I4: 1 | J4: =H4*I4 -> 1.1521396e+08
B5: Staff Loan Repayment | C5: 3175000 | D5: =C5/$C$6 -> 0.098231806 | G5: Opening Balance- 14th Feb USD | H5: ='Cash Report'!D39 -> 255374.67 | I5: ='Cash Report'!$E$31 -> 1343.51 | J5: =H5*I5 -> 3.4309842e+08
B6: Total Cash Inflows for the week | C6: =sum(C4:C5) -> 32321507 | D6: =C6/$C$6*100 -> 100 | G6: Opening Balance- 14th Feb GBP | H6: 2525 | I6: ='Cash Report'!E30 -> 1810.4 | J6: =H6*I6 -> 4571260
B8: OUTFLOWS | C8: Amount | D8: % Ratio | G8: Total Opening Balance | J8: =J4+J5+J6 -> 4.6288365e+08
B9: Payment Batches | C9: 16039879 | D9: =C9/C$15*100 -> 27.805086
B10: Software Tools | C10: 3062831.8 | D10: =C10/C$15*100 -> 5.3094106 | G10: INFLOWS | H10: Amount | I10: % Ratio
B11: Nimc consultancy fee | C11: 36341100 | D11: =C11/C$15*100 -> 62.997197 | G11: Nimc Income | H11: 29146507 | I11: =H11/$C$6 -> 0.90176819
B12: Salary | C12: 857142.86 | D12: =C12/C$15*100 -> 1.4858548 | G12: Staff Loan Repayment | H12: 3175000 | I12: =H12/$C$6 -> 0.098231806
B13: Office Supplies, Fuel & Letter Dispatch | C13: 1373750 | D13: =C13/C$15*100 -> 2.3813919 | H13: =SUM(H11:H12) -> 32321507 | I13: =H13/$H$13*100 -> 100 | J13: =H13 -> 32321507
B14: Bank Charges | C14: 12148.63 | D14: =C14/C$15*100 -> 0.021059617 | G14: TOTAL CASH BALANCE BEFORE OUTFLOWS | J14: =SUM(J8:J13) -> 4.9520515e+08
B15: Total Cash Outflow for the week | C15: =SUM(C9:C14) -> 57686852 | D15: =SUM(D9:D14) -> 100
B16: Net Cash Inflow for the Week | C16: =C6-C15 -> -25365345 | G16: OUTFLOWS | I16: % Ratio
G17: Payment Batches | H17: 16039879 | I17: 27.805086
G18: Software Tools | H18: 3062831.8 | I18: 5.3094106
G19: Nimc consultancy fee | H19: 36341100 | I19: 62.997197
G20: Salary | H20: 857142.86 | I20: 1.4858548
G21: Office Supplies, Fuel & Letter Dispatch | H21: 1373750 | I21: 2.3813919
G22: Bank Charges | H22: 12148.63 | I22: 0.021059617
H23: =SUM(H17:H22) -> 57686852 | I23: =sum(I17:I22) -> 100 | J23: =H23 -> 57686852
G24: CASH BALANCE AS AT 20TH FEB 2026 | J24: =J14-J23 -> 4.375183e+08
G26: Breakdown of Alitheia Investment Balance held in SCB
G27: Opening Balance | H27: 768.94 | I27: ='Cash Report'!$E$31 -> 1343.51 | J27: =H27*I27 -> 1033078.6
G29: Closing Balance | H29: =SUM(H27) -> 768.94 | I29: ='Cash Report'!$E$31 -> 1343.51 | J29: =H29*I29 -> 1033078.6
G32: BREAKDOWN OF PAYMENT BATCH FOR THE WEEK
G33: Beneficiary Names | H33: Amount (N) | I33: Description
G34: Henrich Gold Global Concept | H34: 35000 | I34: Purchase of toner for the printer in ESUT
G35: Johnbosco Obiekwe | H35: 160000 | I35: Staff advance to Johnbosco for ESUT operations
G36: Elohimtech Gadgets and ICT Services | H36: 40000 | I36: Replacement of Christian Okoro Laptop battery in Enugu
G37: Elohimtech Gadgets and ICT Services | H37: 48000 | I37: Replacemebt elitebook batthery and purchase of 4 mouse(ESUT)
G38: Shuttlers | H38: 1570909.2 | I38: Staff Shuttlers Services for Jan 2026
G39: Flyforvalue Aviation Ltd-Collection Account | H39: 1000000 | I39: Funding of Valuejet wallet
G40: Quickfix Engineering Ltd | H40: 754325 | I40: Replacement of 5kva/48v Hybrid Inverter for the main office
G41: Frank Atube | H41: 38200 | I41: Refund for expenses made during Abuja trip (21st - 23rd Jan 2026)
G42: Ademola Koledoye | H42: 352245.8 | I42: Refund for Anthropic subscription and domain registration
G43: Foldage Global Resources | H43: 35000 | I43: Replacement of Elite book Keyboard (Retrieved from Chidinma)
G44: Fagbamila Dolapo | H44: 150000 | I44: 2026 Radio & TV permit'
G45: Mankind Global | H45: 40000 | I45: Replacement MacBook Air charger for Miracle
... G47: Reliance HMO Ltd | H47: 115698.72 | I47: Payment to Reliance HMO
...

Sheet Cash Balance Summary 
B2: BREAKDOWN OF SEAMFIX CASH BALANCES AS AT 20TH FEB 2026
B3: Cash Balances | C3: Amount (Naira) | D3: Amount (USD) | E3: Amount (GBP) | F3: Exchange rate | G3: Naira Equivalent
B4: Seamfix operational A/c balances (Naira) | C4: ='Cash Report'!D64 -> 67365732 | D4: 0 | E4: 0 | F4: 1 | G4: =C4*F4 -> 67365732
B5: Seamfix operational A/c balances (USD) | C5: 0 | D5: ='Cash Report'!D65 -> 272109.11 | E5: 0 | F5: ='Cash Report'!$E$31 -> 1343.51 | G5: ='Cash Report'!J39 -> 3.6558131e+08
B6: Seamfix operational A/c balances (GBP) | C6: 0 | D6: 0 | E6: ='Cash Report'!D66 -> 2525 | F6: ='Cash Report'!E30 -> 1810.4 | G6: ='Cash Report'!F66 -> 4571260
B7: Alitheia funds in the SCB funding a/c | C7: 0 | D7: ='Breakdown of Income and Expendi'!H29 -> 768.94 | E7: 0 | F7: ='Cash Report'!$E$31 -> 1343.51 | G7: =D7*F7 -> 1033078.6
B8: TOTAL | C8: =SUM(C4:C7) -> 67365732 | D8: =SUM(D4:D7) -> 272878.05 | E8: =SUM(E4:E7) -> 2525 | G8: =SUM(G4:G7) -> 4.3855138e+08
B12: BREAKDOWN OF AIF INVESTMENT FUND
B13: Investment House | C13: Principal | D13: Interest | E13: Total | F13: Maturity Date | G13: Investment Type | H13: Comment
B14: Stanbic IBTC Asset Management | C14: =59500-59500 -> 0 | D14: 689.68 | E14: =SUM(C14:D14) -> 689.68 | F14: N/A | G14: Mutual Fund
B15: Cardinal Stone Asset Management Ltd | C15: =752544.4-123000-60000 -> 569544.4 | D15: 131209.01 | E15: =SUM(C15:D15) -> 700753.41 | F15: N/A | G15: Mutual Fund
B16: FBNQuest Asset management | C16: 111975.35 | D16: 1089.64 | E16: =SUM(C16:D16) -> 113064.99 | F16: N/A | G16: Mutual Fund
B17: FBN Quest & Stanbic Investment | C17: 45314.87 | D17: 32146.39 | E17: =SUM(C17:D17) -> 77461.26 | F17: N/A | G17: Mutual Fund | H17: This is held in Naira with FBN and Stanbic. Naira equivalent is N103.5m
B18: Absa Bank | C18: 528300 | D18: 0 | E18: =SUM(C18:D18) -> 528300
B19: SCB Investment/Funding A/c Balance | C19: 769 | D19: 0 | E19: =SUM(C19:D19) -> 769 | F19: N/A | G19: N/A
C20: =SUM(C14:C19) -> 1255903.6 | D20: =SUM(D14:D19) -> 165134.72 | E20: =SUM(E14:E19) -> 1421038.3
B23: BREAKDOWN OF OTHER DOLLAR INVESTMENT
B24: Investment House | C24: Principal | D24: Interest | E24: Total | F24: Maturity Date | G24: Investment Type | H24: Comment
B25: FBNQuest Asset Management | C25: 38400 | D25: 2412.35 | E25: =C25+D25 -> 40812.35 | F25: N/A | G25: Mutual Fund | H25: Earmarked for MinIo/Glo project licenses.
B26: Total USD Investments | C26: =SUM(C25) -> 38400 | D26: =SUM(D25) -> 2412.35 | E26: =SUM(E25) -> 40812.35
B29: BREAKDOWN OF OTHER NAIRA INVESTMENTS
B30: Investment House | C30: Principal | D30: Interest | E30: Total | F30: Maturity Date | G30: Investment Type | H30: Comment
B31: FBN Mutual Fund | C31: 0 | D31: 9255303.4 | E31: =C31+D31 -> 9255303.4 | F31: N/A | G31: Mutual Fund
B32: CORDROS MMF | C32: 5000000 | D32: 2786750.6 | E32: =C32+D32 -> 7786750.6 | F32: N/A | G32: Mutual Fund
B33: Total Naira Investments | C33: =SUM(C31:C32) -> 5000000 | D33: =SUM(D31:D32) -> 12042054 | E33: =SUM(E31:E32) -> 17042054
B36: MARKET VALUE OF MTN SHARES
B37: Investment date | G37: 44531
B38: Invested Amount | G38: 20280000
B39: Market value as at 22nd | G39: 93795000

Sheet Cash Utilizations from Safe
B2: USAGE OF LAST FOUR CASH WITHDRAWALS FOR SAFE
B4: Date | C4: Description | D4: Inflow | E4: Outflow | F4: Balance
B5: 45788 | C5: Balance brought forward from 5th Nov 2025 | F5: 4646
B6: 45819 | C6: Cash withdrwan from GTBank | D6: 20000 | F6: =F5+D6-E6 -> 24646
B7: 45819 | C7: Oct 2025 Management allowance - Lilian | E7: 2000 | F7: =F6+D7-E7 -> 22646
B8: 45819 | C8: Oct 2025 Management allowance - Tobi | E8: 2000 | F8: =F7+D8-E8 -> 20646
B9: 45819 | C9: Oct 2025 Management allowance - Kolade | E9: 2000 | F9: =F8+D9-E9 -> 18646
B10: 45819 | C10: Oct 2025 Management allowance - Diyan | E10: 3250 | F10: =F9+D10-E10 -> 15396
B11: 45819 | C11: BTA refund from Kolade for Kigali Trip | D11: 500 | F11: =F10+D11-E11 -> 15896
B12: 45819 | C12: BTA for South African trip - Chimezie | E12: 700 | F12: =F11+D12-E12 -> 15196
B13: 45819 | C13: BTA for South African trip - Frank | E13: 1620 | F13: =F12+D13-E13 -> 13576
B14: 45819 | C14: Cash deposit into SCB account | E14: 3000 | F14: =F13+D14-E14 -> 10576
B15: 17/11/2025 | C15: BTA for Kenyan trip - Kolade | E15: 1120 | F15: =F14+D15-E15 -> 9456
B16: 17/11/2025 | C16: BTA for Kenyan trip - Samuel | E16: 890 | F16: =F15+D16-E16 -> 8566
B17: 17/11/2025 | C17: BTA for Kenyan trip - Jessica | E17: 890 | F17: =F16+D17-E17 -> 7676
B18: 24/11/2025 | C18: Nov management Allowance to Kolade | E18: 2000 | F18: =F17+D18-E18 -> 5676
B19: 24/11/2025 | C19: BTA refund by Kolade for Kenyan trip | D19: 420 | F19: =F18+D19-E19 -> 6096
B20: 30/11/2025 | C20: BTA refund by Jessica for Kenyan trip | D20: 310 | F20: =F19+D20-E20 -> 6406
B21: 45669 | C21: Dec Management Allowance - Frank | E21: 1000 | F21: =F20+D21-E21 -> 5406
B22: 45881 | C22: Cash withdrawn from Access | D22: 10000 | F22: =F21+D22-E22 -> 15406
B23: 16/12/2025 | C23: Nov Management allowance to Tobi | E23: 2000 | F23: =F22+D23-E23 -> 13406
B24: 16/12/2025 | C24: Dec Management allowance to Tobi | E24: 2000 | F24: =F23+D24-E24 -> 11406
B25: 16/12/2025 | C25: 13th month Management allowance to Tobi | E25: 1000 | F25: =F24+D25-E25 -> 10406
B26: 16/12/2025 | C26: Nov Management allowance to Lilian | E26: 2000 | F26: =F25+D26-E26 -> 8406
B27: 16/12/2025 | C27: Dec Management allowance to Lilian | E27: 2000 | F27: =F26+D27-E27 -> 6406
B28: 16/12/2025 | C28: 13th month Management allowance to Lilian | E28: 1000 | F28: =F27+D28-E28 -> 5406
B29: 16/12/2025 | C29: Dec Management allowance to Kolade | E29: 2000 | F29: =F28+D29-E29 -> 3406
B30: 16/12/2025 | C30: 13th month Management allowance to Kolade | E30: 1000 | F30: =F29+D30-E30 -> 2406
B31: 16/12/2025 | C31: Cash withdrawn from SCB | D31: 13000 | F31: =F30+D31-E31 -> 15406
B32: 16/12/2025 | C32: Nov Management allowance to Diyan | E32: 3250 | F32: =F31+D32-E32 -> 12156
B33: 16/12/2025 | C33: Dec Management allowance to Diyan | E33: 3250 | F33: =F32+D33-E33 -> 8906
B34: 16/12/2025 | C34: 13th month Management allowance to Diyan | E34: 1625 | F34: =F33+D34-E34 -> 7281
B35: 24/12/2025 | C35: Cash deposit in SCB | E35: 5300 | F35: =F34+D35-E35 -> 1981
B36: 46235 | C36: BTA to Frank Atube for Abidjan Trip | E36: 1280 | F36: =F35+D36-E36 -> 701
B37: 23/01/2026 | C37: Cash withdrawn from GTbank | D37: 22000 | F37: =F36+D37-E37 -> 22701
B38: 23/01/2026 | C38: Part payment of Jan Management allowance - Lilian | E38: 500 | F38: =F37+D38-E38 -> 22201
B39: 27/01/2026 | C39: Jan Management allowance - Lilian balance | E39: 1500 | F39: =F38+D39-E39 -> 20701
B40: 27/01/2026 | C40: Jan Management allowance - Frank | E40: 3500 | F40: =F39+D40-E40 -> 17201
B41: 27/01/2026 | C41: Jan Management allowance - Kolade | E41: 2000 | F41: =F40+D41-E41 -> 15201
B42: 27/01/2026 | C42: Jan Management allowance - Diyan | E42: 4500 | F42: =F41+D42-E42 -> 10701
...
