Workbook

Sheet Expense
D2: =SUM(D4:D35) -> 7.8395306e+08 | E2: =SUM(G2:AC2) -> 7.8395306e+08 | G2: =G38 -> 659321680 | H2: =H38 -> 15115115 | I2: =I38 -> 17721102 | J2: =J38 -> 30322.5 | K2: =K38 -> 0 | L2: =L38 -> 0 | M2: =M38 -> 4775676.5 | N2: =N38 -> 0 | ... AC2: =AC38 -> 0
A3: Column 1 | B3: Column 2 | C3: Column 3 | D3: Column 4 | E3: Total | G3: inter | H3: pay. batch | I3: bank charge | J3: NSITF | K3: Refund | L3: ID4Africa Registration | M3: Flight Ticket/Accommodation | N3: Tatvasoft | O3: Pension | P3: Management Allowance | Q3: Office Supplies & Fuel | R3: Software Tools | S3: Shipping & Freight | T3: AWS | U3: Bind | V3: BTA | W3: Nimc consultancy fee | X3: VAT | Y3: WHT | Z3: Hosting | AA3: Salary | AB3: Paye | AC3: Bis Premises & Dev Levy
A4: OUTFLOWS | C4: FBN (PROJECT) | D4: 0 | E4: =SUM(G4:AC4) -> 0
A5: Interbank | B5: =G2 -> 659321680 | C5: FIDELITY | D5: 0 | E5: =SUM(G5:AC5) -> 0
A6: Payment Batches | B6: =H2 -> 15115115 | C6: POLARIS MAIN | D6: 0 | E6: =SUM(G6:AC6) -> 0
A7: =R3 -> Software Tools | B7: =R2 -> 2955236 | C7: POLARIS (OPERATIONS 1) | D7: 0 | E7: =SUM(G7:AC7) -> 0
A8: Flight Ticket/Accommodation | B8: =M2 -> 4775676.5 | C8: POLARIS (OPERATIONS 2) | D8: 0 | E8: =SUM(G8:AC8) -> 0
A9: NSITF Contributions | B9: =J2 -> 30322.5 | C9: SCB | D9: 302048.69 | E9: =SUM(G9:AC9) -> 302048.69 | I9: 302048.69
A10: Bind Creative | B10: =U2 -> 81962700 | C10: UBA Main | D10: 6 | E10: =SUM(G10:AC10) -> 6 | I10: 6
A11: BTA | B11: =V2 -> 1087078.2 | C11: UBA (PROJECT) | D11: 0 | E11: =SUM(G11:AC11) -> 0
A12: Management Allowance | B12: =P2 -> 209053.5 | C12: UBA (COLLECTION 1) | D12: 0 | E12: =SUM(G12:AC12) -> 0
A13: Bank Charges | B13: =I2 -> 17721102 | C13: UBA (COLLECTION 2) | D13: 0 | E13: =SUM(G13:AC13) -> 0
A14: Office Supplies, Fuel & Letter Dispatch | B14: =Q2 -> 775092 | C14: UBA APG | D14: 0 | E14: =SUM(G14:AC14) -> 0
C15: UNION BANK | D15: 0 | E15: =SUM(G15:AC15) -> 0
C16: ZENITH CALL 1 | D16: 0 | E16: =SUM(G16:AC16) -> 0
A17: Refund | B17: =K2 -> 0 | C17: ZENITH (SETTLEMENT) | D17: 0 | E17: =SUM(G17:AC17) -> 0
C18: GTB | D18: 0 | E18: =SUM(G18:AC18) -> 0
A19: Total | B19: =SUM(B5:B18) -> 7.8395306e+08 | C19: GTB (Mastercard corporate debit) | D19: 3123522.5 | E19: =SUM(G19:AC19) -> 3123522.5 | J19: 30322.5 | M19: 3093200
A20: Interbank | B20: =B5 -> 659321680 | C20: Access Bank Main A/C | D20: 16617330 | E20: =SUM(G20:AC20) -> 16617330 | G20: 1500000 | H20: 15115115 | I20: 2215
B21: =SUM(B19-B20) -> 1.2463138e+08 | C21: Access Bank Salary A/C | D21: 0 | E21: =SUM(G21:AC21) -> 0
C22: Wema Card | D22: 775092 | E22: =SUM(G22:AC22) -> 775092 | Q22: 775092
C23: Globus | D23: 0 | E23: =SUM(G23:AC23) -> 0
C24: MoMo Wallet | D24: 0 | E24: =SUM(G24:AC24) -> 0
D25: 0 | E25: =SUM(G25:AC25) -> 0
C26: ZENITH (USD) | D26: 0 | E26: =SUM(G26:AC26) -> 0
C27: CASH IN HAND (USD) | D27: =930*C36 -> 1296131.7 | E27: =SUM(G27:AC27) -> 1296131.7 | P27: =150*C36 -> 209053.5 | V27: =780*C36 -> 1087078.2
C28: CASH IN HAND (POUNDS) | D28: 0 | E28: =SUM(G28:AC28) -> 0
C29: CASH IN TRANSIT | D29: 0 | E29: =SUM(G29:AC29) -> 0
C30: GTB | D30: =7000*C36 -> 9755830 | E30: =SUM(G30:AC30) -> 9755830 | G30: =7000*C36 -> 9755830
C31: GTB MASTERCARD CCC (DOLLAR) | D31: =3327.65*C36 -> 4637712.5 | E31: =SUM(G31:AC31) -> 4637712.5 | M31: =1207.21*C36 -> 1682476.5 | R31: =2120.44*C36 -> 2955236
C32: SCB | D32: =536306.77*Income!C36 -> 7.4744538e+08 | E32: =SUM(G32:AC32) -> 7.4744538e+08 | G32: =465000*Income!C36 -> 648065850 | I32: =12496.92*C36 -> 17416832 | U32: =58809.85*C36 -> 81962700
C33: SCB Funding | D33: 0 | E33: =SUM(G33:AC33) -> 0
C34: UBA | D34: 0 | E34: =SUM(G34:AC34) -> 0
C35: Access USD | D35: 0 | E35: =SUM(G35:AC35) -> 0
C36: =Income!C36 -> 1393.69
D37: =SUM(D4:D35) -> 7.8395306e+08 | E37: =SUM(E4:E35) -> 7.8395306e+08
G38: =SUM(G4:G37) -> 659321680 | H38: =SUM(H4:H37) -> 15115115 | I38: =SUM(I4:I37) -> 17721102 | J38: =SUM(J4:J37) -> 30322.5 | K38: =SUM(K4:K37) -> 0 | L38: =SUM(L4:L37) -> 0 | M38: =SUM(M4:M37) -> 4775676.5 | N38: =SUM(N4:N37) -> 0 | ... AC38: =SUM(AC4:AC37) -> 0

Sheet Income
D2: =SUM(D4:D35) -> 2.4148745e+08 | E2: =SUM(F2:AF2) -> 2.4148745e+08 | F2: =F36 -> 11255830 | G2: =G36 -> 5020 | H2: =H36 -> 11483.5 | I2: =I36 -> 0 | J2: =J36 -> 195000 | K2: =K36 -> 156735000 | L2: =L36 -> 0 | M2: =M36 -> 73143608 | ... Y2: =Y36
E3: Total | F3: Interbank | G3: Refund/Reversal | H3: idqr | I3: Investment Liquidation | J3: Int'l Women Day Donations | K3: Glo Income | L3: Interest Earned | M3: NIMC Income | N3: iTranscript Income | O3: NextGen | P3: Loan Repayment | Q3: Insurance Claim | R3: MTN Income
A4: Inflows | C4: FBN (PROJECT) | D4: 156735000 | E4: =SUM(F4:W4) -> 156735000 | K4: 156735000
A5: Interbank | B5: =F2 -> 11255830 | C5: FIDELITY | D5: 0 | E5: =SUM(F5:W5) -> 0
A6: Nimc Income | B6: =M2 -> 73143608 | C6: POLARIS MAIN | D6: 0 | E6: =SUM(F6:W6) -> 0
A7: Refund/Reversal | B7: =G2 -> 5020 | C7: POLARIS (OPERATIONS 1) | D7: 0 | E7: =SUM(F7:W7) -> 0
A8: IDQR Income | B8: =H2 -> 11483.5 | C8: POLARIS (OPERATIONS 2) | D8: 0 | E8: =SUM(F8:W8) -> 0
A9: Glo Income | B9: =K2 -> 156735000 | C9: SCB | D9: 0 | E9: =SUM(F9:W9) -> 0
A10: Int'l Weman Day Donations | B10: =J2 -> 195000 | C10: UBA MAIN | D10: 11483.5 | E10: =SUM(F10:W10) -> 11483.5 | H10: 11483.5
A11: iTranscript Income | B11: =N2 -> 141512.38 | C11: UBA Project | D11: 0 | E11: =SUM(F11:W11) -> 0
A12: Total | B12: =SUM(B5:B11) -> 2.4148745e+08 | C12: UBA (COLLECTION 1) | D12: 0 | E12: =SUM(F12:W12) -> 0
B13: =B5 -> 11255830 | C13: UBA (COLLECTION 2) | D13: 0 | E13: =SUM(F13:W13) -> 0
B14: =B12-B13 -> 2.3023162e+08 | C14: UBA APG | D14: 0 | E14: =SUM(F14:W14) -> 0
C15: UNION BANK | D15: 0 | E15: =SUM(F15:W15) -> 0
C16: ZENITH CALL 1 | D16: 903 | E16: =SUM(F16:W16) -> 903 | N16: 903
C17: ZENITH (SETTLEMENT) | D17: 0 | E17: =SUM(F17:W17) -> 0
C18: GTB | D18: 40810000 | E18: =SUM(F18:W18) -> 40810000 | M18: 40810000
C19: GTB (Mastercard corporate debit) | E19: =SUM(F19:W19) -> 0
C20: Access Bank Main A/C | D20: 5020 | E20: =SUM(F20:W20) -> 5020 | G20: 5020
C21: Access Bank Salary A/C | D21: 195000 | E21: =SUM(F21:W21) -> 195000 | J21: 195000
C22: Wema Card | D22: 1500000 | E22: =SUM(F22:W22) -> 1500000 | F22: 1500000
C23: Globus | D23: 0 | E23: =SUM(F23:W23) -> 0
C24: MoMo Wallet | D24: 0 | E24: =SUM(F24:W24) -> 0
D25: 0 | E25: =SUM(F25:W25) -> 0
C26: ZENITH (USD) | D26: =4100.89*C36 -> 5715369.4 | E26: =SUM(F26:W26) -> 5715369.4 | M26: =4000*C36 -> 5574760 | N26: =100.89*C36 -> 140609.38
C27: CASH IN HAND (USD) | D27: 0 | E27: =SUM(F27:W27) -> 0
C28: CASH IN HAND (POUNDS) | D28: 0 | E28: =SUM(F28:W28) -> 0
C29: CASH IN TRANSIT | D29: 0 | E29: =SUM(F29:W29) -> 0
C30: GTB | D30: =12900*C36 -> 17978601 | E30: =SUM(G30:W30) -> 17978601 | M30: =12900*C36 -> 17978601
C31: GTB MASTERCARD CCC (DOLLAR) | D31: =7000*C36 -> 9755830 | E31: =SUM(F31:W31) -> 9755830 | F31: =7000*C36 -> 9755830
C32: SCB | E32: =SUM(G32:W32) -> 0
C33: SCB Funding | D33: 0 | E33: =SUM(F33:W33) -> 0
C34: UBA | D34: 0 | E34: =SUM(F34:W34) -> 0
C35: Access USD | D35: =6300*C36 -> 8780247 | E35: =SUM(F35:W35) -> 8780247 | M35: =6300*C36 -> 8780247
C36: ='Cash Report'!E31 -> 1393.69 | D36: =SUM(D4:D35) -> 2.4148745e+08 | E36: =SUM(E4:E35) -> 2.4148745e+08 | F36: =SUM(F4:F35) -> 11255830 | G36: =SUM(G4:G35) -> 5020 | H36: =SUM(H4:H35) -> 11483.5 | I36: =SUM(I4:I35) -> 0 | J36: =SUM(J4:J35) -> 195000 | K36: =SUM(K4:K35) -> 156735000 | ... W36: =SUM(W4:W35) -> 0

Sheet Cash Report
A1: sa
B2: SEAMFIX LIMITED
B3: CASH AND CASH EQUIVALENT REPORT AS AT 13TH MARCH 2026
B4: CASH IN HAND AND BANK
B5: S/N | C5: Banks | D5: OPENING BALANCE | E5: EXCHANGE RATE | F5: OPENING BALANCE (NGN) | G5: INFLOW | H5: OUTFLOW | I5: NET DIFFERENCE | J5: CLOSING BALANCE | K5: Remarks
B6: 1 | C6: FBN (PROJECT) | D6: 1057208.4 | E6: 1 | F6: =D6*E6 -> 1057208.4 | G6: 156735000 | H6: 0 | I6: =G6-H6 -> 156735000 | J6: =F6+I6 -> 1.5779221e+08 | K6: Inflow: Glo Income Outflow:
B7: 2 | C7: FIDELITY | D7: 73124.13 | E7: 1 | F7: =D7*E7 -> 73124.13 | G7: 0 | H7: 0 | I7: =G7-H7 -> 0 | J7: =F7+I7 -> 73124.13 | K7: Inflow: Outflow:
B8: 3 | C8: POLARIS MAIN | D8: 1239057.9 | E8: 1 | F8: =D8*E8 -> 1239057.9 | G8: 0 | H8: 0 | I8: =G8-H8 -> 0 | J8: =F8+I8 -> 1239057.9 | K8: Inflow: Outflow:
B9: 4 | C9: POLARIS (OPERATIONS 1) | D9: 31493.46 | E9: 1 | F9: =D9*E9 -> 31493.46 | G9: 0 | H9: 0 | I9: =G9-H9 -> 0 | J9: =F9+I9 -> 31493.46 | K9: Inflow: Outflow:
B10: 5 | C10: POLARIS (OPERATIONS 2) | D10: 208999.86 | E10: 1 | F10: =D10*E10 -> 208999.86 | G10: 0 | H10: 0 | I10: =G10-H10 -> 0 | J10: =F10+I10 -> 208999.86 | K10: Inflow: Outflow:
B11: 6 | C11: SCB | D11: 2163710.7 | E11: 1 | F11: =D11*E11 -> 2163710.7 | G11: 0 | H11: 302048.69 | I11: =G11-H11 -> -302048.69 | J11: =F11+I11 -> 1861662 | K11: Inflow: Outflow: Bank Charges
B12: 7 | C12: UBA MAIN | D12: 3414395.7 | E12: 1 | F12: =D12*E12 -> 3414395.7 | G12: 11483.5 | H12: 6 | I12: =G12-H12 -> 11477.5 | J12: =F12+I12 -> 3425873.2 | K12: Inflow: IDQR Income Outflow: Bank Charges
B13: 8 | C13: UBA (PROJECT) | D13: 370319.21 | E13: 1 | F13: =D13*E13 -> 370319.21 | G13: 0 | H13: 0 | I13: =G13-H13 -> 0 | J13: =F13+I13 -> 370319.21 | K13: Inflow: Outflow: Bank charges
B14: 9 | C14: UBA (COLLECTION 1) | D14: 564653.84 | E14: 1 | F14: =D14*E14 -> 564653.84 | G14: 0 | H14: 0 | I14: =G14-H14 -> 0 | J14: =F14+I14 -> 564653.84 | K14: Inflow: Outflow:
B15: 10 | C15: UBA (COLLECTION 2) | D15: 745578.1 | E15: 1 | F15: =D15*E15 -> 745578.1 | G15: 0 | H15: 0 | I15: =G15-H15 -> 0 | J15: =F15+I15 -> 745578.1 | K15: Inflow: Outflow:
B16: 11 | C16: UBA APG | D16: 11745.64 | E16: 1 | F16: =D16*E16 -> 11745.64 | G16: 0 | H16: 0 | I16: =G16-H16 -> 0 | J16: =F16+I16 -> 11745.64 | K16: Inflow: Outflow:
B17: 12 | C17: UNION BANK | D17: 158755.71 | E17: 1 | F17: =D17*E17 -> 158755.71 | G17: 0 | H17: 0 | I17: =G17-H17 -> 0 | J17: =F17+I17 -> 158755.71 | K17: Inflow: Interbank transfer Outflow:
... B21: 16 | C21: GTB (Mastercard corporate debit) | D21: 6480068.8 | E21: 1 | F21: =D21*E21 -> 6480068.8 | G21: 0 | H21: 3123522.5 | I21: =G21-H21 -> -3123522.5 | J21: =F21+I21 -> 3356546.3 | K21: Inflows: Interbank Transfer Outflow: Flight booking & NSITF
A22: C | B22: 17 | C22: Access Bank Main A/C | D22: 1.0341635e+08 | E22: 1 | F22: =D22*E22 -> 1.0341635e+08 | G22: 5020 | H22: 16617330 | I22: =G22-H22 -> -16612310 | J22: =F22+I22 -> 86804043 | K22: Inflow: Refund Outflow: Payment Batch, interbank transfer & Bank charges
B23: 18 | C23: Access Bank Salary A/C | D23: 686685.06 | E23: 1 | F23: =D23*E23 -> 686685.06 | G23: 195000 | H23: 0 | I23: =G23-H23 -> 195000 | J23: =F23+I23 -> 881685.06 | K23: Inflows: Int'l Women day donations Outflow:
B24: 19 | C24: Wema | D24: 101797.4 | E24: 1 | F24: =D24*E24 -> 101797.4 | G24: 0 | H24: 0 | I24: =G24-H24 -> 0 | J24: =F24+I24 -> 101797.4 | K24: Inflow: Outflow:
B25: 20 | C25: Wema card A/c | D25: 257681.85 | E25: 1 | F25: =D25*E25 -> 257681.85 | G25: 1500000 | H25: 775092 | I25: =G25-H25 -> 724908 | J25: =F25+I25 -> 982589.85 | K25: Inflow: Interbank transfer Outflow:
B26: 21 | C26: Globus | D26: 990050.45 | E26: 1 | F26: =D26*E26 -> 990050.45 | G26: 0 | H26: 0 | I26: =G26-H26 -> 0 | J26: =F26+I26 -> 990050.45 | K26: Inflow: Outflow:
B27: 22 | C27: Momo Account | D27: 0 | E27: 1 | F27: =D27*E27 -> 0 | G27: 0 | H27: 0 | I27: =G27-H27 -> 0 | J27: =F27+I27 -> 0 | K27: Inflow: Outflow:
C28: TOTAL CASH (NGN) | D28: =SUM(D6:D27) -> 1.6264952e+08 | F28: =SUM(F6:F27) -> 1.6264952e+08 | G28: =SUM(G6:G27) -> 1.9925741e+08 | H28: =SUM(H6:H27) -> 20817999 | I28: =SUM(I6:I27) -> 1.7843941e+08 | J28: =SUM(J6:J27) -> 3.4108893e+08 | K28: Inflow: Outflow:
B30: 23 | C30: CASH IN HAND (POUNDS) | D30: 2525 | E30: 1862.92 | F30: =D30*E30 -> 4703873 | G30: 0 | H30: 0 | I30: =G30-H30 -> 0 | J30: =F30+I30 -> 4703873 | K30: Inflow: Outflow:
B31: 24 | C31: ZENITH BANK (USD) | D31: 6534.23 | E31: 1393.69 | F31: =D31*E31 -> 9106691 | G31: =4100.89*E31 -> 5715369.4 | H31: 0 | I31: =G31-H31 -> 5715369.4 | J31: =F31+I31 -> 14822060 | K31: Inflow: Nimc Income Outflow:
B32: 25 | C32: CASH IN HAND (USD) | D32: 10245 | E32: =$E$31 -> 1393.69 | F32: =D32*E32 -> 14278354 | G32: 0 | H32: =930*E32 -> 1296131.7 | I32: =G32-H32 -> -1296131.7 | J32: =F32+I32 -> 12982222 | K32: Inflow: Outflow: BTA & Mgt Allowances
B33: 26 | C33: CASH IN TRANSIT | D33: 0 | E33: =$E$31 -> 1393.69 | F33: =D33*E33 -> 0 | G33: 0 | H33: 0 | I33: =G33-H33 -> 0 | J33: =F33+I33 -> 0 | K33: Inflow: Outflow:
B34: 27 | C34: GTB MAIN (USD) | D34: 142172.16 | E34: =$E$31 -> 1393.69 | F34: =D34*E34 -> 1.9814392e+08 | G34: =12900*E34 -> 17978601 | H34: =7000*E34 -> 9755830 | I34: =G34-H34 -> 8222771 | J34: =F34+I34 -> 2.0636669e+08 | K34: Inflow:Nimc Income Outflow: Interbank Transfer
B35: 28 | C35: GTB DEBIT CARD (USD) | D35: 5504.35 | E35: =$E$31 -> 1393.69 | F35: =D35*E35 -> 7671357.6 | G35: =7000*E35 -> 9755830 | H35: =3327.65*E35 -> 4637712.5 | I35: =G35-H35 -> 5118117.5 | J35: =F35+I35 -> 12789475 | K35: Inflow: Interbank transfer & Refund Outflow:Software Tools, ID4Africa Registration & Flight & Hotel bookings
B36: 29 | C36: SCB | D36: 631792.71 | E36: =$E$31 -> 1393.69 | F36: =D36*E36 -> 880523182 | G36: 0 | H36: =536306.77*E36 -> 7.4744538e+08 | I36: =G36-H36 -> -7.4744538e+08 | J36: =F36+I36 -> 1.330778e+08 | K36: Inflow: Outflow: Bank charges, SCB overdraft collateral & Bind
B37: 30 | C37: UBA | D37: 13406.85 | E37: =$E$31 -> 1393.69 | F37: =D37*E37 -> 18684993 | G37: 0 | H37: 0 | I37: =G37-H37 -> 0 | J37: =F37+I37 -> 18684993 | K37: Inflow: Outflow:
B38: 31 | C38: Access USD | D38: 62054.2 | E38: =$E$31 -> 1393.69 | F38: =D38*E38 -> 86484318 | G38: =6300*E38 -> 8780247 | H38: 0 | I38: =G38-H38 -> 8780247 | J38: =F38+I38 -> 95264565 | K38: Inflow: NIMC Income Outflow:
B39: TOTAL CASH (USD | D39: =SUM(D31:D38) -> 871709.5 | E39: =$E$31 -> 1393.69 | F39: =SUM(F31:F38) -> 1214892813 | G39: =SUM(G31:G38) -> 42230047 | H39: =SUM(H31:H38) -> 7.6313506e+08 | I39: =SUM(I31:I38) -> -7.2090501e+08 | J39: =SUM(J31:J38) -> 4.939878e+08
B43: TOTAL INVESTMENTS (NGN)
C44: INVESTMENT HOUSE | D44: OPENING BALANCE (PRINCIPAL & iNTEREST PAID | E44: EXCHANGE RATE | F44: OPENING BALANCE (NGN) | G44: INFLOW | H44: OUTFLOW | I44: NET DIFFERENCE | J44: CLOSING BALANCE | K44: COMMENTS
B45: 32 | C45: FBN QUEST | D45: 9255303.4 | E45: 1 | F45: =D45*E45 -> 9255303.4 | G45: 0 | H45: 0 | I45: =G45-H45 -> 0 | J45: =F45+G45-H45 -> 9255303.4
B46: 33 | C46: CORDROS MMF | D46: 7786750.6 | E46: 1 | F46: =D46*E46 -> 7786750.6 | G46: 0 | H46: 0 | I46: =G46-H46 -> 0 | J46: =F46+G46-H46 -> 7786750.6
B47: 34 | C47: FBN QUEST | D47: 1115165.2 | E47: 1 | F47: =D47*E47 -> 1115165.2 | G47: 0 | H47: 0 | I47: =G47-H47 -> 0 | J47: =F47+G47-H47 -> 1115165.2 | K47: Alitheia funds
...

Sheet Breakdown of Income and Expendi
G2: CASH REPORT - 13TH MARCH 2026
B3: Inflows: | C3: Amount | D3: % Ratio | G3: Details | H3: Amount | I3: Exc rate | J3: Naira Equivalent
B4: Nimc Income | C4: 73143608 | D4: =C4/$C$10 -> 0.31769575 | G4: Opening Balance- 7th March NGN | H4: ='Cash Report'!F28 -> 1.6264952e+08 | I4: 1 | J4: =H4*I4 -> 1.6264952e+08
B5: Refund/Reversal | C5: 5020 | D5: =C5/$C$10 -> 2.1804129e-05 | G5: Opening Balance- 7th March USD | H5: ='Cash Report'!D39 -> 871709.5 | I5: ='Cash Report'!$E$31 -> 1393.69 | J5: =H5*I5 -> 1214892813
B6: IDQR Income | C6: 11483.5 | D6: =C6/$C$10 -> 4.9878031e-05 | G6: Opening Balance- 7th March GBP | H6: 2525 | I6: ='Cash Report'!E30 -> 1862.92 | J6: =H6*I6 -> 4703873
B7: Glo Income | C7: 156735000 | D7: =C7/$C$10 -> 0.68077094
B8: Int'l Weman Day Donations | C8: 195000 | D8: =C8/$C$10 -> 0.00084697313 | G8: Total Opening Balance | J8: =J4+J5+J6 -> 1382246209
B9: iTranscript Income | C9: 141512.38 | D9: =C9/$C$10 -> 0.00061465224
B10: Total Cash Inflows for the week | C10: =sum(C4:C9) -> 2.3023162e+08 | D10: =C10/$C$10*100 -> 100 | G10: INFLOWS | H10: Amount | I10: % Ratio
G11: Nimc Income | H11: 73143608 | I11: 0.31769575
B12: OUTFLOWS | C12: Amount | D12: % Ratio | G12: Refund/Reversal | H12: 5020 | I12: 2.1804129e-05
B13: Payment Batches | C13: 15115115 | D13: =C13/C$23*100 -> 1.9561498 | G13: IDQR Income | H13: 11483.5 | I13: 4.9878031e-05
B14: Software Tools | C14: 2955236 | D14: =C14/C$23*100 -> 0.38245718 | G14: Glo Income | H14: 156735000 | I14: 0.68077094
B15: Flight Ticket/Accommodation | C15: 4775676.5 | D15: =C15/C$23*100 -> 0.61805276 | G15: Int'l Weman Day Donations | H15: 195000 | I15: 0.00084697313
B16: NSITF Contributions | C16: 30322.5 | D16: =C16/C$23*100 -> 0.0039242408 | G16: iTranscript Income | H16: 141512.38 | I16: 0.00061465224
B17: Bind Creative | C17: 81962700 | D17: =C17/C$23*100 -> 10.60735 | H17: =SUM(H11:H16) -> 2.3023162e+08 | I17: =sum(I11:I16) -> 1 | J17: =H17 -> 2.3023162e+08
B18: Investment in SCB USD mutua fund | C18: 648065850 | D18: =C18/C$23*100 -> 83.870607 | G18: TOTAL CASH BALANCE BEFORE OUTFLOWS | J18: =SUM(J8:J17) -> 1612477833
B19: BTA | C19: 1087078.2 | D19: =C19/C$23*100 -> 0.14068618
B20: Management Allowance | C20: 209053.5 | D20: =C20/C$23*100 -> 0.027055034 | G20: OUTFLOWS | I20: % Ratio
B21: Bank Charges | C21: 17721102 | D21: =C21/C$23*100 -> 2.2934083 | G21: Payment Batches | H21: 15115115 | I21: 1.9561498
B22: Office Supplies, Fuel & Letter Dispatch | C22: 775092 | D22: =C22/C$23*100 -> 0.10030992 | G22: Software Tools | H22: 2955236 | I22: 0.38245718
B23: Total Cash Outflow for the week | C23: =SUM(C13:C22) -> 7.7269723e+08 | D23: =SUM(D13:D22) -> 100 | G23: Flight Ticket/Accommodation | H23: 4775676.5 | I23: 0.61805276
B24: Net Cash Inflow for the Week | C24: =C10-C23 -> -542465602 | G24: NSITF Contributions | H24: 30322.5 | I24: 0.0039242408
G25: Bind Creative | H25: 81962700 | I25: 10.60735
G26: Investment in SCB USD mutua fund | H26: 648065850 | I26: 83.870607
G27: BTA | H27: 1087078.2 | I27: 0.14068618
G28: Management Allowance | H28: 209053.5 | I28: 0.027055034
G29: Bank Charges | H29: 17721102 | I29: 2.2934083
G30: Office Supplies, Fuel & Letter Dispatch | H30: 775092 | I30: 0.10030992
H31: =SUM(H21:H30) -> 7.7269723e+08 | I31: =sum(I21:I30) -> 100 | J31: =H31 -> 7.7269723e+08
G32: CASH BALANCE AS AT 13TH MARCH 2026 | J32: =J18-J31 -> 8.3978061e+08
G34: Breakdown of Alitheia Investment Balance held in SCB
G35: Opening Balance | H35: 768.94 | I35: ='Cash Report'!$E$31 -> 1393.69 | J35: =H35*I35 -> 1071664
G37: Closing Balance | H37: =SUM(H35) -> 768.94 | I37: ='Cash Report'!$E$31 -> 1393.69 | J37: =H37*I37 -> 1071664
G40: BREAKDOWN OF PAYMENT BATCH FOR THE WEEK
G41: Beneficiary Names | H41: Amount (N) | I41: Description
G42: Ubong Victor | H42: 64700 | I42: Servicing and Gas refilling of the inverter AC in the server room
G43: Ubong Victor | H43: 53900 | I43: Replacement of AC indoor motor and Panel(meeting room wing A
G44: Johnbosco Obiekwe | H44: 160000 | I44: Staff advance to Johnbosco for ESUT operations
G45: Chidubem Chukwu | H45: 600 | I45: Refund for UNN trip (13th to 16th Jan 2026)
...

Sheet Cash Balance Summary 
B2: BREAKDOWN OF SEAMFIX CASH BALANCES AS AT 13TH MARCH 2026
B3: Cash Balances | C3: Amount (Naira) | D3: Amount (USD) | E3: Amount (GBP) | F3: Exchange rate | G3: Naira Equivalent
B4: Seamfix operational A/c balances (Naira) | C4: ='Cash Report'!D64-103000000 -> 2.3808893e+08 | D4: 0 | E4: 0 | F4: 1 | G4: =C4*F4 -> 2.3808893e+08
B5: Seamfix operational A/c balances (USD) | C5: 0 | D5: ='Cash Report'!D65 -> 354445.97 | E5: 0 | F5: ='Cash Report'!$E$31 -> 1393.69 | G5: ='Cash Report'!J39 -> 4.939878e+08
B6: Seamfix operational A/c balances (GBP) | C6: 0 | D6: 0 | E6: ='Cash Report'!D66 -> 2525 | F6: ='Cash Report'!E30 -> 1862.92 | G6: ='Cash Report'!F66 -> 4703873 | I6: =(G5+G6)/F5 -> 357821.09
B7: Alitheia funds in the SCB funding a/c | C7: 0 | D7: ='Breakdown of Income and Expendi'!H37 -> 768.94 | E7: 0 | F7: ='Cash Report'!$E$31 -> 1393.69 | G7: =D7*F7 -> 1071664
B8: TOTAL | C8: =SUM(C4:C7) -> 2.3808893e+08 | D8: =SUM(D4:D7) -> 355214.91 | E8: =SUM(E4:E7) -> 2525 | G8: =SUM(G4:G7) -> 7.3785227e+08
B11: BREAKDOWN OF AIF INVESTMENT FUND
B12: Investment House | C12: Principal | D12: Interest | E12: Total | F12: Maturity Date | G12: Investment Type | H12: Comment | J12: NGN | K12: =G4+E32+G39 -> 3.3330211e+08 | L12: =K12/F5 -> 239150.82
B13: Stanbic IBTC Asset Management | C13: =59500-59500 -> 0 | D13: 689.68 | E13: =SUM(C13:D13) -> 689.68 | F13: N/A | G13: Mutual Fund | J13: USD | K13: =I6+(E24-C24)+D7 -> 361002.38
B14: Cardinal Stone Asset Management Ltd | C14: =752544.4-123000-60000-100000 -> 469544.4 | D14: 131209.01 | E14: =SUM(C14:D14) -> 600753.41 | F14: N/A | G14: Mutual Fund | J14: AIF USD | K14: =E19 -> 1210158.8
B15: FBNQuest Asset management | C15: 111975.35 | D15: 1089.64 | E15: =SUM(C15:D15) -> 113064.99 | F15: N/A | G15: Mutual Fund
B16: Absa Bank | C16: 0 | D16: 29881.75 | E16: =SUM(C16:D16) -> 29881.75 | K16: =K14+K13+L12 -> 1810312
B17: SCB USD Mutual fund | C17: 465000 | D17: 0 | E17: =SUM(C17:D17) -> 465000 | G17: Mutual Fund
B18: SCB Investment/Funding A/c Balance | C18: 769 | D18: 0 | E18: =SUM(C18:D18) -> 769 | F18: N/A | G18: N/A
C19: =SUM(C13:C18) -> 1047288.7 | D19: =SUM(D13:D18) -> 162870.08 | E19: =SUM(E13:E18) -> 1210158.8
K20: 1421038.3
K21: =K20-E19 -> 210879.51
B22: BREAKDOWN OF OTHER DOLLAR INVESTMENT
B23: Investment House | C23: Principal | D23: Interest | E23: Total | F23: Maturity Date | G23: Investment Type | H23: Comment
B24: FBNQuest Asset Management | C24: 38400 | D24: 2412.35 | E24: =C24+D24 -> 40812.35 | F24: N/A | G24: Mutual Fund | H24: Earmarked for MinIo/Glo project licenses.
B25: Total USD Investments | C25: =SUM(C24) -> 38400 | D25: =SUM(D24) -> 2412.35 | E25: =SUM(E24) -> 40812.35
B28: BREAKDOWN OF OTHER NAIRA INVESTMENTS
B29: Investment House | C29: Principal | D29: Interest | E29: Total | F29: Maturity Date | G29: Investment Type | H29: Comment
B30: Stanbic Mutual Fund | C30: 17791.37 | D30: 0 | E30: =C30+D30 -> 17791.37 | F30: N/A | G30: Mutual Fund
H31: N120m is earmarked for NIMC payments.
B32: Total Naira Investments | C32: =SUM(C30:C31) -> 17791.37 | D32: =SUM(D30:D31) -> 0 | E32: =SUM(E30:E31) -> 17791.37
B35: MARKET VALUE OF MTN SHARES
B36: Investment date | G36: 44531
B37: Invested Amount | G37: 20280000
B38: Market value as at 6th March 2026 | G38: 96506116
B39: Market value as at 13th March 2026 | G39: 95195391

Sheet Cash Utilizations from Safe
B2: USAGE OF LAST FOUR CASH WITHDRAWALS FOR SAFE
B4: Date | C4: Description | D4: Inflow | E4: Outflow | F4: Balance
B5: 45669 | C5: Balance brought forward from Nov 2025 | E5: 1000 | F5: 5406
B6: 45881 | C6: Cash withdrawn from Access | D6: 10000 | F6: =F5+D6-E6 -> 15406
B7: 16/12/2025 | C7: Nov Management allowance to Tobi | E7: 2000 | F7: =F6+D7-E7 -> 13406
B8: 16/12/2025 | C8: Dec Management allowance to Tobi | E8: 2000 | F8: =F7+D8-E8 -> 11406
B9: 16/12/2025 | C9: 13th month Management allowance to Tobi | E9: 1000 | F9: =F8+D9-E9 -> 10406
B10: 16/12/2025 | C10: Nov Management allowance to Lilian | E10: 2000 | F10: =F9+D10-E10 -> 8406
B11: 16/12/2025 | C11: Dec Management allowance to Lilian | E11: 2000 | F11: =F10+D11-E11 -> 6406
B12: 16/12/2025 | C12: 13th month Management allowance to Lilian | E12: 1000 | F12: =F11+D12-E12 -> 5406
B13: 16/12/2025 | C13: Dec Management allowance to Kolade | E13: 2000 | F13: =F12+D13-E13 -> 3406
B14: 16/12/2025 | C14: 13th month Management allowance to Kolade | E14: 1000 | F14: =F13+D14-E14 -> 2406
B15: 16/12/2025 | C15: Cash withdrawn from SCB | D15: 13000 | F15: =F14+D15-E15 -> 15406
B16: 16/12/2025 | C16: Nov Management allowance to Diyan | E16: 3250 | F16: =F15+D16-E16 -> 12156
B17: 16/12/2025 | C17: Dec Management allowance to Diyan | E17: 3250 | F17: =F16+D17-E17 -> 8906
B18: 16/12/2025 | C18: 13th month Management allowance to Diyan | E18: 1625 | F18: =F17+D18-E18 -> 7281
B19: 24/12/2025 | C19: Cash deposit in SCB | E19: 5300 | F19: =F18+D19-E19 -> 1981
B20: 46235 | C20: BTA to Frank Atube for Abidjan Trip | E20: 1280 | F20: =F19+D20-E20 -> 701
B21: 23/01/2026 | C21: Cash withdrawn from GTbank | D21: 22000 | F21: =F20+D21-E21 -> 22701
B22: 23/01/2026 | C22: Part payment of Jan Management allowance - Lilian | E22: 500 | F22: =F21+D22-E22 -> 22201
B23: 27/01/2026 | C23: Jan Management allowance - Lilian balance | E23: 1500 | F23: =F22+D23-E23 -> 20701
B24: 27/01/2026 | C24: Jan Management allowance - Frank | E24: 3500 | F24: =F23+D24-E24 -> 17201
B25: 27/01/2026 | C25: Jan Management allowance - Kolade | E25: 2000 | F25: =F24+D25-E25 -> 15201
B26: 27/01/2026 | C26: Jan Management allowance - Diyan | E26: 4500 | F26: =F25+D26-E26 -> 10701
B27: 27/01/2026 | C27: Jan Management allowance - Tobi | E27: 2000 | F27: =F26+D27-E27 -> 8701
B28: 46205 | C28: BTA - Frank | E28: 1105 | F28: =F27+D28-E28 -> 7596
B29: 46205 | C29: BTA - George | E29: 650 | F29: =F28+D29-E29 -> 6946
B30: 13/02/2026 | C30: Feb. Management allowance - Frank Atube | E30: 1000 | F30: =F29+D30-E30 -> 5946
B31: 23/02/2026 | C31: BTA - Ebuka to Cotonou | E31: 940 | F31: =F30+D31-E31 -> 5006
B32: 23/02/2026 | C32: BTA Return - George | D32: 240 | F32: =F31+D32-E32 -> 5246
B33: 23/02/2026 | C33: Refund to Pyrich | E33: 51 | F33: =F32+D33-E33 -> 5195
B34: 25/02/2026 | C34: Cash withdrawn from Access Bank | D34: 15000 | F34: =F33+D34-E34 -> 20195
B35: 46025 | C35: Jan Management allowance - Kolade | E35: 2000 | F35: =F34+D35-E35 -> 18195
B36: 46025 | C36: Jan Management allowance - Diyan | E36: 4500 | F36: =F35+D36-E36 -> 13695
B37: 46025 | C37: Jan Management allowance - Tobi | E37: 2000 | F37: =F36+D37-E37 -> 11695
B38: 46025 | C38: BTA - Ebuka | E38: 1450 | F38: =F37+D38-E38 -> 10245
B39: 46268 | C39: BTA - Philip | E39: 780 | F39: =F38+D39-E39 -> 9465
B40: 46268 | C40: Feb Mgt allowance bal - Lilian | E40: 150 | F40: =F39+D40-E40 -> 9315
