Workbook

Sheet Expense
D2: =SUM(D4:D35) -> 1.0172716e+08 | E2: =SUM(G2:AB2) -> 1.0172716e+08 | G2: =G38 -> 50000000 | H2: =H38 -> 11188116 | I2: =I38 -> 530.75 | J2: =J38 -> 0 | K2: =K38 -> 0 | L2: =L38 -> 569172 | M2: =M38 -> 820011.68 | N2: =N38 -> 0 | ... AB2: =AB38 -> 19439710
A3: Column 1 | B3: Column 2 | C3: Column 3 | D3: Column 4 | E3: Total | G3: inter | H3: pay. batch | I3: bank charge | J3: NIMC Sponsorship | K3: Refund | L3: Training | M3: Flight Ticket/Accommodation | N3: Tatvasoft | O3: Hotel/Acc | P3: Management Allowance | Q3: Office Supplies & Fuel | R3: Software Tools | S3: Shipping & Freight | T3: Pension | U3: Non-Executive Sitting All | V3: BTA | W3: NIMC -Licenses Fee | X3: VAT | Y3: WHT | Z3: Hosting | AA3: Exit Salary | AB3: Paye
A4: OUTFLOWS | C4: FBN (PROJECT) | D4: 0 | E4: =SUM(G4:AB4) -> 0
A5: Interbank | B5: =G2 -> 50000000 | C5: FIDELITY | D5: 0 | E5: =SUM(G5:AA5) -> 0
A6: Payment Batches | B6: =H2 -> 11188116 | C6: POLARIS MAIN | D6: 0 | E6: =SUM(G6:AA6) -> 0
A7: =R3 -> Software Tools | B7: =R2 -> 310013.76 | C7: POLARIS (OPERATIONS 1) | D7: 0 | E7: =SUM(G7:AA7) -> 0
A8: =M3 -> Flight Ticket/Accommodation | B8: =M2 -> 820011.68 | C8: POLARIS (OPERATIONS 2) | D8: 0 | E8: =SUM(G8:AA8) -> 0
A9: =W3 -> NIMC -Licenses Fee | B9: =W2 -> 14752935 | C9: SCB | D9: 0 | E9: =SUM(G9:AA9) -> 0
A10: =AA3 -> Exit Salary | B10: =AA2 -> 3876666.7 | C10: UBA Main | D10: 12 | E10: =SUM(G10:AA10) -> 12 | I10: 12
A11: =V3 -> BTA | B11: =V2 -> 770000 | C11: UBA (PROJECT) | D11: 0 | E11: =SUM(G11:AA11) -> 0
A12: =AB3 -> Paye | B12: =AB2 -> 19439710 | C12: UBA (COLLECTION 1) | D12: 0 | E12: =SUM(G12:AA12) -> 0
A13: =L3 -> Training | B13: =L2 -> 569172 | C13: UBA (COLLECTION 2) | D13: 0 | E13: =SUM(G13:AA13) -> 0
A14: Bank Charges | B14: =I2 -> 530.75 | C14: UBA APG | D14: 0 | E14: =SUM(G14:AA14) -> 0
A15: Total | B15: =SUM(B5:B14) -> 1.0172716e+08 | C15: UNION BANK | D15: 0 | E15: =SUM(G15:AA15) -> 0
A16: Interbank | B16: =B5 -> 50000000 | C16: ZENITH CALL 1 | D16: 0 | E16: =SUM(G16:AA16) -> 0
B17: =SUM(B15-B16) -> 51727156 | C17: ZENITH (SETTLEMENT) | D17: 0 | E17: =SUM(G17:AA17) -> 0
C18: GTB | D18: 69439964 | E18: =SUM(G18:AB18) -> 69439964 | G18: 50000000 | I18: 253.75 | AB18: 19439710
C19: GTB (Mastercard corporate debit) | D19: 518535.5 | E19: =SUM(G19:AB19) -> 518535.5 | M19: 518535.5
C20: Access Bank Main A/C | D20: 22834994 | E20: =SUM(G20:AA20) -> 22834994 | H20: 11188116 | I20: 211.25 | V20: 770000 | W20: 7000000 | AA20: 3876666.7
C21: Access Bank Salary A/C | D21: 7752988.8 | E21: =SUM(G21:AA21) -> 7752988.8 | I21: 53.75 | W21: 7752935
C22: Wema Card | D22: 0 | E22: =SUM(G22:AA22) -> 0
C23: Globus | D23: 0 | E23: =SUM(G23:AA23) -> 0
C24: MoMo Wallet | D24: 0 | E24: =SUM(G24:AA24) -> 0
C26: ZENITH (USD) | D26: 0 | E26: =SUM(G26:AA26) -> 0
C27: CASH IN HAND (USD) | D27: 0 | E27: =SUM(G27:AA27) -> 0
C28: CASH IN HAND (POUNDS) | D28: 0 | E28: =SUM(G28:AA28) -> 0
C29: CASH IN TRANSIT | D29: 0 | E29: =SUM(G29:AA29) -> 0
C30: GTB | D30: 0 | E30: =SUM(G30:AA30) -> 0
C31: GTB MASTERCARD CCC (DOLLAR) | D31: =829.74*C36 -> 1180661.9 | E31: =SUM(G31:AA31) -> 1180661.9 | L31: =400*C36 -> 569172 | M31: =211.87*C36 -> 301476.18 | R31: =217.87*C36 -> 310013.76
C32: SCB | D32: 0 | E32: =SUM(G32:AA32) -> 0
C33: SCB Funding | D33: 0 | E33: =SUM(G33:AA33) -> 0
C34: UBA | D34: 0 | E34: =SUM(G34:AA34) -> 0
C35: Access USD | D35: 0 | E35: =SUM(G35:AA35) -> 0
C36: =Income!C36 -> 1422.93 | E36: =SUM(G36:AA36) -> 0
D37: =SUM(D4:D36) -> 1.0172716e+08 | E37: =SUM(E4:E36) -> 1.0172716e+08
G38: =SUM(G4:G37) -> 50000000 | H38: =SUM(H4:H37) -> 11188116 | I38: =SUM(I4:I37) -> 530.75 | J38: =SUM(J4:J37) -> 0 | K38: =SUM(K4:K37) -> 0 | L38: =SUM(L4:L37) -> 569172 | M38: =SUM(M4:M37) -> 820011.68 | N38: =SUM(N4:N37) -> 0 | ... AB38: =SUM(AB4:AB37) -> 19439710

Sheet Income
D2: =SUM(D4:D35) -> 94229492 | E2: =SUM(F2:AG2) -> 94229492 | F2: =F36 -> 50000000 | G2: =G36 -> 1517937.6 | H2: =H36 -> 0 | I2: =I36 -> 0 | J2: =J36 -> 0 | K2: =K36 -> 0 | L2: =L36 -> 0 | M2: =M36 -> 41013886 | ... Z2: =Z36
E3: Total | F3: Interbank | G3: Refund/Reversal | H3: idqr | I3: Investment Liquidation | J3: Insurance Claim | K3: MTN CIV Income | L3: Interest Earned | M3: NIMC Income | N3: iTranscript Income | O3: NextGen | P3: CIV Inflow | Q3: Loan Repayment | R3: Insurance Claim | S3: MTN Q3 AMC
A4: Inflows | C4: FBN (PROJECT) | D4: 0 | E4: =SUM(F4:X4) -> 0
A5: Interbank | B5: =F2 -> 50000000 | C5: FIDELITY | D5: 0 | E5: =SUM(F5:X5) -> 0
A6: Nimc Income | B6: =M2 -> 41013886 | C6: POLARIS MAIN | D6: 0 | E6: =SUM(F6:X6) -> 0
A7: =G3 -> Refund/Reversal | B7: =G2 -> 1517937.6 | C7: POLARIS (OPERATIONS 1) | D7: 0 | E7: =SUM(F7:X7) -> 0
A8: =N3 -> iTranscript Income | B8: =N2 -> 1697668.8 | C8: POLARIS (OPERATIONS 2) | D8: 0 | E8: =SUM(F8:X8) -> 0
A9: Total | B9: =SUM(B5:B8) -> 94229492 | C9: SCB | D9: 0 | E9: =SUM(F9:X9) -> 0
B10: =B5 -> 50000000 | C10: UBA MAIN | D10: 10500.7 | E10: =SUM(F10:X10) -> 10500.7 | N10: 10500.7
B11: =B9-B10 -> 44229492 | C11: UBA Project | D11: 0 | E11: =SUM(F11:X11) -> 0
C12: UBA (COLLECTION 1) | D12: 0 | E12: =SUM(F12:X12) -> 0
C13: UBA (COLLECTION 2) | D13: 0 | E13: =SUM(F13:X13) -> 0
C14: UBA APG | D14: 0 | E14: =SUM(F14:X14) -> 0
C15: UNION BANK | D15: 0 | E15: =SUM(F15:X15) -> 0
C16: ZENITH CALL 1 | D16: 0 | E16: =SUM(F16:X16) -> 0
C17: ZENITH (SETTLEMENT) | D17: 0 | E17: =SUM(F17:X17) -> 0
C18: GTB | D18: 26500000 | E18: =SUM(F18:X18) -> 26500000 | M18: 26500000
C19: GTB (Mastercard corporate debit) | D19: 0 | E19: =SUM(F19:X19) -> 0
C20: Access Bank Main A/C | D20: 50169000 | E20: =SUM(F20:X20) -> 50169000 | F20: 50000000 | G20: 169000
C21: Access Bank Salary A/C | D21: 0 | E21: =SUM(F21:X21) -> 0
C22: Wema Card | D22: 0 | E22: =SUM(F22:X22) -> 0
C23: Globus | D23: 0 | E23: =SUM(F23:X23) -> 0
C24: MoMo Wallet | D24: 0 | E24: =SUM(F24:X24) -> 0
C26: ZENITH (USD) | D26: =1185.7*C36 -> 1687168.1 | E26: =SUM(F26:X26) -> 1687168.1 | N26: =1185.7*C36 -> 1687168.1
C27: CASH IN HAND (USD) | D27: 0 | E27: =SUM(F27:X27) -> 0
C28: CASH IN HAND (POUNDS) | D28: 0 | E28: =SUM(F28:X28) -> 0
C29: CASH IN TRANSIT | D29: 0 | E29: =SUM(F29:X29) -> 0
C30: GTB | D30: =9300*C36 -> 13233249 | E30: =SUM(F30:X30) -> 13233249 | M30: =9300*C36 -> 13233249
C31: GTB MASTERCARD CCC (DOLLAR) | D31: =948*C36 -> 1348937.6 | E31: =SUM(F31:X31) -> 1348937.6 | G31: =948*C36 -> 1348937.6
C32: SCB | D32: 0 | E32: =SUM(F32:X32) -> 0
C33: SCB Funding | D33: 0 | E33: =SUM(F33:X33) -> 0
C34: UBA | D34: 0 | E34: =SUM(F34:X34) -> 0
C35: Access USD | D35: =900*C36 -> 1280637 | E35: =SUM(F35:X35) -> 1280637 | M35: =900*C36 -> 1280637
C36: ='Cash Report'!E39 -> 1422.93 | D36: =SUM(D4:D35) -> 94229492 | E36: =SUM(E4:E35) -> 94229492 | F36: =SUM(F4:F35) -> 50000000 | G36: =SUM(G4:G35) -> 1517937.6 | H36: =SUM(H4:H35) -> 0 | I36: =SUM(I4:I35) -> 0 | J36: =SUM(J4:J35) -> 0 | K36: =SUM(K4:K35) -> 0 | ... X36: =SUM(X4:X35) -> 0

Sheet Cash Report
A1: sa
B2: SEAMFIX LIMITED
B3: CASH AND CASH EQUIVALENT REPORT AS AT 15TH JANUARY 2026
B4: CASH IN HAND AND BANK
B5: S/N | C5: Banks | D5: OPENING BALANCE | E5: EXCHANGE RATE | F5: OPENING BALANCE (NGN) | G5: INFLOW | H5: OUTFLOW | I5: NET DIFFERENCE | J5: CLOSING BALANCE | K5: Remarks
B6: 1 | C6: FBN (PROJECT) | D6: 1057208.4 | E6: 1 | F6: =D6*E6 -> 1057208.4 | G6: 0 | H6: 0 | I6: =G6-H6 -> 0 | J6: =F6+I6 -> 1057208.4 | K6: Inflow: Outflow:
B7: 2 | C7: FIDELITY | D7: 73124.13 | E7: 1 | F7: =D7*E7 -> 73124.13 | G7: 0 | H7: 0 | I7: =G7-H7 -> 0 | J7: =F7+I7 -> 73124.13 | K7: Inflow: Outflow:
B8: 3 | C8: POLARIS MAIN | D8: 16963099 | E8: 1 | F8: =D8*E8 -> 16963099 | G8: 0 | H8: 0 | I8: =G8-H8 -> 0 | J8: =F8+I8 -> 16963099 | K8: Inflow: Refund Outflow: Bank charges
B9: 4 | C9: POLARIS (OPERATIONS 1) | D9: 31493.46 | E9: 1 | F9: =D9*E9 -> 31493.46 | G9: 0 | H9: 0 | I9: =G9-H9 -> 0 | J9: =F9+I9 -> 31493.46 | K9: Inflow: Outflow:
B10: 5 | C10: POLARIS (OPERATIONS 2) | D10: 208999.86 | E10: 1 | F10: =D10*E10 -> 208999.86 | G10: 0 | H10: 0 | I10: =G10-H10 -> 0 | J10: =F10+I10 -> 208999.86 | K10: Inflow: Outflow:
B11: 6 | C11: SCB | D11: 1043630.6 | E11: 1 | F11: =D11*E11 -> 1043630.6 | G11: 0 | H11: 0 | I11: =G11-H11 -> 0 | J11: =F11+I11 -> 1043630.6 | K11: Inflow: Outflow:
B12: 7 | C12: UBA MAIN | D12: 3339523.7 | E12: 1 | F12: =D12*E12 -> 3339523.7 | G12: 10500.7 | H12: 12 | I12: =G12-H12 -> 10488.7 | J12: =F12+I12 -> 3350012.4 | K12: Inflow:iTranscript Income Outflow: Bank charges
B13: 8 | C13: UBA (PROJECT) | D13: 1170660.2 | E13: 1 | F13: =D13*E13 -> 1170660.2 | G13: 0 | H13: 0 | I13: =G13-H13 -> 0 | J13: =F13+I13 -> 1170660.2 | K13: Inflow: Outflow:
B14: 9 | C14: UBA (COLLECTION 1) | D14: 564653.84 | E14: 1 | F14: =D14*E14 -> 564653.84 | G14: 0 | H14: 0 | I14: =G14-H14 -> 0 | J14: =F14+I14 -> 564653.84 | K14: Inflow: Outflow:
B15: 10 | C15: UBA (COLLECTION 2) | D15: 745578.1 | E15: 1 | F15: =D15*E15 -> 745578.1 | G15: 0 | H15: 0 | I15: =G15-H15 -> 0 | J15: =F15+I15 -> 745578.1 | K15: Inflow: Outflow:
B16: 11 | C16: UBA APG | D16: 11745.64 | E16: 1 | F16: =D16*E16 -> 11745.64 | G16: 0 | H16: 0 | I16: =G16-H16 -> 0 | J16: =F16+I16 -> 11745.64 | K16: Inflow: Outflow:
B17: 12 | C17: UNION BANK | D17: 5458755.7 | E17: 1 | F17: =D17*E17 -> 5458755.7 | G17: 0 | H17: 0 | I17: =G17-H17 -> 0 | J17: =F17+I17 -> 5458755.7 | K17: Inflow: Outflow:
... B21: 16 | C21: GTB (Mastercard corporate debit) | D21: 2433752.8 | E21: 1 | F21: =D21*E21 -> 2433752.8 | G21: 0 | H21: 518535.5 | I21: =G21-H21 -> -518535.5 | J21: =F21+I21 -> 1915217.3 | K21: Inflows: Outflow: Flight
A22: C | B22: 17 | C22: Access Bank Main A/C | D22: 7159226.1 | E22: 1 | F22: =D22*E22 -> 7159226.1 | G22: 50169000 | H22: 22834994 | I22: =G22-H22 -> 27334006 | J22: =F22+I22 -> 34493232 | K22: Inflow: Interbank, Refund Outflow: Payment Batch, Bank charge,BTA, NIMC -License
B23: 18 | C23: Access Bank Salary A/C | D23: 8016007.6 | E23: 1 | F23: =D23*E23 -> 8016007.6 | G23: 0 | H23: 7752988.8 | I23: =G23-H23 -> -7752988.8 | J23: =F23+I23 -> 263018.86 | K23: Inflows: Outflow: NIMC-License Fees, Bank charges
B24: 19 | C24: Wema | D24: 101797.4 | E24: 1 | F24: =D24*E24 -> 101797.4 | G24: 0 | H24: 0 | I24: =G24-H24 -> 0 | J24: =F24+I24 -> 101797.4 | K24: Inflow: Outflow:
B25: 20 | C25: Wema card A/c | D25: 974473.85 | E25: 1 | F25: =D25*E25 -> 974473.85 | G25: 0 | H25: 0 | I25: =G25-H25 -> 0 | J25: =F25+I25 -> 974473.85 | K25: Inflow: Outflow:
B26: 21 | C26: Globus | D26: 990050.45 | E26: 1 | F26: =D26*E26 -> 990050.45 | G26: 0 | H26: 0 | I26: =G26-H26 -> 0 | J26: =F26+I26 -> 990050.45 | K26: Inflow: Outflow:
B27: 22 | C27: Momo Account | D27: 0 | E27: 1 | F27: =D27*E27 -> 0 | G27: 0 | H27: 0 | I27: =G27-H27 -> 0 | J27: =F27+I27 -> 0 | K27: Inflow: Outflow:
C28: TOTAL CASH (NGN) | D28: =SUM(D6:D27) -> 1.2142775e+08 | F28: =SUM(F6:F27) -> 1.2142775e+08 | G28: =SUM(G6:G27) -> 76679501 | H28: =SUM(H6:H27) -> 1.0054649e+08 | I28: =SUM(I6:I27) -> -23866994 | J28: =SUM(J6:J27) -> 97560756 | K28: Inflow: Outflow:
C30: CASH IN HAND (POUNDS) | D30: 2525 | E30: 1912.41 | F30: =D30*E30 -> 4828835.2 | G30: 0 | H30: 0 | I30: =G30-H30 -> 0 | J30: =F30+I30 -> 4828835.2 | K30: Inflow: Outflow: BTA refund
B31: 23 | C31: ZENITH BANK (USD) | D31: 2298.51 | E31: 1422.93 | F31: =D31*E31 -> 3270618.8 | G31: =1185.7*E31 -> 1687168.1 | H31: 0 | I31: =G31-H31 -> 1687168.1 | J31: =F31+I31 -> 4957786.9 | K31: Inflow:iTranscript Income Outflow: Bank charges
B32: 24 | C32: CASH IN HAND (USD) | D32: 701 | E32: =$E$31 -> 1422.93 | F32: =D32*E32 -> 997473.93 | G32: 0 | H32: 0 | I32: =G32-H32 -> 0 | J32: =F32+I32 -> 997473.93 | K32: Inflow: Outflow:BTA
B33: 26 | C33: CASH IN TRANSIT | D33: 0 | E33: =$E$31 -> 1422.93 | F33: =D33*E33 -> 0 | G33: 0 | H33: 0 | I33: =G33-H33 -> 0 | J33: =F33+I33 -> 0 | K33: Inflow: Outflow:
B34: 27 | C34: GTB MAIN (USD) | D34: 14345.39 | E34: =$E$31 -> 1422.93 | F34: =D34*E34 -> 20412486 | G34: =9300*E34 -> 13233249 | H34: 0 | I34: =G34-H34 -> 13233249 | J34: =F34+I34 -> 33645735 | K34: Inflow:Nimc Income Outflow:
B35: 28 | C35: GTB DEBIT CARD (USD) | D35: 9219.2 | E35: =$E$31 -> 1422.93 | F35: =D35*E35 -> 13118276 | G35: =948*E35 -> 1348937.6 | H35: =829.74*E35 -> 1180661.9 | I35: =G35-H35 -> 168275.7 | J35: =F35+I35 -> 13286552 | K35: Inflow: Reversal Outflow:Software Tools, Training, Accommodation
B36: 30 | C36: SCB | D36: 5773.65 | E36: =$E$31 -> 1422.93 | F36: =D36*E36 -> 8215499.8 | G36: 0 | H36: 0 | I36: =G36-H36 -> 0 | J36: =F36+I36 -> 8215499.8 | K36: Inflow: Outflow:
B37: 31 | C37: UBA | D37: 13404.87 | E37: =$E$31 -> 1422.93 | F37: =D37*E37 -> 19074192 | G37: 0 | H37: 0 | I37: =G37-H37 -> 0 | J37: =F37+I37 -> 19074192 | K37: Inflow: Outflow:
B38: 32 | C38: Access USD | D38: 2040.26 | E38: =$E$31 -> 1422.93 | F38: =D38*E38 -> 2903147.2 | G38: =900*E38 -> 1280637 | H38: 0 | I38: =G38-H38 -> 1280637 | J38: =F38+I38 -> 4183784.2 | K38: Inflow: NIMC Outflow:
B39: TOTAL CASH (USD | D39: =SUM(D31:D38) -> 47782.88 | E39: =$E$31 -> 1422.93 | F39: =SUM(F31:F38) -> 67991693 | G39: =SUM(G31:G38) -> 17549992 | H39: =SUM(H31:H38) -> 1180661.9 | I39: =SUM(I31:I38) -> 16369330 | J39: =SUM(J31:J38) -> 84361023
B43: TOTAL INVESTMENTS (NGN)
C44: INVESTMENT HOUSE | D44: OPENING BALANCE (PRINCIPAL & iNTEREST PAID | E44: EXCHANGE RATE | F44: OPENING BALANCE (NGN) | G44: INFLOW | H44: OUTFLOW | I44: NET DIFFERENCE | J44: CLOSING BALANCE | K44: COMMENTS
B45: 29 | C45: STANBIC IBTC | D45: 7359160.5 | E45: 1 | F45: =D45*E45 -> 7359160.5 | G45: 0 | H45: 0 | I45: =G45-H45 -> 0 | J45: =F45+G45-H45 -> 7359160.5
B46: =B45+1 -> 30 | C46: FBN QUEST | D46: =253626188.2-250000000 -> 3626188.2 | E46: 1 | F46: =D46*E46 -> 3626188.2 | G46: 0 | H46: 0 | I46: =G46-H46 -> 0 | J46: =F46+G46-H46 -> 3626188.2
B47: 32 | C47: CORDROS MMF | D47: 7465231.4 | E47: 1 | F47: =D47*E47 -> 7465231.4 | G47: 0 | H47: 0 | I47: =G47-H47 -> 0 | J47: =F47+G47-H47 -> 7465231.4
...

Sheet Breakdown of Income and Expendi
G2: CASH REPORT - 15TH JANUARY 2026
B3: Inflows: | C3: Amount | D3: % Ratio | G3: Details | H3: Amount | I3: Exc rate | J3: Naira Equivalent
B4: Nimc Income | C4: 41013886 | D4: =C4/$C$7 -> 0.92729723 | G4: Opening Balance- 9th Jan NGN | H4: ='Cash Report'!F28 -> 1.2142775e+08 | I4: 1 | J4: =H4*I4 -> 1.2142775e+08
B5: Refund/Reversal | C5: 1517937.6 | D5: =C5/$C$7 -> 0.034319581 | G5: Opening Balance- 9th Jan USD | H5: ='Cash Report'!D39 -> 47782.88 | I5: ='Cash Report'!$E$31 -> 1422.93 | J5: =H5*I5 -> 67991693
B6: iTranscript Income | C6: 1697668.8 | D6: =C6/$C$7 -> 0.038383185 | G6: Opening Balance- 9th Jan USD | H6: 2525 | I6: 1912.41 | J6: =H6*I6 -> 4828835.2
B7: Total Cash Inflows for the week | C7: =SUM(C4:C6) -> 44229492 | D7: =C7/$C$7*100 -> 100
G8: Total Opening Balance | J8: =J4+J5+J6 -> 194248278
B10: OUTFLOWS | C10: Amount | D10: % Ratio | G10: INFLOWS | H10: Amount | I10: % Ratio
B11: Payment Batches | C11: 11188116 | D11: =C11/C$20*100 -> 21.629096 | G11: Nimc Income | H11: 41013886 | I11: =H11/$C$7 -> 0.92729723
B12: Software Tools | C12: 310013.76 | D12: =C12/C$20*100 -> 0.59932496 | G12: Refund/Reversal | H12: 1517937.6 | I12: =H12/$C$7 -> 0.034319581
B13: Flight Ticket/Accommodation | C13: 820011.68 | D13: =C13/C$20*100 -> 1.5852634 | G13: iTranscript Income | H13: 1697668.8 | I13: =H13/$C$7 -> 0.038383185
B14: NIMC -Licenses Fee | C14: 14752935 | D14: =C14/C$20*100 -> 28.520677 | H14: =SUM(H10:H13) -> 44229492 | I14: =H14/$H$14*100 -> 100 | J14: =H14 -> 44229492
B15: Exit Salary | C15: 3876666.7 | D15: =C15/C$20*100 -> 7.4944516 | G15: TOTAL CASH BALANCE BEFORE OUTFLOWS | J15: =SUM(J8:J14) -> 2.3847777e+08
B16: BTA | C16: 770000 | D16: =C16/C$20*100 -> 1.4885798
B17: Paye | C17: 19439710 | D17: =C17/C$20*100 -> 37.581247 | G17: OUTFLOWS | I17: % Ratio
B18: Training | C18: 569172 | D18: =C18/C$20*100 -> 1.100335 | G18: Payment Batches | H18: 11188116 | I18: =H18/H$27*100 -> 21.629096
B19: Bank Charges | C19: 530.75 | D19: =C19/C$20*100 -> 0.0010260568 | G19: Software Tools | H19: 310013.76 | I19: =H19/H$27*100 -> 0.59932496
B20: Total Cash Outflow for the week | C20: =SUM(C11:C19) -> 51727156 | D20: =SUM(D11:D19) -> 100 | G20: Flight Ticket/Accommodation | H20: 820011.68 | I20: =H20/H$27*100 -> 1.5852634
B21: Net Cash Inflow for the Week | C21: =C7-C20 -> -7497663.8 | G21: NIMC -Licenses Fee | H21: 14752935 | I21: =H21/H$27*100 -> 28.520677
G22: Exit Salary | H22: 3876666.7 | I22: =H22/H$27*100 -> 7.4944516
G23: BTA | H23: 770000 | I23: =H23/H$27*100 -> 1.4885798
G24: Paye | H24: 19439710 | I24: =H24/H$27*100 -> 37.581247
G25: Training | H25: 569172 | I25: =H25/H$27*100 -> 1.100335
G26: Bank Charges | H26: 530.75 | I26: =H26/H$27*100 -> 0.0010260568
H27: =SUM(H18:H26) -> 51727156 | I27: =SUM(I18:I26) -> 100 | J27: =H27 -> 51727156
G28: CASH BALANCE AS AT 15TH JAN 2026 | J28: =J15-J27 -> 1.8675061e+08
G30: Breakdown of Alitheia Investment Balance held in SCB
G31: Opening Balance | H31: 768.94 | I31: ='Cash Report'!$E$31 -> 1422.93 | J31: =H31*I31 -> 1094147.8
G33: Closing Balance | H33: =SUM(H31) -> 768.94 | I33: ='Cash Report'!$E$31 -> 1422.93 | J33: =H33*I33 -> 1094147.8
G37: BREAKDOWN OF PAYMENT BATCH FOR THE WEEK
G38: Beneficiary Names | H38: Amount (N) | I38: Description
G39: Ini Medichem Resources | H39: 3945183 | I39: LIRS 2022 audit Facilitation fee for Demand Notice
G40: Yusuf Oni | H40: 500000 | I40: Staff Loan to yusuf Oni
G41: Shuttlers Metropolitan | H41: 1866241.2 | I41: Staff Shuttlers Services for Dec 2025
G42: Valuejet | H42: 580000 | I42: Funding of the Valuejet wallet
G43: Bolt | H43: 296692.05 | I43: Staff Bolt Rides for Dec 2025
G44: Oguno Ebuka Johnbosco | H44: 4000000 | I44: Support for UNN and ESUT Staff
G45: Total | H45: =SUM(H39:H44) -> 11188116

Sheet Cash Balance Summary 
B2: BREAKDOWN OF SEAMFIX CASH BALANCES AS AT 15TH JAN 2026
B3: Cash Balances | C3: Amount (Naira) | D3: Amount (USD) | E3: Amount (GBP) | F3: Exchange rate | G3: Naira Equivalent
B4: Seamfix operational A/c balances (Naira) | C4: ='Cash Report'!D64 -> 97560756 | D4: 0 | E4: 0 | F4: 1 | G4: =C4*F4 -> 97560756
B5: Seamfix operational A/c balances (USD) | C5: 0 | D5: ='Cash Report'!D65 -> 59286.84 | E5: 0 | F5: ='Cash Report'!$E$31 -> 1422.93 | G5: ='Cash Report'!J39 -> 84361023
B6: Seamfix operational A/c balances (GBP) | C6: 0 | D6: 0 | E6: ='Cash Report'!D66 -> 2525 | F6: ='Cash Report'!E30 -> 1912.41 | G6: ='Cash Report'!F66 -> 4828835.2
B7: Alitheia funds in the SCB funding a/c | C7: 0 | D7: ='Breakdown of Income and Expendi'!H33 -> 768.94 | E7: 0 | F7: ='Cash Report'!$E$31 -> 1422.93 | G7: =D7*F7 -> 1094147.8
B8: TOTAL | C8: =SUM(C4:C7) -> 97560756 | D8: =SUM(D4:D7) -> 60055.78 | E8: =SUM(E4:E7) -> 2525 | G8: =SUM(G4:G7) -> 1.8784476e+08
B12: BREAKDOWN OF AIF INVESTMENT FUND
B13: Investment House | C13: Principal | D13: Interest | E13: Total | F13: Maturity Date | G13: Investment Type | H13: Comment
B14: Stanbic IBTC Asset Management | C14: =59500-59500 -> 0 | D14: 689.68 | E14: =SUM(C14:D14) -> 689.68 | F14: N/A | G14: Mutual Fund
B15: Cardinal Stone Asset Management Ltd | C15: =752544.4-123000 -> 629544.4 | D15: 130154.35 | E15: =SUM(C15:D15) -> 759698.75 | F15: N/A | G15: Mutual Fund
B16: FBNQuest Asset management | C16: 111975.35 | D16: 593.71 | E16: =SUM(C16:D16) -> 112569.06 | F16: N/A | G16: Mutual Fund
B17: FBN Quest & Stanbic Investment | C17: 45314.87 | D17: 32146.39 | E17: =SUM(C17:D17) -> 77461.26 | F17: N/A | G17: Mutual Fund | H17: This is held in Naira with FBN and Stanbic. Naira equivalent is N110.2m
B18: Absa Bank | C18: 528300 | D18: 0 | E18: =SUM(C18:D18) -> 528300 | F18: 46063 | G18: Fixed Deposit
B19: SCB Investment/Funding A/c Balance | C19: 769 | D19: 0 | E19: =SUM(C19:D19) -> 769 | F19: N/A | G19: N/A
C20: =SUM(C14:C19) -> 1315903.6 | D20: =SUM(D14:D19) -> 163584.13 | E20: =SUM(E14:E19) -> 1479487.7
B23: BREAKDOWN OF OTHER DOLLAR INVESTMENT
B24: Investment House | C24: Principal | D24: Interest | E24: Total | F24: Maturity Date | G24: Investment Type | H24: Comment
B25: FBNQuest Asset Management | C25: 38400 | D25: 2233.34 | E25: =C25+D25 -> 40633.34 | F25: N/A | G25: Mutual Fund | H25: Earmarked for MinIo/Glo project licenses.
B26: Total USD Investments | C26: =SUM(C25) -> 38400 | D26: =SUM(D25) -> 2233.34 | E26: =SUM(E25) -> 40633.34
B29: BREAKDOWN OF OTHER NAIRA INVESTMENTS
B30: Investment House | C30: Principal | D30: Interest | E30: Total | F30: Maturity Date | G30: Investment Type | H30: Comment
B31: FBN Mutual Fund | C31: 0 | D31: 9141371.5 | E31: =C31+D31 -> 9141371.5 | F31: N/A | G31: Mutual Fund
B32: CORDROS MMF | C32: 5000000 | D32: 2679400 | E32: =C32+D32 -> 7679400 | F32: N/A | G32: Mutual Fund
B33: Total Naira Investments | C33: =SUM(C31:C32) -> 5000000 | D33: =SUM(D31:D32) -> 11820772 | E33: =SUM(E31:E32) -> 16820772
