Workbook
Name C_RATE: Summary!$F$3
Name P_RATE: Summary!$G$3

Sheet Summary
C2: 46142 | L2: 3.4239533e+09 | M2: 2286812.8 | P2: =8000000/12 -> 666666.67 | AA2: 622.94867
D3: =-D12/D8 -> 0.44573318 | F3: =INDEX('FX Rate'!$B$3:$ZZ$8,5,MATCH(Summary!F$6,'FX Rate'!$B$3:$ZZ$3)) -> 1374.55 | G3: =INDEX('FX Rate'!$B$3:$ZZ$8,5,MATCH(Summary!G$6,'FX Rate'!$B$3:$ZZ$3)) -> 1601.9 | L3: =-L12/L8 -> 0.55254625 | M3: =M2-N8 -> 562255.83 | N3: =C_RATE -> 1374.55 | O3: =G3 -> 1601.9 | AA3: =N8-AA2 -> 1723934
C4: NIGERIA INCOME STATEMENT | K4: GROUP INCOME STATEMENT | R4: Target | U4: SEGMENTED INCOME STATEMENT (USD) | AF4: Ratios | AG4: CONSULTING | AH4: PRODUCT-FIXIAM | AI4: GROUP TOTAL | AO4: Sep'25 YTD | AP4: Bridge | AQ4: FY 2025 Exit | AX4: Item | AY4: USD | BC4: SEGMENTED INCOME STATEMENT (NGN)
C5: Income Statement | D5: YTD | E5: YTD | F5: =D5 -> YTD | G5: =E5 -> YTD | H5: Variance (%) | K5: Income Statement | L5: YTD | M5: YTD | N5: =L5 -> YTD | O5: =M5 -> YTD | P5: Variance (%) | V5: PUBLIC SECTOR | W5: TELCO | X5: VERIFY | Y5: OTHERS | Z5: CONSULTING | AA5: PRODUCT-FIXIAM | AB5: GROUP TOTAL | AF5: Gross Profit Margin | AG5: =Z9 -> 0.44375507 | AH5: =AA9 -> -113.29788 | AI5: =AB9 -> 0.42815559 | AN5: Revenue | AO5: =AB6 -> 1076068.8 | AP5: =AQ5-AO5 -> 5062293.2 | AQ5: 6138362 | AR5: $5.1m incremental revenue to bridge revenue gap which si | AX5: Revenue | AY5: =Z6 -> 1075921.2 | BD5: PUBLIC SECTOR | BE5: TELCO | BF5: VERIFY | BG5: OTHERS | BH5: CONSULTING | BI5: PRODUCT-FIXIAM | BJ5: GROUP TOTAL
D6: =C2 -> 46142 | E6: =EOMONTH(D6,-12) -> 45777 | F6: =D6 -> 46142 | G6: =E6 -> 45777 | L6: =$C$2 -> 46142 | M6: =EOMONTH(L6,-12) -> 45777 | N6: =L6 -> 46142 | O6: =M6 -> 45777 | S6: =R8/12*4 -> 1666666.7 | T6: =R9/12*4 -> 2666666.7 | U6: Revenue | V6: =N25 -> 805513.66 | W6: =N24 -> 265137.43 | X6: =N23 -> 4661.0739 | Y6: =N26 -> 609.07883 | Z6: =SUM(V6:Y6) -> 1075921.2 | AA6: =L27/C_RATE -> 147.58112 | AB6: =Z6+AA6 -> 1076068.8 | AC6: =N8 -> 1724556.9 | AD6: =AB6-AC6 -> -648488.11 | AE6: =Z6*C_RATE -> 1.4789075e+09 | AF6: EBITDA Margin | AG6: =Z20 -> 0 | AH6: =AA20 -> 0 | AI6: =AB20 -> 0 | AN6: Cost | AO6: =AO7-AO5 -> -1076068.8 | AP6: =AQ6-AO6 -> -4141046.2 | AQ6: -5217115 | AR6: Budgeted opex and 30% cost of sales provision | AX6: Cost of Sales | AY6: =Z7 -> -598475.73 | BC6: Revenue | BD6: =V6*C_RATE -> 1.1072188e+09 | BE6: =W6*C_RATE -> 3.6444465e+08 | BF6: =X6*C_RATE -> 6406879.1 | BG6: =Y6*C_RATE -> 837209.3 | BH6: =SUM(BD6:BG6) -> 1.4789075e+09 | BI6: =AA6*C_RATE -> 202857.63 | BJ6: =BH6+BI6 -> 1.4791104e+09
D7: NGN | E7: NGN | F7: USD | G7: USD | L7: NGN | M7: NGN | N7: USD | O7: USD | S7: =N8/S6 -> 1.0347342 | T7: =N8/T6 -> 0.64670885 | U7: Direct Expenses | V7: ='Segment Report'!Z5 -> -157852.81 | W7: ='Segment Report'!AA5 -> -351581.99 | X7: ='Segment Report'!AB5 -> -54815.184 | Y7: ='Segment Report'!AC5 -> -34225.743 | Z7: =SUM(V7:Y7) -> -598475.73 | AA7: ='Segment Report'!X5 -> -16868.209 | AB7: =Z7+AA7 -> -615343.94 | AC7: =N9 -> -375233.15 | AD7: =AB7-AC7 -> -240110.79 | AE7: =Z7*C_RATE -> -8.2263481e+08 | AF7: Net Income Margin | AG7: =Z16 -> -1.3364953 | AH7: =AA16 -> -11219.184 | AI7: =AB16 -> -2.8750051 | AN7: EBITDA | AO7: =AB21 -> 0 | AP7: =AQ7-AO7 -> 921247 | AQ7: 921247 | AX7: Gross Profit | AY7: =AY5+AY6 -> 477445.51 | BC7: Direct Expenses | BD7: =V7*C_RATE -> -2.1697658e+08 | BE7: =W7*C_RATE -> -4.8326702e+08 | BF7: =X7*C_RATE -> -75346211 | BG7: =Y7*C_RATE -> -47044995 | BH7: =SUM(BD7:BG7) -> -8.2263481e+08 | BI7: =AA7*C_RATE -> -23186197 | BJ7: =BH7+BI7 -> -8.4582101e+08
B8: TOTAL REVENUE | C8: =PROPER(PL_NG!C19) -> Total Revenue | D8: =SUMIFS( INDEX(NG!C:AL, MATCH($B8, NG!$B:$B, 0), ), NG!$C$3:$AL$3, ">="&DATE(YEAR($C$2),1,1), NG!$C$3:$AL$3, "<="&$C$2 ) -> 2.36368e+09 | E8: =SUMIFS( INDEX(NG!C:AL, MATCH($B8, NG!$B:$B, 0), ), NG!$C$3:$AL$3, ">="&DATE(YEAR($C$2)-1,1,1), NG!$C$3:$AL$3, "<="&EDATE($C$2,-12) ) -> 8.7542054e+08 | F8: =D8/$F$3 -> 1719602.7 | G8: =E8/$G$3 -> 546488.88 | H8: =IFERROR(D8/E8-1,0) -> 1.7000508 | K8: Total Revenue | L8: =SUMIFS( INDEX(Group!C:AL, MATCH($B8, Group!$B:$B, 0), ), Group!$C$3:$AL$3, ">="&DATE(YEAR($C$2),1,1), Group!$C$3:$AL$3, "<="&$C$2 ) -> 2.3704897e+09 | M8: =SUMIFS( INDEX(Group!C:AL, MATCH($B8, Group!$B:$B, 0), ), Group!$C$3:$AL$3, ">="&DATE(YEAR($C$2)-1,1,1), Group!$C$3:$AL$3, "<="&EDATE($C$2,-12) ) -> 9.316079e+08 | N8: =L8/$F$3 -> 1724556.9 | O8: =M8/$G$3 -> 581564.33 | P8: =IFERROR(L8/M8-1,0) -> 1.5445144 | Q8: =L8-M8 -> 1.4388818e+09 | R8: =5000000 -> 5000000 | S8: =N8/R8 -> 0.34491139 | T8: =R8-N8 -> 3275443.1 | U8: Contribution per product | V8: =V6+V7 -> 647660.84 | W8: =W6+W7 -> -86444.561 | X8: =X6+X7 -> -50154.11 | Y8: =Y6+Y7 -> -33616.664 | Z8: =Z6+Z7 -> 477445.51 | AA8: =AA6+AA7 -> -16720.628 | AB8: =AB6+AB7 -> 460724.88 | AE8: =Z8*C_RATE -> 6.5627272e+08 | AF8: Payroll Expense | AG8: =-'Segment Report'!Y7 -> 254958.18 | AH8: =-'Segment Report'!X7 -> 397957.54 | AI8: =AG8+AH8 -> 652915.73 | AN8: EBITDA Margin | AO8: =AO7/AO5 -> 0 | AP8: =AP7/AP5 -> 0.18198215 | AQ8: =AQ7/AQ5 -> 0.15008027 | AX8: Gross Margin | AY8: =AY7/AY5 -> 0.44375507 | BC8: Contribution per product | BD8: =BD6+BD7 -> 8.9024221e+08 | BE8: =BE6+BE7 -> -1.1882237e+08 | BF8: =BF6+BF7 -> -68939332 | BG8: =BG6+BG7 -> -46207785 | BH8: =BH6+BH7 -> 6.5627272e+08 | BI8: =BI6+BI7 -> -22983339 | BJ8: =BJ6+BJ7 -> 6.3328938e+08 | BN8: 510 | BO8: 81600000 | BQ8: =T8/8 -> 409430.38
B9: TOTAL COST OF SALES | C9: Cost of Sales | D9: =SUMIFS( INDEX(NG!C:AL, MATCH($B9, NG!$B:$B, 0), ), NG!$C$3:$AL$3, ">="&DATE(YEAR($C$2),1,1), NG!$C$3:$AL$3, "<="&$C$2 ) -> -5.0525847e+08 | E9: =SUMIFS( INDEX(NG!C:AL, MATCH($B9, NG!$B:$B, 0), ), NG!$C$3:$AL$3, ">="&DATE(YEAR($C$2)-1,1,1), NG!$C$3:$AL$3, "<="&EDATE($C$2,-12) ) -> -2.3859699e+08 | F9: =D9/$F$3 -> -367581 | G9: =E9/$G$3 -> -148946.24 | H9: =IFERROR(D9/E9-1,0) -> 1.117623 | K9: Cost of Sales | L9: =SUMIFS( INDEX(Group!C:AL, MATCH($B9, Group!$B:$B, 0), ), Group!$C$3:$AL$3, ">="&DATE(YEAR($C$2),1,1), Group!$C$3:$AL$3, "<="&$C$2 ) -> -5.1577673e+08 | M9: =SUMIFS( INDEX(Group!C:AL, MATCH($B9, Group!$B:$B, 0), ), Group!$C$3:$AL$3, ">="&DATE(YEAR($C$2)-1,1,1), Group!$C$3:$AL$3, "<="&EDATE($C$2,-12) ) -> -2.5840061e+08 | N9: =L9/$F$3 -> -375233.15 | O9: =M9/$G$3 -> -161308.83 | P9: =IFERROR(L9/M9-1,0) -> 0.99603521 | Q9: =L9-M9 -> -2.5737611e+08 | R9: =8000000 -> 8000000 | S9: =N8/R9 -> 0.21556962 | T9: =R9-N8 -> 6275443.1 | U9: Contribution margin % | V9: =IFERROR(V8/V6,"") -> 0.80403459 | W9: =IFERROR(W8/W6,"") -> -0.32603681 | X9: =IFERROR(X8/X6,"") -> -10.760205 | Y9: =IFERROR(Y8/Y6,"") -> -55.192633 | Z9: =IFERROR(Z8/Z6,"") -> 0.44375507 | AA9: =IFERROR(AA8/AA6,"n/a") -> -113.29788 | AB9: =IFERROR(AB8/AB6,"") -> 0.42815559 | AE9: =Z9*C_RATE -> 609.96354 | AF9: Payroll % of Revenue | AG9: =AG8/Z6 -> 0.23696733 | AH9: =IFERROR(AH8/AA6,"n/a") -> 2696.5343 | AI9: =AI8/AB6 -> 0.60676019 | AX9: Other Revenue | AY9: =Z10 -> -134423.63 | BC9: Contribution margin % | BD9: =IFERROR(BD8/BD6,"") -> 0.80403459 | BE9: =IFERROR(BE8/BE6,"") -> -0.32603681 | BF9: =IFERROR(BF8/BF6,"") -> -10.760205 | BG9: =IFERROR(BG8/BG6,"") -> -55.192633 | BH9: =IFERROR(BH8/BH6,"") -> 0.44375507 | BI9: =IFERROR(BI8/BI6,"n/a") -> -113.29788 | BJ9: =IFERROR(BJ8/BJ6,"") -> 0.42815559 | BO9: =BO8/BN8 -> 160000 | BQ9: =T9/8 -> 784430.38
C10: Gross Profit | D10: =D8+D9 -> 1.8584215e+09 | E10: =E8+E9 -> 6.3682356e+08 | F10: =F8+F9 -> 1352021.7 | G10: =G8+G9 -> 397542.64 | H10: =IFERROR(D10/E10-1,0) -> 1.9182675 | K10: Gross Profit | L10: =L8+L9 -> 1.854713e+09 | M10: =M8+M9 -> 6.7320728e+08 | N10: =N8+N9 -> 1349323.8 | O10: =O8+O9 -> 420255.5 | P10: =IFERROR(L10/M10-1,0) -> 1.75504 | Q10: =L10-M10 -> 1.1815057e+09 | U10: Other income | V10: ='Segment Report'!Z6 -> -100639.41 | W10: ='Segment Report'!AA6 -> -33125.786 | X10: ='Segment Report'!AB6 -> -582.34606 | Y10: ='Segment Report'!AC6 -> -76.097196 | Z10: =SUM(V10:Y10) -> -134423.63 | AA10: ='Segment Report'!X6 -> 187121.98 | AB10: =Z10+AA10 -> 52698.344 | AC10: =N11 -> 52698.344 | AD10: =AB10-AC10 -> 0 | AE10: =Z10*C_RATE -> -1.8477201e+08 | AF10: Employee Count | AG10: =L71-AH10 -> -8 | AH10: 8 | AI10: =AG10+AH10 -> 0 | AP10: Target | AQ10: 0.15 | AX10: Operating Expenses | AY10: =SUM('Segment Report'!Y7:Y15,'Segment Report'!Y16) -> -448237.54 | BC10: Other income | BD10: =V10*C_RATE -> -1.3833389e+08 | BE10: =W10*C_RATE -> -45533049 | BF10: =X10*C_RATE -> -800463.77 | BG10: =Y10*C_RATE -> -104599.4 | BH10: =SUM(BD10:BG10) -> -1.8477201e+08 | BI10: =AA10*C_RATE -> 2.5720852e+08 | BJ10: =BH10+BI10 -> 72436509
B11: TOTAL OTHER REVENUE | C11: Other Income | D11: =SUMIFS( INDEX(NG!C:AL, MATCH($B11, NG!$B:$B, 0), ), NG!$C$3:$AL$3, ">="&DATE(YEAR($C$2),1,1), NG!$C$3:$AL$3, "<="&$C$2 ) -> 72436509 | E11: =SUMIFS( INDEX(NG!C:AL, MATCH($B11, NG!$B:$B, 0), ), NG!$C$3:$AL$3, ">="&DATE(YEAR($C$2)-1,1,1), NG!$C$3:$AL$3, "<="&EDATE($C$2,-12) ) -> 1.2825463e+08 | F11: =D11/$F$3 -> 52698.344 | G11: =E11/$G$3 -> 80064.068 | H11: =IFERROR(D11/E11-1,0) -> -0.4352133 | K11: Other Income | L11: =SUMIFS( INDEX(Group!C:AL, MATCH($B11, Group!$B:$B, 0), ), Group!$C$3:$AL$3, ">="&DATE(YEAR($C$2),1,1), Group!$C$3:$AL$3, "<="&$C$2 ) -> 72436509 | M11: =SUMIFS( INDEX(Group!C:AL, MATCH($B11, Group!$B:$B, 0), ), Group!$C$3:$AL$3, ">="&DATE(YEAR($C$2)-1,1,1), Group!$C$3:$AL$3, "<="&EDATE($C$2,-12) ) -> 1.2825828e+08 | N11: =L11/$F$3 -> 52698.344 | O11: =M11/$G$3 -> 80066.349 | P11: =IFERROR(L11/M11-1,0) -> -0.4352294 | Q11: =L11-M11 -> -55821776 | U11: Operating Expenses | V11: =-'Segment Report'!E16/C_RATE -> -768980.96 | W11: =-'Segment Report'!F16/C_RATE -> -893225.65 | X11: =-'Segment Report'!G16/C_RATE -> -41120.557 | Y11: =-'Segment Report'!H16/C_RATE -> -27127.99 | Z11: =SUM(V11:Y11) -> -1730455.2 | AA11: =-'Segment Report'!I16/C_RATE -> -1621394.8 | AB11: =Z11+AA11 -> -3351849.9 | AC11: =N12 -> -952897.47 | AD11: =AB11-AC11 -> -2398952.5 | AE11: =Z11*C_RATE -> -2.3785971e+09 | AF11: Average Revenue per Employee | AG11: =Z6/AG10/MONTH(C2) -> -33622.539 | AH11: n/a | AI11: =AB6/AI10/MONTH(C2) -> #DIV/0! | AN11: Total budget | AO11: 6560351823 | AX11: EBITDA | AY11: =AY7+AY9+AY10 -> -105215.67 | BC11: Operating Expenses | BD11: =V11*C_RATE -> -1057002780 | BE11: =W11*C_RATE -> -1227783317 | BF11: =X11*C_RATE -> -56522261 | BG11: =Y11*C_RATE -> -37288779 | BH11: =SUM(BD11:BG11) -> -2378597137 | BI11: =AA11*C_RATE -> -2228688178 | BJ11: =BH11+BI11 -> -4607285315
B12: TOTAL OPERATING EXPENSES | C12: Total Operating Expenses | D12: =SUMIFS( INDEX(NG!C:AL, MATCH($B12, NG!$B:$B, 0), ), NG!$C$3:$AL$3, ">="&DATE(YEAR($C$2),1,1), NG!$C$3:$AL$3, "<="&$C$2 ) -> -1.0535706e+09 | E12: =SUMIFS( INDEX(NG!C:AL, MATCH($B12, NG!$B:$B, 0), ), NG!$C$3:$AL$3, ">="&DATE(YEAR($C$2)-1,1,1), NG!$C$3:$AL$3, "<="&EDATE($C$2,-12) ) -> -6.9973042e+08 | F12: =D12/$F$3 -> -766484.01 | G12: =E12/$G$3 -> -436812.8 | H12: =IFERROR(D12/E12-1,0) -> 0.50568071 | K12: Total Operating Expenses | L12: =SUMIFS( INDEX(Group!C:AL, MATCH($B12, Group!$B:$B, 0), ), Group!$C$3:$AL$3, ">="&DATE(YEAR($C$2),1,1), Group!$C$3:$AL$3, "<="&$C$2 ) -> -1.3098052e+09 | M12: =SUMIFS( INDEX(Group!C:AL, MATCH($B12, Group!$B:$B, 0), ), Group!$C$3:$AL$3, ">="&DATE(YEAR($C$2)-1,1,1), Group!$C$3:$AL$3, "<="&EDATE($C$2,-12) ) -> -1.0454146e+09 | N12: =L12/$F$3 -> -952897.47 | O12: =M12/$G$3 -> -652609.13 | P12: =IFERROR(L12/M12-1,0) -> 0.25290507 | Q12: =L12-M12 -> -2.6439065e+08 | R12: =L12+PL_NG!AB38+PL_NG!AB39+PL_NG!AB28+PL_NG!AB34+PL_NG!AB30 -> -1.3771453e+09 | S12: =R12/N3 -> -1001888.1 | U12: EBITDA | V12: =V8+V10+V11 -> -221959.52 | W12: =W8+W10+W11 -> -1012796 | X12: =X8+X10+X11 -> -91857.013 | Y12: =Y8+Y10+Y11 -> -60820.751 | Z12: =Z8+Z10+Z11 -> -1387433.3 | AA12: =AA8+AA10+AA11 -> -1450993.4 | AB12: =AB8+AB10+AB11 -> -2838426.7 | AN12: Capex | AO12: 833331500 | AX12: EBITDA Margin | AY12: =AY11/AY5 -> -0.097791234 | BC12: EBITDA | BD12: =BD8+BD10+BD11 -> -3.0509446e+08 | BE12: =BE8+BE10+BE11 -> -1.3921387e+09 | BF12: =BF8+BF10+BF11 -> -1.2626206e+08 | BG12: =BG8+BG10+BG11 -> -83601164 | BH12: =BH8+BH10+BH11 -> -1.9070964e+09 | BI12: =BI8+BI10+BI11 -> -1.994463e+09 | BJ12: =BJ8+BJ10+BJ11 -> -3.9015594e+09
C13: EBITDA | D13: =D10+D11+D12 -> 8.7728741e+08 | E13: =E10+E11+E12 -> 65347768 | F13: =F10+F11+F12 -> 638236.08 | G13: =G10+G11+G12 -> 40793.912 | H13: =IFERROR(D13/E13-1,0) -> 12.424902 | K13: EBITDA | L13: =L10+L11+L12 -> 6.173443e+08 | M13: =M10+M11+M12 -> -2.43949e+08 | N13: =N10+N11+N12 -> 449124.66 | O13: =O10+O11+O12 -> -152287.28 | P13: =IFERROR(L13/M13-1,0) -> -3.5306285 | Q13: =L13-M13 -> 8.6129329e+08 | U13: EBITDA Margin | V13: =V12/V6 -> -0.27555029 | W13: =W12/W6 -> -3.8198907 | X13: =X12/X6 -> -19.707264 | Y13: =Y12/Y6 -> -99.856946 | Z13: =Z12/Z6 -> -1.2895305 | AA13: =AA12/AA6 -> -9831.8365 | AB13: =AB12/AB6 -> -2.6377743 | AF13: Common Size Analysis | AO13: 5727020323 | AX13: Dep, Int & Taxes | AY13: ='Segment Report'!Y17+'Segment Report'!Y18+'Segment Report'!Y19+'Segment Report'!Y20 -> -35392.781 | BC13: EBITDA Margin | BD13: =BD12/BD6 -> -0.27555029 | BE13: =BE12/BE6 -> -3.8198907 | BF13: =BF12/BF6 -> -19.707264 | BG13: =BG12/BG6 -> -99.856946 | BH13: =BH12/BH6 -> -1.2895305 | BI13: =BI12/BI6 -> -9831.8365 | BJ13: =BJ12/BJ6 -> -2.6377743
B14: TOTAL DEPRECIATION & AMORTISATION | C14: Depreciation & Amortisation | D14: =SUMIFS( INDEX(NG!C:AL, MATCH($B14, NG!$B:$B, 0), ), NG!$C$3:$AL$3, ">="&DATE(YEAR($C$2),1,1), NG!$C$3:$AL$3, "<="&$C$2 ) -> -48860521 | E14: =SUMIFS( INDEX(NG!C:AL, MATCH($B14, NG!$B:$B, 0), ), NG!$C$3:$AL$3, ">="&DATE(YEAR($C$2)-1,1,1), NG!$C$3:$AL$3, "<="&EDATE($C$2,-12) ) -> -19017580 | F14: =D14/$F$3 -> -35546.558 | G14: =E14/$G$3 -> -11871.89 | H14: =IFERROR(D14/E14-1,0) -> 1.5692292 | K14: Depreciation & Amortisation | L14: =SUMIFS( INDEX(Group!C:AL, MATCH($B14, Group!$B:$B, 0), ), Group!$C$3:$AL$3, ">="&DATE(YEAR($C$2),1,1), Group!$C$3:$AL$3, "<="&$C$2 ) -> -49839069 | M14: =SUMIFS( INDEX(Group!C:AL, MATCH($B14, Group!$B:$B, 0), ), Group!$C$3:$AL$3, ">="&DATE(YEAR($C$2)-1,1,1), Group!$C$3:$AL$3, "<="&EDATE($C$2,-12) ) -> -20067919 | N14: =L14/$F$3 -> -36258.462 | O14: =M14/$G$3 -> -12527.573 | P14: =IFERROR(L14/M14-1,0) -> 1.4835196 | Q14: =L14-M14 -> -29771150 | U14: Depreciation, Interest Expense & Tax | V14: =-'Segment Report'!E21/C_RATE -> -21474.355 | W14: =-'Segment Report'!F21/C_RATE -> -22845.713 | X14: =-'Segment Report'!G21/C_RATE -> -5541.4339 | Y14: =-'Segment Report'!H21/C_RATE -> -668.91492 | Z14: =SUM(V14:Y14) -> -50530.416 | AA14: =-'Segment Report'!I21/C_RATE -> -204746.25 | AB14: =Z14+AA14 -> -255276.66 | AC14: =N14+N16+N18 -> -36258.462 | AD14: =AB14-AC14 -> -219018.2 | AF14: as a % of Revenue | AO14: 3694851.8 | AX14: NI | AY14: =AY11+AY13 -> -140608.45 | BC14: Depreciation & Interest Expense | BD14: =V14*C_RATE -> -29517574 | BE14: =W14*C_RATE -> -31402575 | BF14: =X14*C_RATE -> -7616978 | BG14: =Y14*C_RATE -> -919457 | BH14: =SUM(BD14:BG14) -> -69456584 | BI14: =AA14*C_RATE -> -281433954 | BJ14: =BH14+BI14 -> -350890538 | BK14: =L14+L16+L18 -> -49839069
C15: EBIT | D15: =D13+D14 -> 8.2842688e+08 | E15: =E13+E14 -> 46330188 | F15: =F13+F14 -> 602689.52 | G15: =G13+G14 -> 28922.023 | H15: =IFERROR(D15/E15-1,0) -> 16.880931 | K15: EBIT | L15: =L13+L14 -> 5.6750523e+08 | M15: =M13+M14 -> -2.6401692e+08 | N15: =N13+N14 -> 412866.19 | O15: =O13+O14 -> -164814.85 | P15: =IFERROR(L15/M15-1,0) -> -3.1495033 | Q15: =L15-M15 -> 8.3152214e+08 | U15: Profit or Loss | V15: =V12+V14 -> -243433.88 | W15: =W12+W14 -> -1035641.7 | X15: =X12+X14 -> -97398.447 | Y15: =Y12+Y14 -> -61489.666 | Z15: =Z12+Z14 -> -1437963.7 | AA15: =AA12+AA14 -> -1655739.7 | AB15: =AB12+AB14 -> -3093703.4 | AE15: =Z15*C_RATE -> -1.976553e+09 | AF15: Cost of Sales | AG15: =-Z9 -> -0.44375507 | AH15: =AA9 -> -113.29788 | AI15: =AB9 -> 0.42815559 | AX15: Net Margin | AY15: =AY14/AY5 -> -0.13068656 | BC15: Profit or Loss | BD15: =BD12+BD14 -> -3.3461204e+08 | BE15: =BE12+BE14 -> -1.4235413e+09 | BF15: =BF12+BF14 -> -1.3387903e+08 | BG15: =BG12+BG14 -> -84520621 | BH15: =BH12+BH14 -> -1.976553e+09 | BI15: =BI12+BI14 -> -2.275897e+09 | BJ15: =BJ12+BJ14 -> -4.25245e+09
B16: TOTAL INTEREST EXPENSES | C16: Interest Expense | D16: =SUMIFS( INDEX(NG!C:AL, MATCH($B16, NG!$B:$B, 0), ), NG!$C$3:$AL$3, ">="&DATE(YEAR($C$2),1,1), NG!$C$3:$AL$3, "<="&$C$2 ) -> 0 | E16: =SUMIFS( INDEX(NG!C:AL, MATCH($B16, NG!$B:$B, 0), ), NG!$C$3:$AL$3, ">="&DATE(YEAR($C$2)-1,1,1), NG!$C$3:$AL$3, "<="&EDATE($C$2,-12) ) -> 0 | F16: =D16/$F$3 -> 0 | G16: =E16/$G$3 -> 0 | H16: =IFERROR(D16/E16-1,0) -> 0 | K16: Interest Expense | L16: =SUMIFS( INDEX(Group!C:AL, MATCH($B16, Group!$B:$B, 0), ), Group!$C$3:$AL$3, ">="&DATE(YEAR($C$2),1,1), Group!$C$3:$AL$3, "<="&$C$2 ) -> 0 | M16: =SUMIFS( INDEX(Group!C:AL, MATCH($B16, Group!$B:$B, 0), ), Group!$C$3:$AL$3, ">="&DATE(YEAR($C$2)-1,1,1), Group!$C$3:$AL$3, "<="&EDATE($C$2,-12) ) -> 0 | N16: =L16/$F$3 -> 0 | O16: =M16/$G$3 -> 0 | P16: =IFERROR(L16/M16-1,0) -> 0 | Q16: =L16-M16 -> 0 | U16: Profit Margin | V16: =IFERROR(V15/V6,"") -> -0.3022095 | W16: =IFERROR(W15/W6,"") -> -3.9060563 | X16: =IFERROR(X15/X6,"") -> -20.896139 | Y16: =IFERROR(Y15/Y6,"") -> -100.95519 | Z16: =IFERROR(Z15/Z6,"") -> -1.3364953 | AA16: =IFERROR(AA15/AA6,"n/a") -> -11219.184 | AB16: =IFERROR(AB15/AB6,"") -> -2.8750051 | AE16: =Z16*C_RATE -> -1837.0796 | AF16: Operating Expenses | AG16: ='Segment Report'!Y21/Summary!Z6 -> -0.44950346 | AH16: n/a | AI16: ='Segment Report'!W21/Summary!AB6 -> -0.9192311 | BC16: Profit Margin | BD16: =IFERROR(BD15/BD6,"") -> -0.3022095 | BE16: =IFERROR(BE15/BE6,"") -> -3.9060563 | BF16: =IFERROR(BF15/BF6,"") -> -20.896139 | BG16: =IFERROR(BG15/BG6,"") -> -100.95519 | BH16: =IFERROR(BH15/BH6,"") -> -1.3364953 | BI16: =IFERROR(BI15/BI6,"n/a") -> -11219.184 | BJ16: =IFERROR(BJ15/BJ6,"") -> -2.8750051
C17: Profit before Tax | D17: =D15+D16 -> 8.2842688e+08 | E17: =E15+E16 -> 46330188 | F17: =F15+F16 -> 602689.52 | G17: =G15+G16 -> 28922.023 | H17: =IFERROR(D17/E17-1,0) -> 16.880931 | K17: Profit before Tax | L17: =L15+L16 -> 5.6750523e+08 | M17: =M15+M16 -> -2.6401692e+08 | N17: =N15+N16 -> 412866.19 | O17: =O15+O16 -> -164814.85 | P17: =IFERROR(L17/M17-1,0) -> -3.1495033 | Q17: =L17-M17 -> 8.3152214e+08 | U17: Expense to Income Ratio | V17: =100%-V16 -> 1.3022095 | W17: =100%-W16 -> 4.9060563 | X17: =100%-X16 -> 21.896139 | Y17: =100%-Y16 -> 101.95519 | Z17: =100%-Z16 -> 2.3364953 | AA17: =100%-AA16 -> 11220.184 | AB17: =100%-AB16 -> 3.8750051 | AE17: =Z17*C_RATE -> 3211.6296 | AF17: Total Cost | AG17: =Z17 -> 2.3364953 | AH17: n/a | AI17: =AB17 -> 3.8750051 | BC17: Expense to Income Ratio | BD17: =100%-BD16 -> 1.3022095 | BE17: =100%-BE16 -> 4.9060563 | BF17: =100%-BF16 -> 21.896139 | BG17: =100%-BG16 -> 101.95519 | BH17: =100%-BH16 -> 2.3364953 | BI17: =100%-BI16 -> 11220.184 | BJ17: =100%-BJ16 -> 3.8750051
B18: TOTAL TAX EXPENSES | C18: Tax Expense | D18: =SUMIFS( INDEX(NG!C:AL, MATCH($B18, NG!$B:$B, 0), ), NG!$C$3:$AL$3, ">="&DATE(YEAR($C$2),1,1), NG!$C$3:$AL$3, "<="&$C$2 ) -> 0 | E18: =SUMIFS( INDEX(NG!C:AL, MATCH($B18, NG!$B:$B, 0), ), NG!$C$3:$AL$3, ">="&DATE(YEAR($C$2)-1,1,1), NG!$C$3:$AL$3, "<="&EDATE($C$2,-12) ) -> 0 | F18: =D18/$F$3 -> 0 | G18: =E18/$G$3 -> 0 | H18: =IFERROR(D18/E18-1,0) -> 0 | K18: Tax Expense | L18: =SUMIFS( INDEX(Group!C:AL, MATCH($B18, Group!$B:$B, 0), ), Group!$C$3:$AL$3, ">="&DATE(YEAR($C$2),1,1), Group!$C$3:$AL$3, "<="&$C$2 ) -> 0 | M18: =SUMIFS( INDEX(Group!C:AL, MATCH($B18, Group!$B:$B, 0), ), Group!$C$3:$AL$3, ">="&DATE(YEAR($C$2)-1,1,1), Group!$C$3:$AL$3, "<="&EDATE($C$2,-12) ) -> 0 | N18: =L18/$F$3 -> 0 | O18: =M18/$G$3 -> 0 | P18: =IFERROR(L18/M18-1,0) -> 0 | Q18: =L18-M18 -> 0 | U18: *Others- Next Gen, Rose of Sharon & Hardware | Z18: =(Z11+Z14)*C_RATE -> -2.4480537e+09 | AA18: =(AA11+AA14)*C_RATE -> -2510122132 | BC18: *Others- Next Gen, Rose of Sharon & Hardware | BH18: =(BH11+BH14) -> -2448053721 | BI18: =(BI11+BI14) -> -2510122132
C19: Profit After Tax | D19: =D17+D18 -> 8.2842688e+08 | E19: =E17+E18 -> 46330188 | F19: =F17+F18 -> 602689.52 | G19: =G17+G18 -> 28922.023 | H19: =IFERROR(D19/E19-1,0) -> 16.880931 | K19: Profit After Tax | L19: =L17+L18 -> 5.6750523e+08 | M19: =M17+M18 -> -2.6401692e+08 | N19: =N17+N18 -> 412866.19 | O19: =O17+O18 -> -164814.85 | P19: =IFERROR(L19/M19-1,0) -> -3.1495033 | Q19: =L19-M19 -> 8.3152214e+08
D20: =D12+D16+D14+D18 -> -1.1024311e+09 | L20: =L12+L16+L14+L18 -> -1.3596443e+09 | U20: =L12+L14+L16+L18 -> -1.3596443e+09
U21: =L13/L8 -> 0.26042901 | V21: =M16+M18 -> 0 | AD21: =AD11*C_RATE -> -3.2974801e+09 | AE21: =Z21*C_RATE -> 0 | AF21: Ratios | AG21: CONSULTING | AH21: PRODUCT-FIXIAM | AI21: GROUP TOTAL
C22: Revenue by Vertical | D22: =D7 -> NGN | E22: =E7 -> NGN | F22: =F7 -> USD | G22: =G7 -> USD | K22: Revenue by Vertical | L22: =D22 -> NGN | M22: =E22 -> NGN | N22: =F22 -> USD | O22: =G22 -> USD | AF22: Current Ratio | AG22: =(W30+W29)/W34 -> 0.97912996 | AH22: n/a | AI22: =(AA30+AA29)/AA34 -> 2.1085441
B23: Verify | C23: Identity Suite | D23: =SUMIFS( INDEX(NG!C:AL, MATCH($B23, NG!$B:$B, 0), ), NG!$C$3:$AL$3, ">="&DATE(YEAR($C$2),1,1), NG!$C$3:$AL$3, "<="&$C$2 ) -> 0 | E23: =SUMIFS( INDEX(NG!C:AL, MATCH($B23, NG!$B:$B, 0), ), NG!$C$3:$AL$3, ">="&DATE(YEAR($C$2)-1,1,1), NG!$C$3:$AL$3, "<="&EDATE($C$2,-12) ) -> 29039114 | F23: =D23/$F$3 -> 0 | G23: =E23/$G$3 -> 18127.919 | H23: =IFERROR(D23/E23-1,0) -> -1 | I23: =D23/$D$28 -> 0 | K23: Identity Suite | L23: =SUMIFS( INDEX(Group!C:AL, MATCH($B23, Group!$B:$B, 0), ), Group!$C$3:$AL$3, ">="&DATE(YEAR($C$2),1,1), Group!$C$3:$AL$3, "<="&$C$2 ) -> 6406879.1 | M23: =SUMIFS( INDEX(Group!C:AL, MATCH($B23, Group!$B:$B, 0), ), Group!$C$3:$AL$3, ">="&DATE(YEAR($C$2)-1,1,1), Group!$C$3:$AL$3, "<="&EDATE($C$2,-12) ) -> 34044054 | N23: =L23/$F$3 -> 4661.0739 | O23: =M23/$G$3 -> 21252.297 | P23: =IFERROR(L23/M23-1,0) -> -0.81180622 | S23: =N23/$N$28 -> 0.004331576 | T23: =O23/$O$28 -> 0.036543329 | AF23: Asset turnover ratio (Times) | AG23: =Z6/W31 -> 0.52779646 | AH23: n/a | AI23: =AB6/AA31 -> 0.23124478
B24: Telco | C24: Telco Suite | D24: =SUMIFS( INDEX(NG!C:AL, MATCH($B24, NG!$B:$B, 0), ), NG!$C$3:$AL$3, ">="&DATE(YEAR($C$2),1,1), NG!$C$3:$AL$3, "<="&$C$2 ) -> 3.6444465e+08 | E24: =SUMIFS( INDEX(NG!C:AL, MATCH($B24, NG!$B:$B, 0), ), NG!$C$3:$AL$3, ">="&DATE(YEAR($C$2)-1,1,1), NG!$C$3:$AL$3, "<="&EDATE($C$2,-12) ) -> 399567769 | F24: =D24/$F$3 -> 265137.43 | G24: =E24/$G$3 -> 249433.65 | H24: =IFERROR(D24/E24-1,0) -> -0.087902779 | I24: =D24/$D$28 -> 0.2475005 | K24: Telco Suite | L24: =SUMIFS( INDEX(Group!C:AL, MATCH($B24, Group!$B:$B, 0), ), Group!$C$3:$AL$3, ">="&DATE(YEAR($C$2),1,1), Group!$C$3:$AL$3, "<="&$C$2 ) -> 3.6444465e+08 | M24: =SUMIFS( INDEX(Group!C:AL, MATCH($B24, Group!$B:$B, 0), ), Group!$C$3:$AL$3, ">="&DATE(YEAR($C$2)-1,1,1), Group!$C$3:$AL$3, "<="&EDATE($C$2,-12) ) -> 399567769 | N24: =L24/$F$3 -> 265137.43 | O24: =M24/$G$3 -> 249433.65 | P24: =IFERROR(L24/M24-1,0) -> -0.087902779 | S24: =N24/$N$28 -> 0.24639449 | T24: =O24/$O$28 -> 0.42890122 | AF24: Receivables turnover ratio (Times) | AG24: =Z6/'Segment Report'!S57 -> 2.4888134 | AH24: n/a | AI24: =AG24 -> 2.4888134
B25: Public Sector | C25: Public Sector Suite | D25: =SUMIFS( INDEX(NG!C:AL, MATCH($B25, NG!$B:$B, 0), ), NG!$C$3:$AL$3, ">="&DATE(YEAR($C$2),1,1), NG!$C$3:$AL$3, "<="&$C$2 ) -> 1.1072188e+09 | E25: =SUMIFS( INDEX(NG!C:AL, MATCH($B25, NG!$B:$B, 0), ), NG!$C$3:$AL$3, ">="&DATE(YEAR($C$2)-1,1,1), NG!$C$3:$AL$3, "<="&EDATE($C$2,-12) ) -> 428038702 | F25: =D25/$F$3 -> 805513.66 | G25: =E25/$G$3 -> 267206.88 | H25: =IFERROR(D25/E25-1,0) -> 1.5867259 | I25: =D25/$D$28 -> 0.75193094 | K25: Public Sector Suite | L25: =SUMIFS( INDEX(Group!C:AL, MATCH($B25, Group!$B:$B, 0), ), Group!$C$3:$AL$3, ">="&DATE(YEAR($C$2),1,1), Group!$C$3:$AL$3, "<="&$C$2 ) -> 1.1072188e+09 | M25: =SUMIFS( INDEX(Group!C:AL, MATCH($B25, Group!$B:$B, 0), ), Group!$C$3:$AL$3, ">="&DATE(YEAR($C$2)-1,1,1), Group!$C$3:$AL$3, "<="&EDATE($C$2,-12) ) -> 4.7922112e+08 | N25: =L25/$F$3 -> 805513.66 | O25: =M25/$G$3 -> 299157.95 | P25: =IFERROR(L25/M25-1,0) -> 1.3104549 | S25: =N25/$N$28 -> 0.74857076 | T25: =O25/$O$28 -> 0.51440216 | U25: SEGMENTED BALANCE SHEET | AF25: Average Receivable Days Outstanding (Days) | AG25: =(D$6-DATE(2025,1,1))/AG24 -> 194.47018 | AH25: n/a | AI25: =(F$6-DATE(2025,1,1))/AI24 -> 194.47018
B26: Others | C26: Others | D26: =SUMIFS( INDEX(NG!C:AL, MATCH($B26, NG!$B:$B, 0), ), NG!$C$3:$AL$3, ">="&DATE(YEAR($C$2),1,1), NG!$C$3:$AL$3, "<="&$C$2 ) -> 837209.3 | E26: =SUMIFS( INDEX(NG!C:AL, MATCH($B26, NG!$B:$B, 0), ), NG!$C$3:$AL$3, ">="&DATE(YEAR($C$2)-1,1,1), NG!$C$3:$AL$3, "<="&EDATE($C$2,-12) ) -> 18774958 | F26: =D26/$F$3 -> 609.07883 | G26: =E26/$G$3 -> 11720.431 | H26: =IFERROR(D26/E26-1,0) -> -0.95540819 | I26: =D26/$D$28 -> 0.00056856294 | K26: Others | L26: =SUMIFS( INDEX(Group!C:AL, MATCH($B26, Group!$B:$B, 0), ), Group!$C$3:$AL$3, ">="&DATE(YEAR($C$2),1,1), Group!$C$3:$AL$3, "<="&$C$2 ) -> 837209.3 | M26: =SUMIFS( INDEX(Group!C:AL, MATCH($B26, Group!$B:$B, 0), ), Group!$C$3:$AL$3, ">="&DATE(YEAR($C$2)-1,1,1), Group!$C$3:$AL$3, "<="&EDATE($C$2,-12) ) -> 18774958 | N26: =L26/$F$3 -> 609.07883 | O26: =M26/$G$3 -> 11720.431 | P26: =IFERROR(L26/M26-1,0) -> -0.95540819 | S26: =N26/$N$28 -> 0.00056602219 | T26: =O26/$O$28 -> 0.020153283 | V26: CONSULTING BUSINESS | X26: PRODUCT BUSINESS | Z26: TOTAL | AF26: Working capital turnover | AG26: =Z6/(W29+W30-W34) -> -36.483476 | AH26: n/a | AI26: =AB6/(AA29+AA30-AA34) -> 0.68676204
B27: Fixiam | C27: Fixiam | D27: =SUMIFS( INDEX(NG!C:AL, MATCH($B27, NG!$B:$B, 0), ), NG!$C$3:$AL$3, ">="&DATE(YEAR($C$2),1,1), NG!$C$3:$AL$3, "<="&$C$2 ) -> 0 | E27: =SUMIFS( INDEX(NG!C:AL, MATCH($B27, NG!$B:$B, 0), ), NG!$C$3:$AL$3, ">="&DATE(YEAR($C$2)-1,1,1), NG!$C$3:$AL$3, "<="&EDATE($C$2,-12) ) -> 0 | F27: =D27/$F$3 -> 0 | G27: =E27/$G$3 -> 0 | H27: =IFERROR(D27/E27-1,0) -> 0 | K27: Fixiam | L27: =SUMIFS( INDEX(Group!C:AL, MATCH($B27, Group!$B:$B, 0), ), Group!$C$3:$AL$3, ">="&DATE(YEAR($C$2),1,1), Group!$C$3:$AL$3, "<="&$C$2 ) -> 202857.63 | M27: =SUMIFS( INDEX(Group!C:AL, MATCH($B27, Group!$B:$B, 0), ), Group!$C$3:$AL$3, ">="&DATE(YEAR($C$2)-1,1,1), Group!$C$3:$AL$3, "<="&EDATE($C$2,-12) ) -> 0 | N27: =L27/$F$3 -> 147.58112 | O27: =M27/$G$3 -> 0 | P27: =IFERROR(L27/M27-1,0) -> 0 | S27: =N27/$N$28 -> 0.0001371484 | T27: =O27/$O$28 -> 0 | U27: Financial Position Summary | V27: NGN | W27: USD | X27: NGN | Y27: USD | Z27: NGN | AA27: USD | AF27: Payables turnover ratio (Times) | AG27: =-Z7/'Segment Report'!S67 -> 2.3589477 | AH27: n/a | AI27: =-AB7/'Segment Report'!T67 -> 2.4254353
B28: Total | C28: Total | D28: =SUM(D23:D27) -> 1.4725007e+09 | E28: =SUM(E23:E27) -> 875420543 | F28: =SUM(F23:F27) -> 1071260.2 | G28: =SUM(G23:G27) -> 546488.88 | H28: =IFERROR(D28/E28-1,0) -> 0.68204947 | K28: Total | L28: =SUM(L23:L27) -> 1.4791104e+09 | M28: =SUM(M23:M27) -> 9.316079e+08 | N28: =L28/$F$3 -> 1076068.8 | O28: =M28/$G$3 -> 581564.33 | P28: =IFERROR(L28/M28-1,0) -> 0.58769627 | U28: Non Current Assets | V28: =SUM('Segment Report'!Q63:Q65) -> 9.0025456e+08 | W28: =V28/C_RATE -> 654944.94 | X28: =SUM('Segment Report'!P63:P65) -> 1.3994385e+09 | Y28: =X28/C_RATE -> 1018106.7 | Z28: =V28+X28 -> 2.2996931e+09 | AA28: =W28+Y28 -> 1673051.6 | AF28: Average Payables Days Outstanding (Days) | AG28: =(D$6-DATE(2025,1,1))/AG27 -> 205.17623 | AH28: n/a | AI28: =(F$6-DATE(2025,1,1))/AI27 -> 199.55181
D29: =D8-D28 -> 8.911793e+08 | E29: =E8-E28 -> -1.1700001 | L29: =L8-L28 -> 8.9137933e+08 | M29: =M8-M28 -> -1.17 | U29: Cash & Cash Equivalent | V29: ='Segment Report'!Q56 -> 4.4852083e+08 | W29: =V29/C_RATE -> 326303.76 | X29: ='Segment Report'!P56 -> 2.1948175e+09 | Y29: =X29/C_RATE -> 1596753.5 | Z29: =V29+X29 -> 2.6433384e+09 | AA29: =W29+Y29 -> 1923057.3 | AF29: ROA | AG29: =Z15/W31 -> -0.7053975 | AH29: =AA15/Y31 -> -0.63320389 | AI29: =AB15/AA31 -> -0.66482992
U30: Current Assets | V30: =SUM('Segment Report'!Q57:Q62) -> 1.453266e+09 | W30: =V30/C_RATE -> 1057266.8 | X30: =SUM('Segment Report'!P57:P62) -> 0 | Y30: =X30/C_RATE -> 0 | Z30: =V30+X30 -> 1.453266e+09 | AA30: =W30+Y30 -> 1057266.8 | AF30: ROE | AG30: =Z15/W39 -> -3.0353926 | AH30: =AA15/Y39 -> -0.62040548 | AI30: =AB15/AA39 -> -0.98446113
C31: Revenue by Customer | D31: NGN | E31: NGN | F31: USD | G31: USD | K31: Revenue by Customer | L31: NGN | M31: NGN | N31: USD | O31: USD | U31: Total Assets | V31: =SUM(V28:V30) -> 2.8020414e+09 | W31: =SUM(W28:W30) -> 2038515.4 | X31: =SUM(X28:X30) -> 3.5942561e+09 | Y31: =SUM(Y28:Y30) -> 2614860.2 | Z31: =SUM(Z28:Z30) -> 6.3962975e+09 | AA31: =SUM(AA28:AA30) -> 4653375.7
B32: MTN Nigeria | C32: MTN Nigeria | D32: =SUMIFS( INDEX(NG!C:AL, MATCH($B32, NG!$B:$B, 0), ), NG!$C$3:$AL$3, ">="&DATE(YEAR($C$2),1,1), NG!$C$3:$AL$3, "<="&$C$2 ) -> 74230520 | E32: =SUMIFS( INDEX(NG!C:AL, MATCH($B32, NG!$B:$B, 0), ), NG!$C$3:$AL$3, ">="&DATE(YEAR($C$2)-1,1,1), NG!$C$3:$AL$3, "<="&EDATE($C$2,-12) ) -> 3.893693e+08 | F32: =D32/$F$3 -> 54003.507 | G32: =E32/$G$3 -> 243067.17 | H32: =IFERROR(D32/E32-1,0) -> -0.80935703 | K32: MTN Nigeria | L32: =SUMIFS( INDEX(Group!C:AL, MATCH($B32, Group!$B:$B, 0), ), Group!$C$3:$AL$3, ">="&DATE(YEAR($C$2),1,1), Group!$C$3:$AL$3, "<="&$C$2 ) -> 74230520 | M32: =SUMIFS( INDEX(Group!C:AL, MATCH($B32, Group!$B:$B, 0), ), Group!$C$3:$AL$3, ">="&DATE(YEAR($C$2)-1,1,1), Group!$C$3:$AL$3, "<="&EDATE($C$2,-12) ) -> 3.893693e+08 | N32: =L32/$F$3 -> 54003.507 | O32: =M32/$G$3 -> 243067.17 | P32: =IFERROR(L32/M32-1,0) -> -0.80935703
B33: Globacom | C33: Globacom | D33: =SUMIFS( INDEX(NG!C:AL, MATCH($B33, NG!$B:$B, 0), ), NG!$C$3:$AL$3, ">="&DATE(YEAR($C$2),1,1), NG!$C$3:$AL$3, "<="&$C$2 ) -> 2.1006136e+08 | E33: =SUMIFS( INDEX(NG!C:AL, MATCH($B33, NG!$B:$B, 0), ), NG!$C$3:$AL$3, ">="&DATE(YEAR($C$2)-1,1,1), NG!$C$3:$AL$3, "<="&EDATE($C$2,-12) ) -> 113530466 | F33: =D33/$F$3 -> 152821.91 | G33: =E33/$G$3 -> 70872.38 | H33: =IFERROR(D33/E33-1,0) -> 0.8502642 | K33: Globacom | L33: =SUMIFS( INDEX(Group!C:AL, MATCH($B33, Group!$B:$B, 0), ), Group!$C$3:$AL$3, ">="&DATE(YEAR($C$2),1,1), Group!$C$3:$AL$3, "<="&$C$2 ) -> 2.1006136e+08 | M33: =SUMIFS( INDEX(Group!C:AL, MATCH($B33, Group!$B:$B, 0), ), Group!$C$3:$AL$3, ">="&DATE(YEAR($C$2)-1,1,1), Group!$C$3:$AL$3, "<="&EDATE($C$2,-12) ) -> 113530466 | N33: =L33/$F$3 -> 152821.91 | O33: =M33/$G$3 -> 70872.38 | P33: =IFERROR(L33/M33-1,0) -> 0.8502642 | U33: Non current Liabilities | V33: ='Segment Report'!Q66 -> 21499461 | W33: =V33/C_RATE -> 15641.09 | X33: ='Segment Report'!P66 -> 0 | Y33: =X33/C_RATE -> 0 | Z33: =V33+X33 -> 21499461 | AA33: =W33+Y33 -> 15641.09
B34: UNN | C34: UNN | D34: =SUMIFS( INDEX(NG!C:AL, MATCH($B34, NG!$B:$B, 0), ), NG!$C$3:$AL$3, ">="&DATE(YEAR($C$2),1,1), NG!$C$3:$AL$3, "<="&$C$2 ) -> 31897727 | E34: =SUMIFS( INDEX(NG!C:AL, MATCH($B34, NG!$B:$B, 0), ), NG!$C$3:$AL$3, ">="&DATE(YEAR($C$2)-1,1,1), NG!$C$3:$AL$3, "<="&EDATE($C$2,-12) ) -> 1.2810687e+08 | F34: =D34/$F$3 -> 23205.941 | G34: =E34/$G$3 -> 79971.827 | H34: =IFERROR(D34/E34-1,0) -> -0.7510069 | K34: UNN | L34: =SUMIFS( INDEX(Group!C:AL, MATCH($B34, Group!$B:$B, 0), ), Group!$C$3:$AL$3, ">="&DATE(YEAR($C$2),1,1), Group!$C$3:$AL$3, "<="&$C$2 ) -> 31897727 | M34: =SUMIFS( INDEX(Group!C:AL, MATCH($B34, Group!$B:$B, 0), ), Group!$C$3:$AL$3, ">="&DATE(YEAR($C$2)-1,1,1), Group!$C$3:$AL$3, "<="&EDATE($C$2,-12) ) -> 1.2810687e+08 | N34: =L34/$F$3 -> 23205.941 | O34: =M34/$G$3 -> 79971.827 | P34: =IFERROR(L34/M34-1,0) -> -0.7510069 | U34: Current Liabilities | V34: =SUM('Segment Report'!Q67:Q70) -> 1.9423232e+09 | W34: =V34/C_RATE -> 1413061.2 | X34: =SUM('Segment Report'!P67:P70) -> 536074.5 | Y34: =X34/C_RATE -> 390 | Z34: =V34+X34 -> 1.9428593e+09 | AA34: =W34+Y34 -> 1413451.2
B35: NIMC | C35: NIMC | D35: =SUMIFS( INDEX(NG!C:AL, MATCH($B35, NG!$B:$B, 0), ), NG!$C$3:$AL$3, ">="&DATE(YEAR($C$2),1,1), NG!$C$3:$AL$3, "<="&$C$2 ) -> 1.0434591e+09 | E35: =SUMIFS( INDEX(NG!C:AL, MATCH($B35, NG!$B:$B, 0), ), NG!$C$3:$AL$3, ">="&DATE(YEAR($C$2)-1,1,1), NG!$C$3:$AL$3, "<="&EDATE($C$2,-12) ) -> 1.9659983e+08 | F35: =D35/$F$3 -> 759127.82 | G35: =E35/$G$3 -> 122729.15 | H35: =IFERROR(D35/E35-1,0) -> 4.3075281 | K35: NIMC | L35: =SUMIFS( INDEX(Group!C:AL, MATCH($B35, Group!$B:$B, 0), ), Group!$C$3:$AL$3, ">="&DATE(YEAR($C$2),1,1), Group!$C$3:$AL$3, "<="&$C$2 ) -> 1.0434591e+09 | M35: =SUMIFS( INDEX(Group!C:AL, MATCH($B35, Group!$B:$B, 0), ), Group!$C$3:$AL$3, ">="&DATE(YEAR($C$2)-1,1,1), Group!$C$3:$AL$3, "<="&EDATE($C$2,-12) ) -> 1.9659983e+08 | N35: =L35/$F$3 -> 759127.82 | O35: =M35/$G$3 -> 122729.15 | P35: =IFERROR(L35/M35-1,0) -> 4.3075281 | R35: =L35/L8 -> 0.44018716 | U35: Total Liabilities | V35: =SUM(V33:V34) -> 1.9638227e+09 | W35: =SUM(W33:W34) -> 1428702.2 | X35: =SUM(X33:X34) -> 536074.5 | Y35: =SUM(Y33:Y34) -> 390 | Z35: =SUM(Z33:Z34) -> 1.9643588e+09 | AA35: =SUM(AA33:AA34) -> 1429092.2
B36: Orange Liberia | C36: Orange Liberia | D36: =SUMIFS( INDEX(NG!C:AL, MATCH($B36, NG!$B:$B, 0), ), NG!$C$3:$AL$3, ">="&DATE(YEAR($C$2),1,1), NG!$C$3:$AL$3, "<="&$C$2 ) -> 44042974 | E36: =SUMIFS( INDEX(NG!C:AL, MATCH($B36, NG!$B:$B, 0), ), NG!$C$3:$AL$3, ">="&DATE(YEAR($C$2)-1,1,1), NG!$C$3:$AL$3, "<="&EDATE($C$2,-12) ) -> 0 | F36: =D36/$F$3 -> 32041.74 | G36: =E36/$G$3 -> 0 | H36: =IFERROR(D36/E36-1,0) -> 0 | K36: Orange Liberia | L36: =SUMIFS( INDEX(Group!C:AL, MATCH($B36, Group!$B:$B, 0), ), Group!$C$3:$AL$3, ">="&DATE(YEAR($C$2),1,1), Group!$C$3:$AL$3, "<="&$C$2 ) -> 44042974 | M36: =SUMIFS( INDEX(Group!C:AL, MATCH($B36, Group!$B:$B, 0), ), Group!$C$3:$AL$3, ">="&DATE(YEAR($C$2)-1,1,1), Group!$C$3:$AL$3, "<="&EDATE($C$2,-12) ) -> 0 | N36: =L36/$F$3 -> 32041.74 | O36: =M36/$G$3 -> 0 | P36: =IFERROR(L36/M36-1,0) -> 0
B37: MTN CIV | C37: MTN CIV | D37: =SUMIFS( INDEX(NG!C:AL, MATCH($B37, NG!$B:$B, 0), ), NG!$C$3:$AL$3, ">="&DATE(YEAR($C$2),1,1), NG!$C$3:$AL$3, "<="&$C$2 ) -> 35992741 | E37: =SUMIFS( INDEX(NG!C:AL, MATCH($B37, NG!$B:$B, 0), ), NG!$C$3:$AL$3, ">="&DATE(YEAR($C$2)-1,1,1), NG!$C$3:$AL$3, "<="&EDATE($C$2,-12) ) -> 0 | F37: =D37/$F$3 -> 26185.109 | G37: =E37/$G$3 -> 0 | H37: =IFERROR(D37/E37-1,0) -> 0 | K37: MTN CIV | L37: =SUMIFS( INDEX(Group!C:AL, MATCH($B37, Group!$B:$B, 0), ), Group!$C$3:$AL$3, ">="&DATE(YEAR($C$2),1,1), Group!$C$3:$AL$3, "<="&$C$2 ) -> 35992741 | M37: =SUMIFS( INDEX(Group!C:AL, MATCH($B37, Group!$B:$B, 0), ), Group!$C$3:$AL$3, ">="&DATE(YEAR($C$2)-1,1,1), Group!$C$3:$AL$3, "<="&EDATE($C$2,-12) ) -> 0 | N37: =L37/$F$3 -> 26185.109 | O37: =M37/$G$3 -> 0 | P37: =IFERROR(L37/M37-1,0) -> 0 | U37: Equity | V37: =SUM('Segment Report'!Q71) -> 2.1702404e+08 | W37: =V37/C_RATE -> 157887.34 | X37: =SUM('Segment Report'!P71) -> 6489017168 | Y37: =X37/C_RATE -> 4720830.2 | Z37: =V37+X37 -> 6.7060412e+09 | AA37: =W37+Y37 -> 4878717.6
B38: Verified Customers | C38: Verified Customers | D38: =SUMIFS( INDEX(NG!C:AL, MATCH($B38, NG!$B:$B, 0), ), NG!$C$3:$AL$3, ">="&DATE(YEAR($C$2),1,1), NG!$C$3:$AL$3, "<="&$C$2 ) -> 0 | E38: =SUMIFS( INDEX(NG!C:AL, MATCH($B38, NG!$B:$B, 0), ), NG!$C$3:$AL$3, ">="&DATE(YEAR($C$2)-1,1,1), NG!$C$3:$AL$3, "<="&EDATE($C$2,-12) ) -> 6942928.8 | F38: =D38/$F$3 -> 0 | G38: =E38/$G$3 -> 4334.1837 | H38: =IFERROR(D38/E38-1,0) -> -1 | K38: Verified Customers | L38: =SUMIFS( INDEX(Group!C:AL, MATCH($B38, Group!$B:$B, 0), ), Group!$C$3:$AL$3, ">="&DATE(YEAR($C$2),1,1), Group!$C$3:$AL$3, "<="&$C$2 ) -> 0 | M38: =SUMIFS( INDEX(Group!C:AL, MATCH($B38, Group!$B:$B, 0), ), Group!$C$3:$AL$3, ">="&DATE(YEAR($C$2)-1,1,1), Group!$C$3:$AL$3, "<="&EDATE($C$2,-12) ) -> 6942928.8 | N38: =L38/$F$3 -> 0 | O38: =M38/$G$3 -> 4334.1837 | P38: =IFERROR(L38/M38-1,0) -> -1 | U38: Retained Earnings | V38: =SUM('Segment Report'!Q72) -> 4.3414477e+08 | W38: =V38/C_RATE -> 315845.02 | X38: =SUM('Segment Report'!P72) -> -2.8206148e+09 | Y38: =X38/C_RATE -> -2052027.8 | Z38: =V38+X38 -> -2.38647e+09 | AA38: =W38+Y38 -> -1736182.7
B39: Others Customers | C39: Others Customers | D39: =SUMIFS( INDEX(NG!C:AL, MATCH($B39, NG!$B:$B, 0), ), NG!$C$3:$AL$3, ">="&DATE(YEAR($C$2),1,1), NG!$C$3:$AL$3, "<="&$C$2 ) -> 8930232.6 | E39: =SUMIFS( INDEX(NG!C:AL, MATCH($B39, NG!$B:$B, 0), ), NG!$C$3:$AL$3, ">="&DATE(YEAR($C$2)-1,1,1), NG!$C$3:$AL$3, "<="&EDATE($C$2,-12) ) -> 40871142 | F39: =D39/$F$3 -> 6496.8408 | G39: =E39/$G$3 -> 25514.166 | H39: =IFERROR(D39/E39-1,0) -> -0.78150274 | K39: Others Customers | L39: =SUMIFS( INDEX(Group!C:AL, MATCH($B39, Group!$B:$B, 0), ), Group!$C$3:$AL$3, ">="&DATE(YEAR($C$2),1,1), Group!$C$3:$AL$3, "<="&$C$2 ) -> 8930232.6 | M39: =SUMIFS( INDEX(Group!C:AL, MATCH($B39, Group!$B:$B, 0), ), Group!$C$3:$AL$3, ">="&DATE(YEAR($C$2)-1,1,1), Group!$C$3:$AL$3, "<="&EDATE($C$2,-12) ) -> 40871142 | N39: =L39/$F$3 -> 6496.8408 | O39: =M39/$G$3 -> 25514.166 | P39: =IFERROR(L39/M39-1,0) -> -0.78150274 | U39: Total Equity | V39: =V37+V38 -> 6.5116881e+08 | W39: =V39/C_RATE -> 473732.36 | X39: =X37+X38 -> 3.6684024e+09 | Y39: =X39/C_RATE -> 2668802.5 | Z39: =Z37+Z38 -> 4.3195712e+09 | AA39: =AA37+AA38 -> 3142534.8
B40: MFA Benin | C40: MFA Benin | D40: =SUMIFS( INDEX(NG!C:AL, MATCH($B40, NG!$B:$B, 0), ), NG!$C$3:$AL$3, ">="&DATE(YEAR($C$2),1,1), NG!$C$3:$AL$3, "<="&$C$2 ) -> 23885962 | E40: =SUMIFS( INDEX(NG!C:AL, MATCH($B40, NG!$B:$B, 0), ), NG!$C$3:$AL$3, ">="&DATE(YEAR($C$2)-1,1,1), NG!$C$3:$AL$3, "<="&EDATE($C$2,-12) ) -> 0 | F40: =D40/$F$3 -> 17377.296 | G40: =E40/$G$3 -> 0 | H40: =IFERROR(D40/E40-1,0) -> 0 | K40: MFA Benin | L40: =SUMIFS( INDEX(Group!C:AL, MATCH($B40, Group!$B:$B, 0), ), Group!$C$3:$AL$3, ">="&DATE(YEAR($C$2),1,1), Group!$C$3:$AL$3, "<="&$C$2 )+869175 -> 24755137 | M40: =SUMIFS( INDEX(Group!C:AL, MATCH($B40, Group!$B:$B, 0), ), Group!$C$3:$AL$3, ">="&DATE(YEAR($C$2)-1,1,1), Group!$C$3:$AL$3, "<="&EDATE($C$2,-12) ) -> 0 | N40: =L40/$F$3 -> 18009.63 | O40: =M40/$G$3 -> 0 | P40: =IFERROR(L40/M40-1,0) -> 0
B41: Fixiam | C41: Fixiam | D41: =SUMIFS( INDEX(NG!C:AL, MATCH($B41, NG!$B:$B, 0), ), NG!$C$3:$AL$3, ">="&DATE(YEAR($C$2),1,1), NG!$C$3:$AL$3, "<="&$C$2 ) -> 0 | E41: =SUMIFS( INDEX(NG!C:AL, MATCH($B41, NG!$B:$B, 0), ), NG!$C$3:$AL$3, ">="&DATE(YEAR($C$2)-1,1,1), NG!$C$3:$AL$3, "<="&EDATE($C$2,-12) ) -> 0 | F41: =D41/$F$3 -> 0 | G41: =E41/$G$3 -> 0 | H41: =IFERROR(D41/E41-1,0) -> 0 | K41: Fixiam | L41: =SUMIFS( INDEX(Group!C:AL, MATCH($B41, Group!$B:$B, 0), ), Group!$C$3:$AL$3, ">="&DATE(YEAR($C$2),1,1), Group!$C$3:$AL$3, "<="&$C$2 ) -> 202857.63 | M41: =SUMIFS( INDEX(Group!C:AL, MATCH($B41, Group!$B:$B, 0), ), Group!$C$3:$AL$3, ">="&DATE(YEAR($C$2)-1,1,1), Group!$C$3:$AL$3, "<="&EDATE($C$2,-12) ) -> 0 | N41: =L41/$F$3 -> 147.58112 | O41: =M41/$G$3 -> 0 | P41: =IFERROR(L41/M41-1,0) -> 0
...

Sheet NG
U2: =IF(U$3<=Summary!$C$2,_xlfn.XLOOKUP(NG!$B4,PL_NG!$C:$C,PL_NG!V:V),0) -> 2.0916453e+08 | V2: =IF(V$3<=Summary!$C$2,_xlfn.XLOOKUP(NG!$B4,PL_NG!$C:$C,PL_NG!W:W),0) -> 1.8398851e+08 | W2: =IF(W$3<=Summary!$C$2,_xlfn.XLOOKUP(NG!$B4,PL_NG!$C:$C,PL_NG!X:X),0) -> 4.0119621e+08
C3: 45322 | D3: =EOMONTH(C3,1) -> 45351 | E3: =EOMONTH(D3,1) -> 45382 | F3: =EOMONTH(E3,1) -> 45412 | G3: =EOMONTH(F3,1) -> 45443 | H3: =EOMONTH(G3,1) -> 45473 | I3: =EOMONTH(H3,1) -> 45504 | J3: =EOMONTH(I3,1) -> 45535 | K3: =EOMONTH(J3,1) -> 45565 | ... AL3: =EOMONTH(AK3,1) -> 46387
B4: TOTAL REVENUE | C4: =IF(C$3<=Summary!$C$2,_xlfn.XLOOKUP(NG!$B4,PL_NG!$C:$C,PL_NG!D:D),0) -> 1.7517098e+08 | D4: =IF(D$3<=Summary!$C$2,_xlfn.XLOOKUP(NG!$B4,PL_NG!$C:$C,PL_NG!E:E),0) -> 5.1848939e+08 | E4: =IF(E$3<=Summary!$C$2,_xlfn.XLOOKUP(NG!$B4,PL_NG!$C:$C,PL_NG!F:F),0) -> 5.2701424e+08 | F4: =IF(F$3<=Summary!$C$2,_xlfn.XLOOKUP(NG!$B4,PL_NG!$C:$C,PL_NG!G:G),0) -> 5.4183986e+08 | G4: =IF(G$3<=Summary!$C$2,_xlfn.XLOOKUP(NG!$B4,PL_NG!$C:$C,PL_NG!H:H),0) -> 2.067278e+08 | H4: =IF(H$3<=Summary!$C$2,_xlfn.XLOOKUP(NG!$B4,PL_NG!$C:$C,PL_NG!I:I),0) -> 2.1943995e+08 | I4: =IF(I$3<=Summary!$C$2,_xlfn.XLOOKUP(NG!$B4,PL_NG!$C:$C,PL_NG!J:J),0) -> 2.1383883e+08 | J4: =IF(J$3<=Summary!$C$2,_xlfn.XLOOKUP(NG!$B4,PL_NG!$C:$C,PL_NG!K:K),0) -> 3.1320444e+08 | K4: =IF(K$3<=Summary!$C$2,_xlfn.XLOOKUP(NG!$B4,PL_NG!$C:$C,PL_NG!L:L),0) -> 1.2182022e+08 | L4: =IF(L$3<=Summary!$C$2,_xlfn.XLOOKUP(NG!$B4,PL_NG!$C:$C,PL_NG!M:M),0) -> 1.7337772e+08 | M4: =IF(M$3<=Summary!$C$2,_xlfn.XLOOKUP(NG!$B4,PL_NG!$C:$C,PL_NG!N:N),0) -> 2.2699189e+08 | N4: =IF(N$3<=Summary!$C$2,_xlfn.XLOOKUP(NG!$B4,PL_NG!$C:$C,PL_NG!O:O),0) -> 5.92258e+08 | O4: =IF(O$3<=Summary!$C$2,_xlfn.XLOOKUP(NG!$B4,PL_NG!$C:$C,PL_NG!P:P),0) -> 2.1326861e+08 | P4: =IF(P$3<=Summary!$C$2,_xlfn.XLOOKUP(NG!$B4,PL_NG!$C:$C,PL_NG!Q:Q),0) -> 1.9704868e+08 | Q4: =IF(Q$3<=Summary!$C$2,_xlfn.XLOOKUP(NG!$B4,PL_NG!$C:$C,PL_NG!R:R),0) -> 2.2240303e+08 | R4: =IF(R$3<=Summary!$C$2,_xlfn.XLOOKUP(NG!$B4,PL_NG!$C:$C,PL_NG!S:S),0) -> 2.4270022e+08 | S4: =IF(S$3<=Summary!$C$2,_xlfn.XLOOKUP(NG!$B4,PL_NG!$C:$C,PL_NG!T:T),0) -> 1.7449216e+08 | T4: =IF(T$3<=Summary!$C$2,_xlfn.XLOOKUP(NG!$B4,PL_NG!$C:$C,PL_NG!U:U),0) -> 1.1974094e+08 | U4: =IF(U$3<=Summary!$C$2,_xlfn.XLOOKUP(NG!$B4,PL_NG!$C:$C,PL_NG!V:V),0) -> 2.0916453e+08 | V4: =IF(V$3<=Summary!$C$2,_xlfn.XLOOKUP(NG!$B4,PL_NG!$C:$C,PL_NG!W:W),0) -> 1.8398851e+08 | W4: =IF(W$3<=Summary!$C$2,_xlfn.XLOOKUP(NG!$B4,PL_NG!$C:$C,PL_NG!X:X),0) -> 4.0119621e+08 | X4: =IF(X$3<=Summary!$C$2,_xlfn.XLOOKUP(NG!$B4,PL_NG!$C:$C,PL_NG!Y:Y),0) -> 7.5500317e+08 | Y4: =IF(Y$3<=Summary!$C$2,_xlfn.XLOOKUP(NG!$B4,PL_NG!$C:$C,PL_NG!Z:Z),0) -> 3.2266712e+08 | Z4: =IF(Z$3<=Summary!$C$2,_xlfn.XLOOKUP(NG!$B4,PL_NG!$C:$C,PL_NG!AA:AA),0) -> 3.1213675e+08 | AA4: =IF(AA$3<=Summary!$C$2,_xlfn.XLOOKUP(NG!$B4,PL_NG!$C:$C,PL_NG!AB:AB),0) -> 7.1293977e+08 | AB4: =IF(AB$3<=Summary!$C$2,_xlfn.XLOOKUP(NG!$B4,PL_NG!$C:$C,PL_NG!AC:AC),0) -> 7.5719318e+08 | AC4: =IF(AC$3<=Summary!$C$2,_xlfn.XLOOKUP(NG!$B4,PL_NG!$C:$C,PL_NG!AD:AD),0) -> 5.4911753e+08 | AD4: =IF(AD$3<=Summary!$C$2,_xlfn.XLOOKUP(NG!$B4,PL_NG!$C:$C,PL_NG!AE:AE),0) -> 3.4442948e+08 | AE4: =IF(AE$3<=Summary!$C$2,_xlfn.XLOOKUP(NG!$B4,PL_NG!$C:$C,PL_NG!AF:AF),0) -> 0 | AF4: =IF(AF$3<=Summary!$C$2,_xlfn.XLOOKUP(NG!$B4,PL_NG!$C:$C,PL_NG!AG:AG),0) -> 0 | AG4: =IF(AG$3<=Summary!$C$2,_xlfn.XLOOKUP(NG!$B4,PL_NG!$C:$C,PL_NG!AH:AH),0) -> 0 | AH4: =IF(AH$3<=Summary!$C$2,_xlfn.XLOOKUP(NG!$B4,PL_NG!$C:$C,PL_NG!AI:AI),0) -> 0 | AI4: =IF(AI$3<=Summary!$C$2,_xlfn.XLOOKUP(NG!$B4,PL_NG!$C:$C,PL_NG!AJ:AJ),0) -> 0 | AJ4: =IF(AJ$3<=Summary!$C$2,_xlfn.XLOOKUP(NG!$B4,PL_NG!$C:$C,PL_NG!AK:AK),0) -> 0 | AK4: =IF(AK$3<=Summary!$C$2,_xlfn.XLOOKUP(NG!$B4,PL_NG!$C:$C,PL_NG!AL:AL),0) -> 0 | AL4: =IF(AL$3<=Summary!$C$2,_xlfn.XLOOKUP(NG!$B4,PL_NG!$C:$C,PL_NG!AM:AM),0) -> 0
B5: TOTAL COST OF SALES | C5: =IF(C$3<=Summary!$C$2,_xlfn.XLOOKUP(NG!$B5,PL_NG!$C:$C,PL_NG!D:D),0) -> -83261122 | D5: =IF(D$3<=Summary!$C$2,_xlfn.XLOOKUP(NG!$B5,PL_NG!$C:$C,PL_NG!E:E),0) -> -1.0207195e+08 | E5: =IF(E$3<=Summary!$C$2,_xlfn.XLOOKUP(NG!$B5,PL_NG!$C:$C,PL_NG!F:F),0) -> -1.303486e+08 | F5: =IF(F$3<=Summary!$C$2,_xlfn.XLOOKUP(NG!$B5,PL_NG!$C:$C,PL_NG!G:G),0) -> -1.5508989e+08 | G5: =IF(G$3<=Summary!$C$2,_xlfn.XLOOKUP(NG!$B5,PL_NG!$C:$C,PL_NG!H:H),0) -> -1.8365757e+08 | H5: =IF(H$3<=Summary!$C$2,_xlfn.XLOOKUP(NG!$B5,PL_NG!$C:$C,PL_NG!I:I),0) -> -73738085 | I5: =IF(I$3<=Summary!$C$2,_xlfn.XLOOKUP(NG!$B5,PL_NG!$C:$C,PL_NG!J:J),0) -> -63584964 | J5: =IF(J$3<=Summary!$C$2,_xlfn.XLOOKUP(NG!$B5,PL_NG!$C:$C,PL_NG!K:K),0) -> -1.5667029e+08 | K5: =IF(K$3<=Summary!$C$2,_xlfn.XLOOKUP(NG!$B5,PL_NG!$C:$C,PL_NG!L:L),0) -> -80126589 | L5: =IF(L$3<=Summary!$C$2,_xlfn.XLOOKUP(NG!$B5,PL_NG!$C:$C,PL_NG!M:M),0) -> -78233709 | M5: =IF(M$3<=Summary!$C$2,_xlfn.XLOOKUP(NG!$B5,PL_NG!$C:$C,PL_NG!N:N),0) -> -87318733 | N5: =IF(N$3<=Summary!$C$2,_xlfn.XLOOKUP(NG!$B5,PL_NG!$C:$C,PL_NG!O:O),0) -> -1.0404002e+08 | O5: =IF(O$3<=Summary!$C$2,_xlfn.XLOOKUP(NG!$B5,PL_NG!$C:$C,PL_NG!P:P),0) -> -72177218 | P5: =IF(P$3<=Summary!$C$2,_xlfn.XLOOKUP(NG!$B5,PL_NG!$C:$C,PL_NG!Q:Q),0) -> -52445967 | Q5: =IF(Q$3<=Summary!$C$2,_xlfn.XLOOKUP(NG!$B5,PL_NG!$C:$C,PL_NG!R:R),0) -> -56447543 | R5: =IF(R$3<=Summary!$C$2,_xlfn.XLOOKUP(NG!$B5,PL_NG!$C:$C,PL_NG!S:S),0) -> -57526259 | S5: =IF(S$3<=Summary!$C$2,_xlfn.XLOOKUP(NG!$B5,PL_NG!$C:$C,PL_NG!T:T),0) -> -67775465 | T5: =IF(T$3<=Summary!$C$2,_xlfn.XLOOKUP(NG!$B5,PL_NG!$C:$C,PL_NG!U:U),0) -> -62498337 | U5: =IF(U$3<=Summary!$C$2,_xlfn.XLOOKUP(NG!$B5,PL_NG!$C:$C,PL_NG!V:V),0) -> -1.0371963e+08 | V5: =IF(V$3<=Summary!$C$2,_xlfn.XLOOKUP(NG!$B5,PL_NG!$C:$C,PL_NG!W:W),0) -> 9725952.2 | W5: =IF(W$3<=Summary!$C$2,_xlfn.XLOOKUP(NG!$B5,PL_NG!$C:$C,PL_NG!X:X),0) -> -1.0742246e+08 | X5: =IF(X$3<=Summary!$C$2,_xlfn.XLOOKUP(NG!$B5,PL_NG!$C:$C,PL_NG!Y:Y),0) -> -75931737 | Y5: =IF(Y$3<=Summary!$C$2,_xlfn.XLOOKUP(NG!$B5,PL_NG!$C:$C,PL_NG!Z:Z),0) -> -62873576 | Z5: =IF(Z$3<=Summary!$C$2,_xlfn.XLOOKUP(NG!$B5,PL_NG!$C:$C,PL_NG!AA:AA),0) -> -1.4672293e+08 | AA5: =IF(AA$3<=Summary!$C$2,_xlfn.XLOOKUP(NG!$B5,PL_NG!$C:$C,PL_NG!AB:AB),0) -> -1.5200236e+08 | AB5: =IF(AB$3<=Summary!$C$2,_xlfn.XLOOKUP(NG!$B5,PL_NG!$C:$C,PL_NG!AC:AC),0) -> -1.4038357e+08 | AC5: =IF(AC$3<=Summary!$C$2,_xlfn.XLOOKUP(NG!$B5,PL_NG!$C:$C,PL_NG!AD:AD),0) -> -1.4172901e+08 | AD5: =IF(AD$3<=Summary!$C$2,_xlfn.XLOOKUP(NG!$B5,PL_NG!$C:$C,PL_NG!AE:AE),0) -> -71143523 | AE5: =IF(AE$3<=Summary!$C$2,_xlfn.XLOOKUP(NG!$B5,PL_NG!$C:$C,PL_NG!AF:AF),0) -> 0 | AF5: =IF(AF$3<=Summary!$C$2,_xlfn.XLOOKUP(NG!$B5,PL_NG!$C:$C,PL_NG!AG:AG),0) -> 0 | AG5: =IF(AG$3<=Summary!$C$2,_xlfn.XLOOKUP(NG!$B5,PL_NG!$C:$C,PL_NG!AH:AH),0) -> 0 | AH5: =IF(AH$3<=Summary!$C$2,_xlfn.XLOOKUP(NG!$B5,PL_NG!$C:$C,PL_NG!AI:AI),0) -> 0 | AI5: =IF(AI$3<=Summary!$C$2,_xlfn.XLOOKUP(NG!$B5,PL_NG!$C:$C,PL_NG!AJ:AJ),0) -> 0 | AJ5: =IF(AJ$3<=Summary!$C$2,_xlfn.XLOOKUP(NG!$B5,PL_NG!$C:$C,PL_NG!AK:AK),0) -> 0 | AK5: =IF(AK$3<=Summary!$C$2,_xlfn.XLOOKUP(NG!$B5,PL_NG!$C:$C,PL_NG!AL:AL),0) -> 0 | AL5: =IF(AL$3<=Summary!$C$2,_xlfn.XLOOKUP(NG!$B5,PL_NG!$C:$C,PL_NG!AM:AM),0) -> 0
A6: 3.8049509e+08 | B6: TOTAL OTHER REVENUE | C6: =IF(C$3<=Summary!$C$2,_xlfn.XLOOKUP(NG!$B6,PL_NG!$C:$C,PL_NG!D:D),0) -> 54873.98 | D6: =IF(D$3<=Summary!$C$2,_xlfn.XLOOKUP(NG!$B6,PL_NG!$C:$C,PL_NG!E:E),0) -> 28793.59 | E6: =IF(E$3<=Summary!$C$2,_xlfn.XLOOKUP(NG!$B6,PL_NG!$C:$C,PL_NG!F:F),0) -> 36275.65 | F6: =IF(F$3<=Summary!$C$2,_xlfn.XLOOKUP(NG!$B6,PL_NG!$C:$C,PL_NG!G:G),0) -> 308917.02 | G6: =IF(G$3<=Summary!$C$2,_xlfn.XLOOKUP(NG!$B6,PL_NG!$C:$C,PL_NG!H:H),0) -> 9570381.1 | H6: =IF(H$3<=Summary!$C$2,_xlfn.XLOOKUP(NG!$B6,PL_NG!$C:$C,PL_NG!I:I),0) -> 33173690 | I6: =IF(I$3<=Summary!$C$2,_xlfn.XLOOKUP(NG!$B6,PL_NG!$C:$C,PL_NG!J:J),0) -> 31628524 | J6: =IF(J$3<=Summary!$C$2,_xlfn.XLOOKUP(NG!$B6,PL_NG!$C:$C,PL_NG!K:K),0) -> 33151885 | K6: =IF(K$3<=Summary!$C$2,_xlfn.XLOOKUP(NG!$B6,PL_NG!$C:$C,PL_NG!L:L),0) -> 2841293 | L6: =IF(L$3<=Summary!$C$2,_xlfn.XLOOKUP(NG!$B6,PL_NG!$C:$C,PL_NG!M:M),0) -> 77487952 | M6: =IF(M$3<=Summary!$C$2,_xlfn.XLOOKUP(NG!$B6,PL_NG!$C:$C,PL_NG!N:N),0) -> 41107532 | N6: =IF(N$3<=Summary!$C$2,_xlfn.XLOOKUP(NG!$B6,PL_NG!$C:$C,PL_NG!O:O),0) -> 43432413 | O6: =IF(O$3<=Summary!$C$2,_xlfn.XLOOKUP(NG!$B6,PL_NG!$C:$C,PL_NG!P:P),0) -> 39006804 | P6: =IF(P$3<=Summary!$C$2,_xlfn.XLOOKUP(NG!$B6,PL_NG!$C:$C,PL_NG!Q:Q),0) -> 31301634 | Q6: =IF(Q$3<=Summary!$C$2,_xlfn.XLOOKUP(NG!$B6,PL_NG!$C:$C,PL_NG!R:R),0) -> 28246672 | R6: =IF(R$3<=Summary!$C$2,_xlfn.XLOOKUP(NG!$B6,PL_NG!$C:$C,PL_NG!S:S),0) -> 29699520 | S6: =IF(S$3<=Summary!$C$2,_xlfn.XLOOKUP(NG!$B6,PL_NG!$C:$C,PL_NG!T:T),0) -> 23109999 | T6: =IF(T$3<=Summary!$C$2,_xlfn.XLOOKUP(NG!$B6,PL_NG!$C:$C,PL_NG!U:U),0) -> 21501586 | U6: =IF(U$3<=Summary!$C$2,_xlfn.XLOOKUP(NG!$B6,PL_NG!$C:$C,PL_NG!V:V),0) -> 21339894 | V6: =IF(V$3<=Summary!$C$2,_xlfn.XLOOKUP(NG!$B6,PL_NG!$C:$C,PL_NG!W:W),0) -> 31930751 | W6: =IF(W$3<=Summary!$C$2,_xlfn.XLOOKUP(NG!$B6,PL_NG!$C:$C,PL_NG!X:X),0) -> 15620184 | X6: =IF(X$3<=Summary!$C$2,_xlfn.XLOOKUP(NG!$B6,PL_NG!$C:$C,PL_NG!Y:Y),0) -> 16531444 | Y6: =IF(Y$3<=Summary!$C$2,_xlfn.XLOOKUP(NG!$B6,PL_NG!$C:$C,PL_NG!Z:Z),0) -> 16189960 | Z6: =IF(Z$3<=Summary!$C$2,_xlfn.XLOOKUP(NG!$B6,PL_NG!$C:$C,PL_NG!AA:AA),0) -> 1.3506537e+08 | AA6: =IF(AA$3<=Summary!$C$2,_xlfn.XLOOKUP(NG!$B6,PL_NG!$C:$C,PL_NG!AB:AB),0) -> 5399535.4 | AB6: =IF(AB$3<=Summary!$C$2,_xlfn.XLOOKUP(NG!$B6,PL_NG!$C:$C,PL_NG!AC:AC),0) -> 22316487 | AC6: =IF(AC$3<=Summary!$C$2,_xlfn.XLOOKUP(NG!$B6,PL_NG!$C:$C,PL_NG!AD:AD),0) -> -18478033 | AD6: =IF(AD$3<=Summary!$C$2,_xlfn.XLOOKUP(NG!$B6,PL_NG!$C:$C,PL_NG!AE:AE),0) -> 63198520 | AE6: =IF(AE$3<=Summary!$C$2,_xlfn.XLOOKUP(NG!$B6,PL_NG!$C:$C,PL_NG!AF:AF),0) -> 0 | AF6: =IF(AF$3<=Summary!$C$2,_xlfn.XLOOKUP(NG!$B6,PL_NG!$C:$C,PL_NG!AG:AG),0) -> 0 | AG6: =IF(AG$3<=Summary!$C$2,_xlfn.XLOOKUP(NG!$B6,PL_NG!$C:$C,PL_NG!AH:AH),0) -> 0 | AH6: =IF(AH$3<=Summary!$C$2,_xlfn.XLOOKUP(NG!$B6,PL_NG!$C:$C,PL_NG!AI:AI),0) -> 0 | AI6: =IF(AI$3<=Summary!$C$2,_xlfn.XLOOKUP(NG!$B6,PL_NG!$C:$C,PL_NG!AJ:AJ),0) -> 0 | AJ6: =IF(AJ$3<=Summary!$C$2,_xlfn.XLOOKUP(NG!$B6,PL_NG!$C:$C,PL_NG!AK:AK),0) -> 0 | AK6: =IF(AK$3<=Summary!$C$2,_xlfn.XLOOKUP(NG!$B6,PL_NG!$C:$C,PL_NG!AL:AL),0) -> 0 | AL6: =IF(AL$3<=Summary!$C$2,_xlfn.XLOOKUP(NG!$B6,PL_NG!$C:$C,PL_NG!AM:AM),0) -> 0
A7: 13716119 | B7: TOTAL OPERATING EXPENSES | C7: =IF(C$3<=Summary!$C$2,_xlfn.XLOOKUP(NG!$B7,PL_NG!$C:$C,PL_NG!D:D),0) -> -1.0754466e+08 | D7: =IF(D$3<=Summary!$C$2,_xlfn.XLOOKUP(NG!$B7,PL_NG!$C:$C,PL_NG!E:E),0) -> -98190212 | E7: =IF(E$3<=Summary!$C$2,_xlfn.XLOOKUP(NG!$B7,PL_NG!$C:$C,PL_NG!F:F),0) -> -1.3064742e+08 | F7: =IF(F$3<=Summary!$C$2,_xlfn.XLOOKUP(NG!$B7,PL_NG!$C:$C,PL_NG!G:G),0) -> -1.404921e+08 | G7: =IF(G$3<=Summary!$C$2,_xlfn.XLOOKUP(NG!$B7,PL_NG!$C:$C,PL_NG!H:H),0) -> -2.367973e+08 | H7: =IF(H$3<=Summary!$C$2,_xlfn.XLOOKUP(NG!$B7,PL_NG!$C:$C,PL_NG!I:I),0) -> -2.6473028e+08 | I7: =IF(I$3<=Summary!$C$2,_xlfn.XLOOKUP(NG!$B7,PL_NG!$C:$C,PL_NG!J:J),0) -> -2.1825787e+08 | J7: =IF(J$3<=Summary!$C$2,_xlfn.XLOOKUP(NG!$B7,PL_NG!$C:$C,PL_NG!K:K),0) -> -1.0862124e+08 | K7: =IF(K$3<=Summary!$C$2,_xlfn.XLOOKUP(NG!$B7,PL_NG!$C:$C,PL_NG!L:L),0) -> -61752847 | L7: =IF(L$3<=Summary!$C$2,_xlfn.XLOOKUP(NG!$B7,PL_NG!$C:$C,PL_NG!M:M),0) -> -4.3569865e+08 | M7: =IF(M$3<=Summary!$C$2,_xlfn.XLOOKUP(NG!$B7,PL_NG!$C:$C,PL_NG!N:N),0) -> -4.107843e+08 | N7: =IF(N$3<=Summary!$C$2,_xlfn.XLOOKUP(NG!$B7,PL_NG!$C:$C,PL_NG!O:O),0) -> -5.2302543e+08 | O7: =IF(O$3<=Summary!$C$2,_xlfn.XLOOKUP(NG!$B7,PL_NG!$C:$C,PL_NG!P:P),0) -> -1.9283026e+08 | P7: =IF(P$3<=Summary!$C$2,_xlfn.XLOOKUP(NG!$B7,PL_NG!$C:$C,PL_NG!Q:Q),0) -> -2.1932431e+08 | Q7: =IF(Q$3<=Summary!$C$2,_xlfn.XLOOKUP(NG!$B7,PL_NG!$C:$C,PL_NG!R:R),0) -> -1.9066781e+08 | R7: =IF(R$3<=Summary!$C$2,_xlfn.XLOOKUP(NG!$B7,PL_NG!$C:$C,PL_NG!S:S),0) -> -96908036 | S7: =IF(S$3<=Summary!$C$2,_xlfn.XLOOKUP(NG!$B7,PL_NG!$C:$C,PL_NG!T:T),0) -> -3.9144955e+08 | T7: =IF(T$3<=Summary!$C$2,_xlfn.XLOOKUP(NG!$B7,PL_NG!$C:$C,PL_NG!U:U),0) -> -3.2246172e+08 | U7: =IF(U$3<=Summary!$C$2,_xlfn.XLOOKUP(NG!$B7,PL_NG!$C:$C,PL_NG!V:V),0) -> -2.8351007e+08 | V7: =IF(V$3<=Summary!$C$2,_xlfn.XLOOKUP(NG!$B7,PL_NG!$C:$C,PL_NG!W:W),0) -> -2.5699323e+08 | W7: =IF(W$3<=Summary!$C$2,_xlfn.XLOOKUP(NG!$B7,PL_NG!$C:$C,PL_NG!X:X),0) -> -4.3838489e+08 | X7: =IF(X$3<=Summary!$C$2,_xlfn.XLOOKUP(NG!$B7,PL_NG!$C:$C,PL_NG!Y:Y),0) -> -3.2583244e+08 | Y7: =IF(Y$3<=Summary!$C$2,_xlfn.XLOOKUP(NG!$B7,PL_NG!$C:$C,PL_NG!Z:Z),0) -> -3.0577045e+08 | Z7: =IF(Z$3<=Summary!$C$2,_xlfn.XLOOKUP(NG!$B7,PL_NG!$C:$C,PL_NG!AA:AA),0) -> -1.0351769e+09 | AA7: =IF(AA$3<=Summary!$C$2,_xlfn.XLOOKUP(NG!$B7,PL_NG!$C:$C,PL_NG!AB:AB),0) -> -2.9690634e+08 | AB7: =IF(AB$3<=Summary!$C$2,_xlfn.XLOOKUP(NG!$B7,PL_NG!$C:$C,PL_NG!AC:AC),0) -> -2.7563622e+08 | AC7: =IF(AC$3<=Summary!$C$2,_xlfn.XLOOKUP(NG!$B7,PL_NG!$C:$C,PL_NG!AD:AD),0) -> -2.4194446e+08 | AD7: =IF(AD$3<=Summary!$C$2,_xlfn.XLOOKUP(NG!$B7,PL_NG!$C:$C,PL_NG!AE:AE),0) -> -2.3908358e+08 | AE7: =IF(AE$3<=Summary!$C$2,_xlfn.XLOOKUP(NG!$B7,PL_NG!$C:$C,PL_NG!AF:AF),0) -> 0 | AF7: =IF(AF$3<=Summary!$C$2,_xlfn.XLOOKUP(NG!$B7,PL_NG!$C:$C,PL_NG!AG:AG),0) -> 0 | AG7: =IF(AG$3<=Summary!$C$2,_xlfn.XLOOKUP(NG!$B7,PL_NG!$C:$C,PL_NG!AH:AH),0) -> 0 | AH7: =IF(AH$3<=Summary!$C$2,_xlfn.XLOOKUP(NG!$B7,PL_NG!$C:$C,PL_NG!AI:AI),0) -> 0 | AI7: =IF(AI$3<=Summary!$C$2,_xlfn.XLOOKUP(NG!$B7,PL_NG!$C:$C,PL_NG!AJ:AJ),0) -> 0 | AJ7: =IF(AJ$3<=Summary!$C$2,_xlfn.XLOOKUP(NG!$B7,PL_NG!$C:$C,PL_NG!AK:AK),0) -> 0 | AK7: =IF(AK$3<=Summary!$C$2,_xlfn.XLOOKUP(NG!$B7,PL_NG!$C:$C,PL_NG!AL:AL),0) -> 0 | AL7: =IF(AL$3<=Summary!$C$2,_xlfn.XLOOKUP(NG!$B7,PL_NG!$C:$C,PL_NG!AM:AM),0) -> 0
A8: =A6+A7 -> 3.9421121e+08 | B8: TOTAL DEPRECIATION & AMORTISATION | C8: =IF(C$3<=Summary!$C$2,_xlfn.XLOOKUP(NG!$B8,PL_NG!$C:$C,PL_NG!D:D),0) -> -2883128.6 | D8: =IF(D$3<=Summary!$C$2,_xlfn.XLOOKUP(NG!$B8,PL_NG!$C:$C,PL_NG!E:E),0) -> -3092261.8 | E8: =IF(E$3<=Summary!$C$2,_xlfn.XLOOKUP(NG!$B8,PL_NG!$C:$C,PL_NG!F:F),0) -> -2791404 | F8: =IF(F$3<=Summary!$C$2,_xlfn.XLOOKUP(NG!$B8,PL_NG!$C:$C,PL_NG!G:G),0) -> -2466666.5 | G8: =IF(G$3<=Summary!$C$2,_xlfn.XLOOKUP(NG!$B8,PL_NG!$C:$C,PL_NG!H:H),0) -> -2852194 | H8: =IF(H$3<=Summary!$C$2,_xlfn.XLOOKUP(NG!$B8,PL_NG!$C:$C,PL_NG!I:I),0) -> -3230819.9 | I8: =IF(I$3<=Summary!$C$2,_xlfn.XLOOKUP(NG!$B8,PL_NG!$C:$C,PL_NG!J:J),0) -> -3043818.7 | J8: =IF(J$3<=Summary!$C$2,_xlfn.XLOOKUP(NG!$B8,PL_NG!$C:$C,PL_NG!K:K),0) -> -4240446.2 | K8: =IF(K$3<=Summary!$C$2,_xlfn.XLOOKUP(NG!$B8,PL_NG!$C:$C,PL_NG!L:L),0) -> -4195644.7 | L8: =IF(L$3<=Summary!$C$2,_xlfn.XLOOKUP(NG!$B8,PL_NG!$C:$C,PL_NG!M:M),0) -> -4361665.9 | M8: =IF(M$3<=Summary!$C$2,_xlfn.XLOOKUP(NG!$B8,PL_NG!$C:$C,PL_NG!N:N),0) -> -4486868.4 | N8: =IF(N$3<=Summary!$C$2,_xlfn.XLOOKUP(NG!$B8,PL_NG!$C:$C,PL_NG!O:O),0) -> -4477281.8 | O8: =IF(O$3<=Summary!$C$2,_xlfn.XLOOKUP(NG!$B8,PL_NG!$C:$C,PL_NG!P:P),0) -> -4543051 | P8: =IF(P$3<=Summary!$C$2,_xlfn.XLOOKUP(NG!$B8,PL_NG!$C:$C,PL_NG!Q:Q),0) -> -4808597.7 | Q8: =IF(Q$3<=Summary!$C$2,_xlfn.XLOOKUP(NG!$B8,PL_NG!$C:$C,PL_NG!R:R),0) -> -4836131.7 | R8: =IF(R$3<=Summary!$C$2,_xlfn.XLOOKUP(NG!$B8,PL_NG!$C:$C,PL_NG!S:S),0) -> -4829799.5 | S8: =IF(S$3<=Summary!$C$2,_xlfn.XLOOKUP(NG!$B8,PL_NG!$C:$C,PL_NG!T:T),0) -> -4837481.2 | T8: =IF(T$3<=Summary!$C$2,_xlfn.XLOOKUP(NG!$B8,PL_NG!$C:$C,PL_NG!U:U),0) -> -4837481.2 | U8: =IF(U$3<=Summary!$C$2,_xlfn.XLOOKUP(NG!$B8,PL_NG!$C:$C,PL_NG!V:V),0) -> -7470963.8 | V8: =IF(V$3<=Summary!$C$2,_xlfn.XLOOKUP(NG!$B8,PL_NG!$C:$C,PL_NG!W:W),0) -> -6389594.9 | W8: =IF(W$3<=Summary!$C$2,_xlfn.XLOOKUP(NG!$B8,PL_NG!$C:$C,PL_NG!X:X),0) -> -6356357.1 | X8: =IF(X$3<=Summary!$C$2,_xlfn.XLOOKUP(NG!$B8,PL_NG!$C:$C,PL_NG!Y:Y),0) -> -6349940.4 | Y8: =IF(Y$3<=Summary!$C$2,_xlfn.XLOOKUP(NG!$B8,PL_NG!$C:$C,PL_NG!Z:Z),0) -> -6565088.8 | Z8: =IF(Z$3<=Summary!$C$2,_xlfn.XLOOKUP(NG!$B8,PL_NG!$C:$C,PL_NG!AA:AA),0) -> -6608072.1 | AA8: =IF(AA$3<=Summary!$C$2,_xlfn.XLOOKUP(NG!$B8,PL_NG!$C:$C,PL_NG!AB:AB),0) -> -12176015 | AB8: =IF(AB$3<=Summary!$C$2,_xlfn.XLOOKUP(NG!$B8,PL_NG!$C:$C,PL_NG!AC:AC),0) -> -12299363 | AC8: =IF(AC$3<=Summary!$C$2,_xlfn.XLOOKUP(NG!$B8,PL_NG!$C:$C,PL_NG!AD:AD),0) -> -12082020 | AD8: =IF(AD$3<=Summary!$C$2,_xlfn.XLOOKUP(NG!$B8,PL_NG!$C:$C,PL_NG!AE:AE),0) -> -12303124 | AE8: =IF(AE$3<=Summary!$C$2,_xlfn.XLOOKUP(NG!$B8,PL_NG!$C:$C,PL_NG!AF:AF),0) -> 0 | AF8: =IF(AF$3<=Summary!$C$2,_xlfn.XLOOKUP(NG!$B8,PL_NG!$C:$C,PL_NG!AG:AG),0) -> 0 | AG8: =IF(AG$3<=Summary!$C$2,_xlfn.XLOOKUP(NG!$B8,PL_NG!$C:$C,PL_NG!AH:AH),0) -> 0 | AH8: =IF(AH$3<=Summary!$C$2,_xlfn.XLOOKUP(NG!$B8,PL_NG!$C:$C,PL_NG!AI:AI),0) -> 0 | AI8: =IF(AI$3<=Summary!$C$2,_xlfn.XLOOKUP(NG!$B8,PL_NG!$C:$C,PL_NG!AJ:AJ),0) -> 0 | AJ8: =IF(AJ$3<=Summary!$C$2,_xlfn.XLOOKUP(NG!$B8,PL_NG!$C:$C,PL_NG!AK:AK),0) -> 0 | AK8: =IF(AK$3<=Summary!$C$2,_xlfn.XLOOKUP(NG!$B8,PL_NG!$C:$C,PL_NG!AL:AL),0) -> 0 | AL8: =IF(AL$3<=Summary!$C$2,_xlfn.XLOOKUP(NG!$B8,PL_NG!$C:$C,PL_NG!AM:AM),0) -> 0
A9: 4.5453379e+08 | B9: TOTAL INTEREST EXPENSES | C9: =IF(C$3<=Summary!$C$2,_xlfn.XLOOKUP(NG!$B9,PL_NG!$C:$C,PL_NG!D:D),0) -> 0 | D9: =IF(D$3<=Summary!$C$2,_xlfn.XLOOKUP(NG!$B9,PL_NG!$C:$C,PL_NG!E:E),0) -> -321442.6 | E9: =IF(E$3<=Summary!$C$2,_xlfn.XLOOKUP(NG!$B9,PL_NG!$C:$C,PL_NG!F:F),0) -> -1014508.5 | F9: =IF(F$3<=Summary!$C$2,_xlfn.XLOOKUP(NG!$B9,PL_NG!$C:$C,PL_NG!G:G),0) -> 0 | G9: =IF(G$3<=Summary!$C$2,_xlfn.XLOOKUP(NG!$B9,PL_NG!$C:$C,PL_NG!H:H),0) -> 0 | H9: =IF(H$3<=Summary!$C$2,_xlfn.XLOOKUP(NG!$B9,PL_NG!$C:$C,PL_NG!I:I),0) -> 0 | I9: =IF(I$3<=Summary!$C$2,_xlfn.XLOOKUP(NG!$B9,PL_NG!$C:$C,PL_NG!J:J),0) -> 0 | J9: =IF(J$3<=Summary!$C$2,_xlfn.XLOOKUP(NG!$B9,PL_NG!$C:$C,PL_NG!K:K),0) -> 0 | K9: =IF(K$3<=Summary!$C$2,_xlfn.XLOOKUP(NG!$B9,PL_NG!$C:$C,PL_NG!L:L),0) -> 0 | L9: =IF(L$3<=Summary!$C$2,_xlfn.XLOOKUP(NG!$B9,PL_NG!$C:$C,PL_NG!M:M),0) -> 0 | M9: =IF(M$3<=Summary!$C$2,_xlfn.XLOOKUP(NG!$B9,PL_NG!$C:$C,PL_NG!N:N),0) -> 0 | N9: =IF(N$3<=Summary!$C$2,_xlfn.XLOOKUP(NG!$B9,PL_NG!$C:$C,PL_NG!O:O),0) -> 0 | O9: =IF(O$3<=Summary!$C$2,_xlfn.XLOOKUP(NG!$B9,PL_NG!$C:$C,PL_NG!P:P),0) -> 0 | P9: =IF(P$3<=Summary!$C$2,_xlfn.XLOOKUP(NG!$B9,PL_NG!$C:$C,PL_NG!Q:Q),0) -> 0 | Q9: =IF(Q$3<=Summary!$C$2,_xlfn.XLOOKUP(NG!$B9,PL_NG!$C:$C,PL_NG!R:R),0) -> 0 | R9: =IF(R$3<=Summary!$C$2,_xlfn.XLOOKUP(NG!$B9,PL_NG!$C:$C,PL_NG!S:S),0) -> 0 | S9: =IF(S$3<=Summary!$C$2,_xlfn.XLOOKUP(NG!$B9,PL_NG!$C:$C,PL_NG!T:T),0) -> -144180000 | T9: =IF(T$3<=Summary!$C$2,_xlfn.XLOOKUP(NG!$B9,PL_NG!$C:$C,PL_NG!U:U),0) -> 0 | U9: =IF(U$3<=Summary!$C$2,_xlfn.XLOOKUP(NG!$B9,PL_NG!$C:$C,PL_NG!V:V),0) -> 0 | V9: =IF(V$3<=Summary!$C$2,_xlfn.XLOOKUP(NG!$B9,PL_NG!$C:$C,PL_NG!W:W),0) -> 0 | W9: =IF(W$3<=Summary!$C$2,_xlfn.XLOOKUP(NG!$B9,PL_NG!$C:$C,PL_NG!X:X),0) -> 0 | X9: =IF(X$3<=Summary!$C$2,_xlfn.XLOOKUP(NG!$B9,PL_NG!$C:$C,PL_NG!Y:Y),0) -> -134088144 | Y9: =IF(Y$3<=Summary!$C$2,_xlfn.XLOOKUP(NG!$B9,PL_NG!$C:$C,PL_NG!Z:Z),0) -> 0 | Z9: =IF(Z$3<=Summary!$C$2,_xlfn.XLOOKUP(NG!$B9,PL_NG!$C:$C,PL_NG!AA:AA),0) -> 0 | AA9: =IF(AA$3<=Summary!$C$2,_xlfn.XLOOKUP(NG!$B9,PL_NG!$C:$C,PL_NG!AB:AB),0) -> 0 | AB9: =IF(AB$3<=Summary!$C$2,_xlfn.XLOOKUP(NG!$B9,PL_NG!$C:$C,PL_NG!AC:AC),0) -> 0 | AC9: =IF(AC$3<=Summary!$C$2,_xlfn.XLOOKUP(NG!$B9,PL_NG!$C:$C,PL_NG!AD:AD),0) -> 0 | AD9: =IF(AD$3<=Summary!$C$2,_xlfn.XLOOKUP(NG!$B9,PL_NG!$C:$C,PL_NG!AE:AE),0) -> 0 | AE9: =IF(AE$3<=Summary!$C$2,_xlfn.XLOOKUP(NG!$B9,PL_NG!$C:$C,PL_NG!AF:AF),0) -> 0 | AF9: =IF(AF$3<=Summary!$C$2,_xlfn.XLOOKUP(NG!$B9,PL_NG!$C:$C,PL_NG!AG:AG),0) -> 0 | AG9: =IF(AG$3<=Summary!$C$2,_xlfn.XLOOKUP(NG!$B9,PL_NG!$C:$C,PL_NG!AH:AH),0) -> 0 | AH9: =IF(AH$3<=Summary!$C$2,_xlfn.XLOOKUP(NG!$B9,PL_NG!$C:$C,PL_NG!AI:AI),0) -> 0 | AI9: =IF(AI$3<=Summary!$C$2,_xlfn.XLOOKUP(NG!$B9,PL_NG!$C:$C,PL_NG!AJ:AJ),0) -> 0 | AJ9: =IF(AJ$3<=Summary!$C$2,_xlfn.XLOOKUP(NG!$B9,PL_NG!$C:$C,PL_NG!AK:AK),0) -> 0 | AK9: =IF(AK$3<=Summary!$C$2,_xlfn.XLOOKUP(NG!$B9,PL_NG!$C:$C,PL_NG!AL:AL),0) -> 0 | AL9: =IF(AL$3<=Summary!$C$2,_xlfn.XLOOKUP(NG!$B9,PL_NG!$C:$C,PL_NG!AM:AM),0) -> 0
